Workbook
Name AFHomesStaff0: 'Reference Lists'!$A$2:$A$2
Name AFHomesStaff1: 'Reference Lists'!$B$2:$B$2
Name AFHomesStaff2: 'Reference Lists'!$C$2:$C$2
Name AFHomesStaff3: 'Reference Lists'!$D$2:$D$2
Name AFHomesEmpty: 'Address Lists'!$D$1
Name AFHomesProvinces: 'Address Lists'!$A$2:$A$84
Name AFHomesCities0: 'Address Lists'!$C$2:$AC$2
Name AFHomesCities1: 'Address Lists'!$C$3:$N$3
Name AFHomesCities2: 'Address Lists'!$C$4:$P$4
Name AFHomesCities3: 'Address Lists'!$C$5:$S$5
Name AFHomesCities4: 'Address Lists'!$C$6:$T$6
Name AFHomesCities5: 'Address Lists'!$C$7:$T$7
Name AFHomesCities6: 'Address Lists'!$C$8:$I$8
Name AFHomesCities7: 'Address Lists'!$C$9:$J$9
Name AFHomesCities8: 'Address Lists'!$C$10:$N$10
Name AFHomesCities9: 'Address Lists'!$C$11:$N$11
Name AFHomesCities10: 'Address Lists'!$C$12:$H$12
Name AFHomesCities11: 'Address Lists'!$C$13:$AJ$13
Name AFHomesCities12: 'Address Lists'!$C$14:$P$14
Name AFHomesCities13: 'Address Lists'!$C$15:$J$15
Name AFHomesCities14: 'Address Lists'!$C$16:$AX$16
Name AFHomesCities15: 'Address Lists'!$C$17:$X$17
Name AFHomesCities16: 'Address Lists'!$C$18:$Z$18
Name AFHomesCities17: 'Address Lists'!$C$19:$AE$19
Name AFHomesCities18: 'Address Lists'!$C$20:$N$20
Name AFHomesCities19: 'Address Lists'!$C$21:$AM$21
Name AFHomesCities20: 'Address Lists'!$C$22:$G$22
Name AFHomesCities21: 'Address Lists'!$C$23:$S$23
Name AFHomesCities22: 'Address Lists'!$C$24:$M$24
Name AFHomesCities23: 'Address Lists'!$C$25:$Y$25
Name AFHomesCities24: 'Address Lists'!$C$26:$BC$26
Name AFHomesCities25: 'Address Lists'!$C$27:$T$27
Name AFHomesCities26: 'Address Lists'!$C$28:$G$28
Name AFHomesCities27: 'Address Lists'!$C$29:$M$29
Name AFHomesCities28: 'Address Lists'!$C$30:$M$30
Name AFHomesCities29: 'Address Lists'!$C$31:$M$31
Name AFHomesCities30: 'Address Lists'!$C$32:$M$32
Name AFHomesCities31: 'Address Lists'!$C$33:$I$33
Name AFHomesCities32: 'Address Lists'!$C$34:$Y$34
Name AFHomesCities33: 'Address Lists'!$C$35:$G$35
Name AFHomesCities34: 'Address Lists'!$C$36:$M$36
Name AFHomesCities35: 'Address Lists'!$C$37:$Y$37
Name AFHomesCities36: 'Address Lists'!$C$38:$AJ$38
Name AFHomesCities37: 'Address Lists'!$C$39:$AT$39
Name AFHomesCities38: 'Address Lists'!$C$40:$AM$40
Name AFHomesCities39: 'Address Lists'!$C$41:$J$41
Name AFHomesCities40: 'Address Lists'!$C$42:$V$42
Name AFHomesCities41: 'Address Lists'!$C$43:$AF$43
Name AFHomesCities42: 'Address Lists'!$C$44:$Y$44
Name AFHomesCities43: 'Address Lists'!$C$45:$AP$45
Name AFHomesCities44: 'Address Lists'!$C$46:$AS$46
Name AFHomesCities45: 'Address Lists'!$C$47:$O$47
Name AFHomesCities46: 'Address Lists'!$C$48:$Z$48
Name AFHomesCities47: 'Address Lists'!$C$49:$H$49
Name AFHomesCities48: 'Address Lists'!$C$50:$W$50
Name AFHomesCities49: 'Address Lists'!$C$51:$S$51
Name AFHomesCities50: 'Address Lists'!$C$52:$S$52
Name AFHomesCities51: 'Address Lists'!$C$53:$AB$53
Name AFHomesCities52: 'Address Lists'!$C$54:$L$54
Name AFHomesCities53: 'Address Lists'!$C$55:$AH$55

Sheet Start Here
A1: AF Homes | Customer import
A2: Enter one purchase on Customers. On other tabs, select its VIP card ID / Purchase reference. No separate customer key.
A3: Customer ID (RA No.): copy the exact existing company Excel ID, even when that customer is not yet in this system.
A4: Only Gold can have an optional supplementary holder. Silver and Bronze cannot have supplementary holders.
A5: For genuinely new customers without a company ID, leave it blank to generate YYYY-NNNN (for example 2026-0001) on save.
A6: Reuse the same VIP card ID / Purchase reference when correcting or importing the same purchase again.
A7: Use one Birth date, Contract date or Payment date. Enter a date or use the calendar if your Excel supports it.
A8: Age calculates automatically. Citizenship is typed. Landline and TIN are optional; supplied TINs must be complete.
A9: Select Province, then City / Municipality, then Barangay. ZIP fills only from a unique postal reference match.
A10: Select the actual registered Referrer and VIP Recommender. They must share the same VD genealogy tree.
A11: List every actual payment once. Payment claim reference may be blank; the importer generates a stable reference.
A12: Separate identical payments need distinct claim references. Keep Receipt / Bank reference where available.
... A22: Points spending uses actual service or overnight dates in Philippine time, never the staff processing date. Allowances cannot exchange.

Sheet Customers
A1: Customer ID (RA No.) | B1: VIP card ID / Purchase reference (blank generates) | C1: Existing reservation reference | D1: Existing document status (optional) | E1: First name | F1: Last name | G1: Middle name | H1: Suffix | I1: Birth date | J1: Age (calculated) | K1: Gender | L1: Citizenship | M1: Civil status | N1: Address line 1 | O1: Address line 2 | P1: Province | Q1: City / Municipality | R1: Barangay | S1: Postal code | T1: Landline (optional) | U1: Email | V1: Mobile number | W1: TIN (optional) | X1: Occupation / Business name | Y1: Office / Business address | Z1: Position | AA1: VIP plan | AB1: Payment terms | AC1: Contract date | AD1: Regular contract price | AE1: Approved discount amount (claimed) | AF1: Contract total (calculated) | AG1: Included reservation fee | AH1: Payments stated (calculated) | AI1: Remaining balance (calculated) | AJ1: Existing card activation status | AK1: Existing Stay Points total | AL1: Existing card activation date | AM1: Existing card valid until | AN1: VIP purchase date (if known) | AO1: Payment term months for VIP ID (1-36; optional) | AP1: Contract type (new IDs: Standard)
D2: Pending | E2: Miguel | F2: Santos | G2: Reyes | I2: 1988-03-14 | J2: =IF(I2="","",DATEDIF(I2,TODAY(),"Y")) | K2: Male | L2: Filipino | M2: Married | N2: 18 Sampaguita Street | P2: Laguna | Q2: City of Calamba | R2: Bucal | S2: 4027 | U2: miguel.santos@afhomes-local.test | V2: 09178462510 | X2: Architect | AA2: BRONZE | AB2: Spot cash | AC2: 2026-10-01 | AD2: 60000.00 | AE2: 0.00 | AF2: =IF(B2="","",AD2-AE2) | AG2: 10000.00 | AH2: =IF(B2="","",SUMIF('Payments'!$A$2:$A$5001,B2,'Payments'!$D$2:$D$5001)) | AI2: =IF(B2="","",AF2-AH2) | AO2: 1 | AP2: Standard
A3: 2025-0782 | D3: Reservation Paid | E3: Isabella | F3: Mendoza | G3: Cruz | I3: 1992-07-22 | J3: =IF(I3="","",DATEDIF(I3,TODAY(),"Y")) | K3: Female | L3: Filipino | M3: Single | N3: 42 Mahogany Avenue | P3: Cavite | Q3: City of Tagaytay | R3: Kaybagal South | S3: 4120 | U3: isabella.mendoza@afhomes-local.test | V3: 09178462511 | X3: Pharmacist | AA3: BRONZE | AB3: Move a | AC3: 2026-10-01 | AD3: 60000.00 | AE3: 0.00 | AF3: =IF(B3="","",AD3-AE3) | AG3: 10000.00 | AH3: =IF(B3="","",SUMIF('Payments'!$A$2:$A$5001,B3,'Payments'!$D$2:$D$5001)) | AI3: =IF(B3="","",AF3-AH3) | AO3: 1 | AP3: Standard
D4: Partially Paid | E4: Rafael | F4: Bautista | G4: Navarro | I4: 1985-11-06 | J4: =IF(I4="","",DATEDIF(I4,TODAY(),"Y")) | K4: Male | L4: Filipino | M4: Married | N4: 7 Acacia Lane | P4: Batangas | Q4: City of Lipa | R4: Balintawak | S4: 4217 | U4: rafael.bautista@afhomes-local.test | V4: 09178462512 | X4: Civil Engineer | AA4: BRONZE | AB4: Installment 4_month | AC4: 2026-10-01 | AD4: 72000.00 | AE4: 0.00 | AF4: =IF(B4="","",AD4-AE4) | AG4: 10000.00 | AH4: =IF(B4="","",SUMIF('Payments'!$A$2:$A$5001,B4,'Payments'!$D$2:$D$5001)) | AI4: =IF(B4="","",AF4-AH4) | AO4: 4 | AP4: Standard
A5: 2025-0784 | D5: Down Payment | E5: Camille | F5: Villanueva | G5: Garcia | I5: 1990-02-18 | J5: =IF(I5="","",DATEDIF(I5,TODAY(),"Y")) | K5: Female | L5: Filipino | M5: Single | N5: 25 Ilang Ilang Street | P5: Rizal | Q5: City of Antipolo | R5: San Roque | S5: 1870 | U5: camille.villanueva@afhomes-local.test | V5: 09178462513 | X5: Accountant | AA5: SILVER | AB5: Move b1 40 12 | AC5: 2026-10-01 | AD5: 300000.00 | AE5: 0.00 | AF5: =IF(B5="","",AD5-AE5) | AG5: 10000.00 | AH5: =IF(B5="","",SUMIF('Payments'!$A$2:$A$5001,B5,'Payments'!$D$2:$D$5001)) | AI5: =IF(B5="","",AF5-AH5) | AO5: 12 | AP5: Standard
D6: Fully Paid | E6: Lorenzo | F6: Aquino | G6: Ramos | I6: 1983-09-10 | J6: =IF(I6="","",DATEDIF(I6,TODAY(),"Y")) | K6: Male | L6: Filipino | M6: Married | N6: 63 Narra Road | P6: Bulacan | Q6: City of Malolos | R6: Guinhawa | S6: 3000 | U6: lorenzo.aquino@afhomes-local.test | V6: 09178462514 | X6: Business Owner | AA6: GOLD | AB6: Move b2 25 12 | AC6: 2026-10-01 | AD6: 384000.00 | AE6: 0.00 | AF6: =IF(B6="","",AD6-AE6) | AG6: 10000.00 | AH6: =IF(B6="","",SUMIF('Payments'!$A$2:$A$5001,B6,'Payments'!$D$2:$D$5001)) | AI6: =IF(B6="","",AF6-AH6) | AO6: 12 | AP6: Standard
A7: 2025-0786 | B7: 26011500841G1C01S | D7: Active VIP | E7: Patricia | F7: Delos Reyes | G7: Flores | I7: 1989-05-27 | J7: =IF(I7="","",DATEDIF(I7,TODAY(),"Y")) | K7: Female | L7: Filipino | M7: Single | N7: 31 Rosal Street | P7: Pampanga | Q7: City of San Fernando | R7: Del Pilar | S7: 2000 | U7: patricia.delosreyes@afhomes-local.test | V7: 09178462515 | X7: Dentist | AA7: GOLD | AB7: Spot cash | AC7: 2026-01-15 | AD7: 312000.00 | AE7: 0.00 | AF7: =IF(B7="","",AD7-AE7) | AG7: 10000.00 | AH7: =IF(B7="","",SUMIF('Payments'!$A$2:$A$5001,B7,'Payments'!$D$2:$D$5001)) | AI7: =IF(B7="","",AF7-AH7) | AJ7: Active | AK7: 10000 | AL7: 2026-01-17 | AM7: 2031-01-17 | AO7: 1 | AP7: Standard
D8: Active VIP | E8: Gabriel | F8: Castillo | G8: Torres | I8: 1991-12-03 | J8: =IF(I8="","",DATEDIF(I8,TODAY(),"Y")) | K8: Male | L8: Filipino | M8: Married | N8: 9 Camia Drive | P8: Laguna | Q8: City of San Pablo | R8: San Rafael | S8: 4000 | U8: gabriel.castillo@afhomes-local.test | V8: 09178462516 | X8: IT Consultant | AA8: SILVER | AB8: Installment 4_month | AC8: 2026-01-15 | AD8: 300000.00 | AE8: 0.00 | AF8: =IF(B8="","",AD8-AE8) | AG8: 10000.00 | AH8: =IF(B8="","",SUMIF('Payments'!$A$2:$A$5001,B8,'Payments'!$D$2:$D$5001)) | AI8: =IF(B8="","",AF8-AH8) | AJ8: Active | AK8: 17500 | AL8: 2026-01-17 | AM8: 2031-01-17 | AO8: 4 | AP8: Standard
A9: 2025-0788 | B9: 25050100612S1T12N | D9: Expired | E9: Sofia | F9: Mercado | G9: Domingo | I9: 1986-08-15 | J9: =IF(I9="","",DATEDIF(I9,TODAY(),"Y")) | K9: Female | L9: Filipino | M9: Single | N9: 56 Molave Street | P9: Cavite | Q9: Silang | R9: Biga I | S9: 4118 | U9: sofia.mercado@afhomes-local.test | V9: 09178462517 | X9: Teacher | AA9: SILVER | AB9: Move b1 40 12 | AC9: 2025-05-01 | AD9: 300000.00 | AE9: 0.00 | AF9: =IF(B9="","",AD9-AE9) | AG9: 10000.00 | AH9: =IF(B9="","",SUMIF('Payments'!$A$2:$A$5001,B9,'Payments'!$D$2:$D$5001)) | AI9: =IF(B9="","",AF9-AH9) | AJ9: Expired | AK9: 4000 | AL9: 2025-05-03 | AM9: 2026-05-03 | AO9: 12 | AP9: Non-Standard
D10: Suspended | E10: Adrian | F10: Fernandez | G10: Gonzales | I10: 1980-04-29 | J10: =IF(I10="","",DATEDIF(I10,TODAY(),"Y")) | K10: Male | L10: Filipino | M10: Married | N10: 14 Yakal Avenue | P10: Batangas | Q10: City of Tanauan | R10: Darasa | S10: 4232 | U10: adrian.fernandez@afhomes-local.test | V10: 09178462518 | X10: Entrepreneur | AA10: BRONZE | AB10: Move a | AC10: 2026-01-15 | AD10: 60000.00 | AE10: 0.00 | AF10: =IF(B10="","",AD10-AE10) | AG10: 10000.00 | AH10: =IF(B10="","",SUMIF('Payments'!$A$2:$A$5001,B10,'Payments'!$D$2:$D$5001)) | AI10: =IF(B10="","",AF10-AH10) | AJ10: Suspended | AK10: 4000 | AL10: 2026-01-17 | AM10: 2031-01-17 | AO10: 1 | AP10: Standard
A11: 2025-0790 | D11: Cancelled | E11: Beatrice | F11: Salazar | G11: Dizon | I11: 1994-10-09 | J11: =IF(I11="","",DATEDIF(I11,TODAY(),"Y")) | K11: Female | L11: Filipino | M11: Single | N11: 88 Jasmine Street | P11: Bulacan | Q11: Santa Maria | R11: Poblacion | S11: 3022 | U11: beatrice.salazar@afhomes-local.test | V11: 09178462519 | X11: Physical Therapist | AA11: GOLD | AB11: Move b2 25 12 | AC11: 2026-01-15 | AD11: 384000.00 | AE11: 0.00 | AF11: =IF(B11="","",AD11-AE11) | AG11: 10000.00 | AH11: =IF(B11="","",SUMIF('Payments'!$A$2:$A$5001,B11,'Payments'!$D$2:$D$5001)) | AI11: =IF(B11="","",AF11-AH11) | AJ11: Cancelled | AK11: 4000 | AL11: 2026-01-17 | AM11: 2031-01-17 | AO11: 12 | AP11: Standard
J12: =IF(I12="","",DATEDIF(I12,TODAY(),"Y")) | S12: =IF(P12="","",IFERROR(VLOOKUP(P12&"|"&Q12&"|"&R12,'Postal Codes'!$A$2:$B$1516,2,FALSE),IFERROR(VLOOKUP(P12&"|"&Q12,'Postal Codes'!$A$2:$B$1516,2,FALSE),""))) | AF12: =IF(B12="","",AD12-AE12) | AH12: =IF(B12="","",SUMIF('Payments'!$A$2:$A$5001,B12,'Payments'!$D$2:$D$5001)) | AI12: =IF(B12="","",AF12-AH12)
J13: =IF(I13="","",DATEDIF(I13,TODAY(),"Y")) | S13: =IF(P13="","",IFERROR(VLOOKUP(P13&"|"&Q13&"|"&R13,'Postal Codes'!$A$2:$B$1516,2,FALSE),IFERROR(VLOOKUP(P13&"|"&Q13,'Postal Codes'!$A$2:$B$1516,2,FALSE),""))) | AF13: =IF(B13="","",AD13-AE13) | AH13: =IF(B13="","",SUMIF('Payments'!$A$2:$A$5001,B13,'Payments'!$D$2:$D$5001)) | AI13: =IF(B13="","",AF13-AH13)
J14: =IF(I14="","",DATEDIF(I14,TODAY(),"Y")) | S14: =IF(P14="","",IFERROR(VLOOKUP(P14&"|"&Q14&"|"&R14,'Postal Codes'!$A$2:$B$1516,2,FALSE),IFERROR(VLOOKUP(P14&"|"&Q14,'Postal Codes'!$A$2:$B$1516,2,FALSE),""))) | AF14: =IF(B14="","",AD14-AE14) | AH14: =IF(B14="","",SUMIF('Payments'!$A$2:$A$5001,B14,'Payments'!$D$2:$D$5001)) | AI14: =IF(B14="","",AF14-AH14)
J15: =IF(I15="","",DATEDIF(I15,TODAY(),"Y")) | S15: =IF(P15="","",IFERROR(VLOOKUP(P15&"|"&Q15&"|"&R15,'Postal Codes'!$A$2:$B$1516,2,FALSE),IFERROR(VLOOKUP(P15&"|"&Q15,'Postal Codes'!$A$2:$B$1516,2,FALSE),""))) | AF15: =IF(B15="","",AD15-AE15) | AH15: =IF(B15="","",SUMIF('Payments'!$A$2:$A$5001,B15,'Payments'!$D$2:$D$5001)) | AI15: =IF(B15="","",AF15-AH15)
J16: =IF(I16="","",DATEDIF(I16,TODAY(),"Y")) | S16: =IF(P16="","",IFERROR(VLOOKUP(P16&"|"&Q16&"|"&R16,'Postal Codes'!$A$2:$B$1516,2,FALSE),IFERROR(VLOOKUP(P16&"|"&Q16,'Postal Codes'!$A$2:$B$1516,2,FALSE),""))) | AF16: =IF(B16="","",AD16-AE16) | AH16: =IF(B16="","",SUMIF('Payments'!$A$2:$A$5001,B16,'Payments'!$D$2:$D$5001)) | AI16: =IF(B16="","",AF16-AH16)
J17: =IF(I17="","",DATEDIF(I17,TODAY(),"Y")) | S17: =IF(P17="","",IFERROR(VLOOKUP(P17&"|"&Q17&"|"&R17,'Postal Codes'!$A$2:$B$1516,2,FALSE),IFERROR(VLOOKUP(P17&"|"&Q17,'Postal Codes'!$A$2:$B$1516,2,FALSE),""))) | AF17: =IF(B17="","",AD17-AE17) | AH17: =IF(B17="","",SUMIF('Payments'!$A$2:$A$5001,B17,'Payments'!$D$2:$D$5001)) | AI17: =IF(B17="","",AF17-AH17)
J18: =IF(I18="","",DATEDIF(I18,TODAY(),"Y")) | S18: =IF(P18="","",IFERROR(VLOOKUP(P18&"|"&Q18&"|"&R18,'Postal Codes'!$A$2:$B$1516,2,FALSE),IFERROR(VLOOKUP(P18&"|"&Q18,'Postal Codes'!$A$2:$B$1516,2,FALSE),""))) | AF18: =IF(B18="","",AD18-AE18) | AH18: =IF(B18="","",SUMIF('Payments'!$A$2:$A$5001,B18,'Payments'!$D$2:$D$5001)) | AI18: =IF(B18="","",AF18-AH18)
J19: =IF(I19="","",DATEDIF(I19,TODAY(),"Y")) | S19: =IF(P19="","",IFERROR(VLOOKUP(P19&"|"&Q19&"|"&R19,'Postal Codes'!$A$2:$B$1516,2,FALSE),IFERROR(VLOOKUP(P19&"|"&Q19,'Postal Codes'!$A$2:$B$1516,2,FALSE),""))) | AF19: =IF(B19="","",AD19-AE19) | AH19: =IF(B19="","",SUMIF('Payments'!$A$2:$A$5001,B19,'Payments'!$D$2:$D$5001)) | AI19: =IF(B19="","",AF19-AH19)
J20: =IF(I20="","",DATEDIF(I20,TODAY(),"Y")) | S20: =IF(P20="","",IFERROR(VLOOKUP(P20&"|"&Q20&"|"&R20,'Postal Codes'!$A$2:$B$1516,2,FALSE),IFERROR(VLOOKUP(P20&"|"&Q20,'Postal Codes'!$A$2:$B$1516,2,FALSE),""))) | AF20: =IF(B20="","",AD20-AE20) | AH20: =IF(B20="","",SUMIF('Payments'!$A$2:$A$5001,B20,'Payments'!$D$2:$D$5001)) | AI20: =IF(B20="","",AF20-AH20)
J21: =IF(I21="","",DATEDIF(I21,TODAY(),"Y")) | S21: =IF(P21="","",IFERROR(VLOOKUP(P21&"|"&Q21&"|"&R21,'Postal Codes'!$A$2:$B$1516,2,FALSE),IFERROR(VLOOKUP(P21&"|"&Q21,'Postal Codes'!$A$2:$B$1516,2,FALSE),""))) | AF21: =IF(B21="","",AD21-AE21) | AH21: =IF(B21="","",SUMIF('Payments'!$A$2:$A$5001,B21,'Payments'!$D$2:$D$5001)) | AI21: =IF(B21="","",AF21-AH21)
J22: =IF(I22="","",DATEDIF(I22,TODAY(),"Y")) | S22: =IF(P22="","",IFERROR(VLOOKUP(P22&"|"&Q22&"|"&R22,'Postal Codes'!$A$2:$B$1516,2,FALSE),IFERROR(VLOOKUP(P22&"|"&Q22,'Postal Codes'!$A$2:$B$1516,2,FALSE),""))) | AF22: =IF(B22="","",AD22-AE22) | AH22: =IF(B22="","",SUMIF('Payments'!$A$2:$A$5001,B22,'Payments'!$D$2:$D$5001)) | AI22: =IF(B22="","",AF22-AH22)
J23: =IF(I23="","",DATEDIF(I23,TODAY(),"Y")) | S23: =IF(P23="","",IFERROR(VLOOKUP(P23&"|"&Q23&"|"&R23,'Postal Codes'!$A$2:$B$1516,2,FALSE),IFERROR(VLOOKUP(P23&"|"&Q23,'Postal Codes'!$A$2:$B$1516,2,FALSE),""))) | AF23: =IF(B23="","",AD23-AE23) | AH23: =IF(B23="","",SUMIF('Payments'!$A$2:$A$5001,B23,'Payments'!$D$2:$D$5001)) | AI23: =IF(B23="","",AF23-AH23)
... J101: =IF(I101="","",DATEDIF(I101,TODAY(),"Y")) | S101: =IF(P101="","",IFERROR(VLOOKUP(P101&"|"&Q101&"|"&R101,'Postal Codes'!$A$2:$B$1516,2,FALSE),IFERROR(VLOOKUP(P101&"|"&Q101,'Postal Codes'!$A$2:$B$1516,2,FALSE),""))) | AF101: =IF(B101="","",AD101-AE101) | AH101: =IF(B101="","",SUMIF('Payments'!$A$2:$A$5001,B101,'Payments'!$D$2:$D$5001)) | AI101: =IF(B101="","",AF101-AH101)

Sheet Supplementary Holders
A1: Gold purchase reference (select) | B1: First name | C1: Last name | D1: Middle name | E1: Suffix | F1: Birth date | G1: Age (calculated) | H1: Gender | I1: Citizenship | J1: Civil status | K1: Address line 1 | L1: Address line 2 | M1: Province | N1: City / Municipality | O1: Barangay | P1: Postal code | Q1: Landline (optional) | R1: Email | S1: Mobile number | T1: TIN (optional) | U1: Occupation / Business name | V1: Office / Business address | W1: Position
G2: =IF(F2="","",DATEDIF(F2,TODAY(),"Y")) | P2: =IF(M2="","",IFERROR(VLOOKUP(M2&"|"&N2&"|"&O2,'Postal Codes'!$A$2:$B$1516,2,FALSE),IFERROR(VLOOKUP(M2&"|"&N2,'Postal Codes'!$A$2:$B$1516,2,FALSE),"")))
G3: =IF(F3="","",DATEDIF(F3,TODAY(),"Y")) | P3: =IF(M3="","",IFERROR(VLOOKUP(M3&"|"&N3&"|"&O3,'Postal Codes'!$A$2:$B$1516,2,FALSE),IFERROR(VLOOKUP(M3&"|"&N3,'Postal Codes'!$A$2:$B$1516,2,FALSE),"")))
G4: =IF(F4="","",DATEDIF(F4,TODAY(),"Y")) | P4: =IF(M4="","",IFERROR(VLOOKUP(M4&"|"&N4&"|"&O4,'Postal Codes'!$A$2:$B$1516,2,FALSE),IFERROR(VLOOKUP(M4&"|"&N4,'Postal Codes'!$A$2:$B$1516,2,FALSE),"")))
G5: =IF(F5="","",DATEDIF(F5,TODAY(),"Y")) | P5: =IF(M5="","",IFERROR(VLOOKUP(M5&"|"&N5&"|"&O5,'Postal Codes'!$A$2:$B$1516,2,FALSE),IFERROR(VLOOKUP(M5&"|"&N5,'Postal Codes'!$A$2:$B$1516,2,FALSE),"")))
G6: =IF(F6="","",DATEDIF(F6,TODAY(),"Y")) | P6: =IF(M6="","",IFERROR(VLOOKUP(M6&"|"&N6&"|"&O6,'Postal Codes'!$A$2:$B$1516,2,FALSE),IFERROR(VLOOKUP(M6&"|"&N6,'Postal Codes'!$A$2:$B$1516,2,FALSE),"")))
G7: =IF(F7="","",DATEDIF(F7,TODAY(),"Y")) | P7: =IF(M7="","",IFERROR(VLOOKUP(M7&"|"&N7&"|"&O7,'Postal Codes'!$A$2:$B$1516,2,FALSE),IFERROR(VLOOKUP(M7&"|"&N7,'Postal Codes'!$A$2:$B$1516,2,FALSE),"")))
G8: =IF(F8="","",DATEDIF(F8,TODAY(),"Y")) | P8: =IF(M8="","",IFERROR(VLOOKUP(M8&"|"&N8&"|"&O8,'Postal Codes'!$A$2:$B$1516,2,FALSE),IFERROR(VLOOKUP(M8&"|"&N8,'Postal Codes'!$A$2:$B$1516,2,FALSE),"")))
G9: =IF(F9="","",DATEDIF(F9,TODAY(),"Y")) | P9: =IF(M9="","",IFERROR(VLOOKUP(M9&"|"&N9&"|"&O9,'Postal Codes'!$A$2:$B$1516,2,FALSE),IFERROR(VLOOKUP(M9&"|"&N9,'Postal Codes'!$A$2:$B$1516,2,FALSE),"")))
G10: =IF(F10="","",DATEDIF(F10,TODAY(),"Y")) | P10: =IF(M10="","",IFERROR(VLOOKUP(M10&"|"&N10&"|"&O10,'Postal Codes'!$A$2:$B$1516,2,FALSE),IFERROR(VLOOKUP(M10&"|"&N10,'Postal Codes'!$A$2:$B$1516,2,FALSE),"")))
G11: =IF(F11="","",DATEDIF(F11,TODAY(),"Y")) | P11: =IF(M11="","",IFERROR(VLOOKUP(M11&"|"&N11&"|"&O11,'Postal Codes'!$A$2:$B$1516,2,FALSE),IFERROR(VLOOKUP(M11&"|"&N11,'Postal Codes'!$A$2:$B$1516,2,FALSE),"")))
G12: =IF(F12="","",DATEDIF(F12,TODAY(),"Y")) | P12: =IF(M12="","",IFERROR(VLOOKUP(M12&"|"&N12&"|"&O12,'Postal Codes'!$A$2:$B$1516,2,FALSE),IFERROR(VLOOKUP(M12&"|"&N12,'Postal Codes'!$A$2:$B$1516,2,FALSE),"")))
G13: =IF(F13="","",DATEDIF(F13,TODAY(),"Y")) | P13: =IF(M13="","",IFERROR(VLOOKUP(M13&"|"&N13&"|"&O13,'Postal Codes'!$A$2:$B$1516,2,FALSE),IFERROR(VLOOKUP(M13&"|"&N13,'Postal Codes'!$A$2:$B$1516,2,FALSE),"")))
... G101: =IF(F101="","",DATEDIF(F101,TODAY(),"Y")) | P101: =IF(M101="","",IFERROR(VLOOKUP(M101&"|"&N101&"|"&O101,'Postal Codes'!$A$2:$B$1516,2,FALSE),IFERROR(VLOOKUP(M101&"|"&N101,'Postal Codes'!$A$2:$B$1516,2,FALSE),"")))

Sheet Sales Team
A1: Purchase reference (select customer) | B1: VD / SVD (workbook claim) | C1: SSM (workbook claim) | D1: SM (workbook claim) | E1: Referrer | F1: VIP Recommender | G1: Recommender contact | H1: Recommender email
A2: miguel.santos@afhomes-local.test | B2: Eduardo Manalo | C2: Cristina Vergara | D2: Roberto Alcantara | E2: Mariel Soriano | F2: Daniel Pineda | G2: =IFERROR(VLOOKUP(F2,'Reference Lists'!$F$2:$M$2,7,FALSE),"") | H2: =IFERROR(VLOOKUP(F2,'Reference Lists'!$F$2:$M$2,8,FALSE),"")
A3: 2025-0782 | B3: Eduardo Manalo | C3: Cristina Vergara | D3: Roberto Alcantara | E3: Mariel Soriano | F3: Daniel Pineda | G3: =IFERROR(VLOOKUP(F3,'Reference Lists'!$F$2:$M$2,7,FALSE),"") | H3: =IFERROR(VLOOKUP(F3,'Reference Lists'!$F$2:$M$2,8,FALSE),"")
A4: rafael.bautista@afhomes-local.test | B4: Eduardo Manalo | C4: Cristina Vergara | D4: Roberto Alcantara | E4: Mariel Soriano | F4: Daniel Pineda | G4: =IFERROR(VLOOKUP(F4,'Reference Lists'!$F$2:$M$2,7,FALSE),"") | H4: =IFERROR(VLOOKUP(F4,'Reference Lists'!$F$2:$M$2,8,FALSE),"")
A5: 2025-0784 | B5: Eduardo Manalo | C5: Cristina Vergara | D5: Roberto Alcantara | E5: Mariel Soriano | F5: Daniel Pineda | G5: =IFERROR(VLOOKUP(F5,'Reference Lists'!$F$2:$M$2,7,FALSE),"") | H5: =IFERROR(VLOOKUP(F5,'Reference Lists'!$F$2:$M$2,8,FALSE),"")
A6: lorenzo.aquino@afhomes-local.test | B6: Eduardo Manalo | C6: Cristina Vergara | D6: Roberto Alcantara | E6: Mariel Soriano | F6: Daniel Pineda | G6: =IFERROR(VLOOKUP(F6,'Reference Lists'!$F$2:$M$2,7,FALSE),"") | H6: =IFERROR(VLOOKUP(F6,'Reference Lists'!$F$2:$M$2,8,FALSE),"")
A7: 26011500841G1C01S | B7: Eduardo Manalo | C7: Cristina Vergara | D7: Roberto Alcantara | E7: Mariel Soriano | F7: Daniel Pineda | G7: =IFERROR(VLOOKUP(F7,'Reference Lists'!$F$2:$M$2,7,FALSE),"") | H7: =IFERROR(VLOOKUP(F7,'Reference Lists'!$F$2:$M$2,8,FALSE),"")
A8: gabriel.castillo@afhomes-local.test | B8: Eduardo Manalo | C8: Cristina Vergara | D8: Roberto Alcantara | E8: Mariel Soriano | F8: Daniel Pineda | G8: =IFERROR(VLOOKUP(F8,'Reference Lists'!$F$2:$M$2,7,FALSE),"") | H8: =IFERROR(VLOOKUP(F8,'Reference Lists'!$F$2:$M$2,8,FALSE),"")
A9: 25050100612S1T12N | B9: Eduardo Manalo | C9: Cristina Vergara | D9: Roberto Alcantara | E9: Mariel Soriano | F9: Daniel Pineda | G9: =IFERROR(VLOOKUP(F9,'Reference Lists'!$F$2:$M$2,7,FALSE),"") | H9: =IFERROR(VLOOKUP(F9,'Reference Lists'!$F$2:$M$2,8,FALSE),"")
A10: adrian.fernandez@afhomes-local.test | B10: Eduardo Manalo | C10: Cristina Vergara | D10: Roberto Alcantara | E10: Mariel Soriano | F10: Daniel Pineda | G10: =IFERROR(VLOOKUP(F10,'Reference Lists'!$F$2:$M$2,7,FALSE),"") | H10: =IFERROR(VLOOKUP(F10,'Reference Lists'!$F$2:$M$2,8,FALSE),"")
A11: 2025-0790 | B11: Eduardo Manalo | C11: Cristina Vergara | D11: Roberto Alcantara | E11: Mariel Soriano | F11: Daniel Pineda | G11: =IFERROR(VLOOKUP(F11,'Reference Lists'!$F$2:$M$2,7,FALSE),"") | H11: =IFERROR(VLOOKUP(F11,'Reference Lists'!$F$2:$M$2,8,FALSE),"")
G12: =IFERROR(VLOOKUP(F12,'Reference Lists'!$F$2:$M$2,7,FALSE),"") | H12: =IFERROR(VLOOKUP(F12,'Reference Lists'!$F$2:$M$2,8,FALSE),"")
G13: =IFERROR(VLOOKUP(F13,'Reference Lists'!$F$2:$M$2,7,FALSE),"") | H13: =IFERROR(VLOOKUP(F13,'Reference Lists'!$F$2:$M$2,8,FALSE),"")
G14: =IFERROR(VLOOKUP(F14,'Reference Lists'!$F$2:$M$2,7,FALSE),"") | H14: =IFERROR(VLOOKUP(F14,'Reference Lists'!$F$2:$M$2,8,FALSE),"")
G15: =IFERROR(VLOOKUP(F15,'Reference Lists'!$F$2:$M$2,7,FALSE),"") | H15: =IFERROR(VLOOKUP(F15,'Reference Lists'!$F$2:$M$2,8,FALSE),"")
G16: =IFERROR(VLOOKUP(F16,'Reference Lists'!$F$2:$M$2,7,FALSE),"") | H16: =IFERROR(VLOOKUP(F16,'Reference Lists'!$F$2:$M$2,8,FALSE),"")
G17: =IFERROR(VLOOKUP(F17,'Reference Lists'!$F$2:$M$2,7,FALSE),"") | H17: =IFERROR(VLOOKUP(F17,'Reference Lists'!$F$2:$M$2,8,FALSE),"")
G18: =IFERROR(VLOOKUP(F18,'Reference Lists'!$F$2:$M$2,7,FALSE),"") | H18: =IFERROR(VLOOKUP(F18,'Reference Lists'!$F$2:$M$2,8,FALSE),"")
G19: =IFERROR(VLOOKUP(F19,'Reference Lists'!$F$2:$M$2,7,FALSE),"") | H19: =IFERROR(VLOOKUP(F19,'Reference Lists'!$F$2:$M$2,8,FALSE),"")
G20: =IFERROR(VLOOKUP(F20,'Reference Lists'!$F$2:$M$2,7,FALSE),"") | H20: =IFERROR(VLOOKUP(F20,'Reference Lists'!$F$2:$M$2,8,FALSE),"")
G21: =IFERROR(VLOOKUP(F21,'Reference Lists'!$F$2:$M$2,7,FALSE),"") | H21: =IFERROR(VLOOKUP(F21,'Reference Lists'!$F$2:$M$2,8,FALSE),"")
G22: =IFERROR(VLOOKUP(F22,'Reference Lists'!$F$2:$M$2,7,FALSE),"") | H22: =IFERROR(VLOOKUP(F22,'Reference Lists'!$F$2:$M$2,8,FALSE),"")
G23: =IFERROR(VLOOKUP(F23,'Reference Lists'!$F$2:$M$2,7,FALSE),"") | H23: =IFERROR(VLOOKUP(F23,'Reference Lists'!$F$2:$M$2,8,FALSE),"")
... G101: =IFERROR(VLOOKUP(F101,'Reference Lists'!$F$2:$M$2,7,FALSE),"") | H101: =IFERROR(VLOOKUP(F101,'Reference Lists'!$F$2:$M$2,8,FALSE),"")

Sheet Payments
A1: Purchase reference (select customer) | B1: Payment claim reference (optional) | C1: Purpose | D1: Amount paid (claimed) | E1: Payment date | F1: Payment method | G1: Receipt / Bank reference | H1: Notes
A2: 2025-0782 | B2: RC-261002-1042 | C2: Reservation fee | D2: 10000.00 | E2: 2026-10-02 | F2: Bank transfer | G2: RC-261002-1042 | H2: Payment confirmed against archived receipt.
A3: rafael.bautista@afhomes-local.test | B3: RC-261002-1043 | C3: Down payment | D3: 30000.00 | E3: 2026-10-02 | F3: Cash | G3: RC-261002-1043 | H3: Payment confirmed against archived receipt.
A4: 2025-0784 | B4: RC-261002-1044 | C4: Down payment | D4: 120000.00 | E4: 2026-10-02 | F4: Bank transfer | G4: RC-261002-1044 | H4: Payment confirmed against archived receipt.
A5: lorenzo.aquino@afhomes-local.test | B5: RC-261002-1045 | C5: Full payment | D5: 384000.00 | E5: 2026-10-02 | F5: Cash | G5: RC-261002-1045 | H5: Payment confirmed against archived receipt.

Sheet Reference Lists
A1: VD / SVD | B1: SSM | C1: SM | D1: OST | F1: Registered staff | G1: Role | H1: AA number | I1: VD tree | J1: SSM | K1: SM | L1: Contact number | M1: Email | P1: Customer link: VIP ID / Customer ID / email
P2: =IF('Customers'!B2<>"",'Customers'!B2,IF('Customers'!A2<>"",'Customers'!A2,IF('Customers'!U2<>"",'Customers'!U2,"")))
P3: =IF('Customers'!B3<>"",'Customers'!B3,IF('Customers'!A3<>"",'Customers'!A3,IF('Customers'!U3<>"",'Customers'!U3,"")))
P4: =IF('Customers'!B4<>"",'Customers'!B4,IF('Customers'!A4<>"",'Customers'!A4,IF('Customers'!U4<>"",'Customers'!U4,"")))
P5: =IF('Customers'!B5<>"",'Customers'!B5,IF('Customers'!A5<>"",'Customers'!A5,IF('Customers'!U5<>"",'Customers'!U5,"")))
P6: =IF('Customers'!B6<>"",'Customers'!B6,IF('Customers'!A6<>"",'Customers'!A6,IF('Customers'!U6<>"",'Customers'!U6,"")))
P7: =IF('Customers'!B7<>"",'Customers'!B7,IF('Customers'!A7<>"",'Customers'!A7,IF('Customers'!U7<>"",'Customers'!U7,"")))
P8: =IF('Customers'!B8<>"",'Customers'!B8,IF('Customers'!A8<>"",'Customers'!A8,IF('Customers'!U8<>"",'Customers'!U8,"")))
P9: =IF('Customers'!B9<>"",'Customers'!B9,IF('Customers'!A9<>"",'Customers'!A9,IF('Customers'!U9<>"",'Customers'!U9,"")))
P10: =IF('Customers'!B10<>"",'Customers'!B10,IF('Customers'!A10<>"",'Customers'!A10,IF('Customers'!U10<>"",'Customers'!U10,"")))
P11: =IF('Customers'!B11<>"",'Customers'!B11,IF('Customers'!A11<>"",'Customers'!A11,IF('Customers'!U11<>"",'Customers'!U11,"")))
P12: =IF('Customers'!B12<>"",'Customers'!B12,IF('Customers'!A12<>"",'Customers'!A12,IF('Customers'!U12<>"",'Customers'!U12,"")))
P13: =IF('Customers'!B13<>"",'Customers'!B13,IF('Customers'!A13<>"",'Customers'!A13,IF('Customers'!U13<>"",'Customers'!U13,"")))
... P101: =IF('Customers'!B101<>"",'Customers'!B101,IF('Customers'!A101<>"",'Customers'!A101,IF('Customers'!U101<>"",'Customers'!U101,"")))

Sheet Address Lists
A1: Address group | B1: List reference | C1: Choices
A2: Abra | B2: AFHomesCities0 | C2: Bangued | D2: Boliney | E2: Bucay | F2: Bucloc | G2: Daguioman | H2: Danglas | I2: Dolores | J2: La Paz | K2: Lacub | L2: Lagangilang | M2: Lagayan | N2: Langiden | O2: Licuan-Baay | P2: Luba | Q2: Malibcong | R2: Manabo | S2: Peñarrubia | T2: Pidigan | U2: Pilar | V2: Sallapadan | W2: San Isidro | X2: San Juan | Y2: San Quintin | Z2: Tayum | AA2: Tineg | AB2: Tubo | AC2: Villaviciosa
A3: Agusan del Norte | B3: AFHomesCities1 | C3: Buenavista | D3: Carmen | E3: City of Butuan | F3: City of Cabadbaran | G3: Jabonga | H3: Kitcharao | I3: Las Nieves | J3: Magallanes | K3: Nasipit | L3: Remedios T. Romualdez | M3: Santiago | N3: Tubay
A4: Agusan del Sur | B4: AFHomesCities2 | C4: Bunawan | D4: City of Bayugan | E4: Esperanza | F4: La Paz | G4: Loreto | H4: Prosperidad | I4: Rosario | J4: San Francisco | K4: San Luis | L4: Santa Josefa | M4: Sibagat | N4: Talacogon | O4: Trento | P4: Veruela
A5: Aklan | B5: AFHomesCities3 | C5: Altavas | D5: Balete | E5: Banga | F5: Batan | G5: Buruanga | H5: Ibajay | I5: Kalibo | J5: Lezo | K5: Libacao | L5: Madalag | M5: Makato | N5: Malay | O5: Malinao | P5: Nabas | Q5: New Washington | R5: Numancia | S5: Tangalan
A6: Albay | B6: AFHomesCities4 | C6: Bacacay | D6: Camalig | E6: City of Legazpi | F6: City of Ligao | G6: City of Tabaco | H6: Daraga | I6: Guinobatan | J6: Jovellar | K6: Libon | L6: Malilipot | M6: Malinao | N6: Manito | O6: Oas | P6: Pio Duran | Q6: Polangui | R6: Rapu-Rapu | S6: Santo Domingo | T6: Tiwi
A7: Antique | B7: AFHomesCities5 | C7: Anini-Y | D7: Barbaza | E7: Belison | F7: Bugasong | G7: Caluya | H7: Culasi | I7: Hamtic | J7: Laua-An | K7: Libertad | L7: Pandan | M7: Patnongon | N7: San Jose | O7: San Remigio | P7: Sebaste | Q7: Sibalom | R7: Tibiao | S7: Tobias Fornier | T7: Valderrama
A8: Apayao | B8: AFHomesCities6 | C8: Calanasan | D8: Conner | E8: Flora | F8: Kabugao | G8: Luna | H8: Pudtol | I8: Santa Marcela
A9: Aurora | B9: AFHomesCities7 | C9: Baler | D9: Casiguran | E9: Dilasag | F9: Dinalungan | G9: Dingalan | H9: Dipaculao | I9: Maria Aurora | J9: San Luis
A10: Basilan | B10: AFHomesCities8 | C10: Akbar | D10: Al-Barka | E10: City of Lamitan | F10: Hadji Mohammad Ajul | G10: Hadji Muhtamad | H10: Lantawan | I10: Maluso | J10: Sumisip | K10: Tabuan-Lasa | L10: Tipo-Tipo | M10: Tuburan | N10: Ungkaya Pukan
A11: Bataan | B11: AFHomesCities9 | C11: Abucay | D11: Bagac | E11: City of Balanga | F11: Dinalupihan | G11: Hermosa | H11: Limay | I11: Mariveles | J11: Morong | K11: Orani | L11: Orion | M11: Pilar | N11: Samal
A12: Batanes | B12: AFHomesCities10 | C12: Basco | D12: Itbayat | E12: Ivana | F12: Mahatao | G12: Sabtang | H12: Uyugan
A13: Batangas | B13: AFHomesCities11 | C13: Agoncillo | D13: Alitagtag | E13: Balayan | F13: Balete | G13: Batangas City | H13: Bauan | I13: Calatagan | J13: City of Calaca | K13: City of Lipa | L13: City of Sto. Tomas | M13: City of Tanauan | N13: Cuenca | O13: Ibaan | P13: Laurel | Q13: Lemery | R13: Lian | S13: Lobo | T13: Mabini | U13: Malvar | V13: Mataasnakahoy | W13: Nasugbu | X13: Padre Garcia | Y13: Rosario | Z13: San Jose | AA13: San Juan | AB13: San Luis | AC13: San Nicolas | AD13: San Pascual | AE13: Santa Teresita | AF13: Taal | AG13: Talisay | AH13: Taysan | AI13: Tingloy | AJ13: Tuy
A14: Benguet | B14: AFHomesCities12 | C14: Atok | D14: Bakun | E14: Bokod | F14: Buguias | G14: City of Baguio | H14: Itogon | I14: Kabayan | J14: Kapangan | K14: Kibungan | L14: La Trinidad | M14: Mankayan | N14: Sablan | O14: Tuba | P14: Tublay
A15: Biliran | B15: AFHomesCities13 | C15: Almeria | D15: Biliran | E15: Cabucgayan | F15: Caibiran | G15: Culaba | H15: Kawayan | I15: Maripipi | J15: Naval
A16: Bohol | B16: AFHomesCities14 | C16: Alburquerque | D16: Alicia | E16: Anda | F16: Antequera | G16: Baclayon | H16: Balilihan | I16: Batuan | J16: Bien Unido | K16: Bilar | L16: Buenavista | M16: Calape | N16: Candijay | O16: Carmen | P16: Catigbian | Q16: City of Tagbilaran | R16: Clarin | S16: Corella | T16: Cortes | U16: Dagohoy | V16: Danao | W16: Dauis | X16: Dimiao | Y16: Duero | Z16: Garcia Hernandez | AA16: Getafe | AB16: Guindulman | AC16: Inabanga | AD16: Jagna | AE16: Lila | AF16: Loay | AG16: Loboc | AH16: Loon | AI16: Mabini | AJ16: Maribojoc | AK16: Panglao | AL16: Pilar | AM16: President Carlos P. Garcia | AN16: Sagbayan | AO16: San Isidro | AP16: San Miguel | AQ16: Sevilla | AR16: Sierra Bullones | AS16: Sikatuna | AT16: Talibon | AU16: Trinidad | AV16: Tubigon | AW16: Ubay | AX16: Valencia
A17: Bukidnon | B17: AFHomesCities15 | C17: Baungon | D17: Cabanglasan | E17: City of Malaybalay | F17: City of Valencia | G17: Damulog | H17: Dangcagan | I17: Don Carlos | J17: Impasug-ong | K17: Kadingilan | L17: Kalilangan | M17: Kibawe | N17: Kitaotao | O17: Lantapan | P17: Libona | Q17: Malitbog | R17: Manolo Fortich | S17: Maramag | T17: Pangantucan | U17: Quezon | V17: San Fernando | W17: Sumilao | X17: Talakag
A18: Bulacan | B18: AFHomesCities16 | C18: Angat | D18: Balagtas | E18: Bocaue | F18: Bulacan | G18: Bustos | H18: Calumpit | I18: City of Baliwag | J18: City of Malolos | K18: City of Meycauayan | L18: City of San Jose Del Monte | M18: Doña Remedios Trinidad | N18: Guiguinto | O18: Hagonoy | P18: Marilao | Q18: Norzagaray | R18: Obando | S18: Pandi | T18: Paombong | U18: Plaridel | V18: Pulilan | W18: San Ildefonso | X18: San Miguel | Y18: San Rafael | Z18: Santa Maria
A19: Cagayan | B19: AFHomesCities17 | C19: Abulug | D19: Alcala | E19: Allacapan | F19: Amulung | G19: Aparri | H19: Baggao | I19: Ballesteros | J19: Buguey | K19: Calayan | L19: Camalaniugan | M19: Claveria | N19: Enrile | O19: Gattaran | P19: Gonzaga | Q19: Iguig | R19: Lal-Lo | S19: Lasam | T19: Pamplona | U19: Peñablanca | V19: Piat | W19: Rizal | X19: Sanchez-Mira | Y19: Santa Ana | Z19: Santa Praxedes | AA19: Santa Teresita | AB19: Santo Niño | AC19: Solana | AD19: Tuao | AE19: Tuguegarao City
A20: Camarines Norte | B20: AFHomesCities18 | C20: Basud | D20: Capalonga | E20: Daet | F20: Jose Panganiban | G20: Labo | H20: Mercedes | I20: Paracale | J20: San Lorenzo Ruiz | K20: San Vicente | L20: Santa Elena | M20: Talisay | N20: Vinzons
A21: Camarines Sur | B21: AFHomesCities19 | C21: Baao | D21: Balatan | E21: Bato | F21: Bombon | G21: Buhi | H21: Bula | I21: Cabusao | J21: Calabanga | K21: Camaligan | L21: Canaman | M21: Caramoan | N21: City of Iriga | O21: City of Naga | P21: Del Gallego | Q21: Gainza | R21: Garchitorena | S21: Goa | T21: Lagonoy | U21: Libmanan | V21: Lupi | W21: Magarao | X21: Milaor | Y21: Minalabac | Z21: Nabua | AA21: Ocampo | AB21: Pamplona | AC21: Pasacao | AD21: Pili | AE21: Presentacion | AF21: Ragay | AG21: Sagñay | AH21: San Fernando | AI21: San Jose | AJ21: Sipocot | AK21: Siruma | AL21: Tigaon | AM21: Tinambac
A22: Camiguin | B22: AFHomesCities20 | C22: Catarman | D22: Guinsiliban | E22: Mahinog | F22: Mambajao | G22: Sagay
A23: Capiz | B23: AFHomesCities21 | C23: City of Roxas | D23: Cuartero | E23: Dao | F23: Dumalag | G23: Dumarao | H23: Ivisan | I23: Jamindan | J23: Ma-Ayon | K23: Mambusao | L23: Panay | M23: Panitan | N23: Pilar | O23: Pontevedra | P23: President Roxas | Q23: Sapi-An | R23: Sigma | S23: Tapaz
A24: Catanduanes | B24: AFHomesCities22 | C24: Bagamanoc | D24: Baras | E24: Bato | F24: Caramoran | G24: Gigmoto | H24: Pandan | I24: Panganiban | J24: San Andres | K24: San Miguel | L24: Viga | M24: Virac
A25: Cavite | B25: AFHomesCities23 | C25: Alfonso | D25: Amadeo | E25: Carmona | F25: City of Bacoor | G25: City of Cavite | H25: City of Dasmariñas | I25: City of General Trias | J25: City of Imus | K25: City of Tagaytay | L25: City of Trece Martires | M25: Gen. Mariano Alvarez | N25: General Emilio Aguinaldo | O25: Indang | P25: Kawit | Q25: Magallanes | R25: Maragondon | S25: Mendez | T25: Naic | U25: Noveleta | V25: Rosario | W25: Silang | X25: Tanza | Y25: Ternate
A26: Cebu | B26: AFHomesCities24 | C26: Alcantara | D26: Alcoy | E26: Alegria | F26: Aloguinsan | G26: Argao | H26: Asturias | I26: Badian | J26: Balamban | K26: Bantayan | L26: Barili | M26: Boljoon | N26: Borbon | O26: Carmen | P26: Catmon | Q26: City of Bogo | R26: City of Carcar | S26: City of Cebu | T26: City of Lapu-Lapu | U26: City of Mandaue | V26: City of Naga | W26: City of Talisay | X26: City of Toledo | Y26: Compostela | Z26: Consolacion | AA26: Cordova | AB26: Daanbantayan | AC26: Dalaguete | AD26: Danao City | AE26: Dumanjug | AF26: Ginatilan | AG26: Liloan | AH26: Madridejos | AI26: Malabuyoc | AJ26: Medellin | AK26: Minglanilla | AL26: Moalboal | AM26: Oslob | AN26: Pilar | AO26: Pinamungajan | AP26: Poro | AQ26: Ronda | AR26: Samboan | AS26: San Fernando | AT26: San Francisco | AU26: San Remigio | AV26: Santa Fe | AW26: Santander | AX26: Sibonga | AY26: Sogod | AZ26: Tabogon | BA26: Tabuelan | BB26: Tuburan | BC26: Tudela
A27: Cotabato | B27: AFHomesCities25 | C27: Alamada | D27: Aleosan | E27: Antipas | F27: Arakan | G27: Banisilan | H27: Carmen | I27: City of Kidapawan | J27: Kabacan | K27: Libungan | L27: M'Lang | M27: Magpet | N27: Makilala | O27: Matalam | P27: Midsayap | Q27: Pigkawayan | R27: Pikit | S27: President Roxas | T27: Tulunan
A28: Davao Occidental | B28: AFHomesCities26 | C28: Don Marcelino | D28: Jose Abad Santos | E28: Malita | F28: Santa Maria | G28: Sarangani
A29: Davao Oriental | B29: AFHomesCities27 | C29: Baganga | D29: Banaybanay | E29: Boston | F29: Caraga | G29: Cateel | H29: City of Mati | I29: Governor Generoso | J29: Lupon | K29: Manay | L29: San Isidro | M29: Tarragona
A30: Davao de Oro | B30: AFHomesCities28 | C30: Compostela | D30: Laak | E30: Mabini | F30: Maco | G30: Maragusan | H30: Mawab | I30: Monkayo | J30: Montevista | K30: Nabunturan | L30: New Bataan | M30: Pantukan
A31: Davao del Norte | B31: AFHomesCities29 | C31: Asuncion | D31: Braulio E. Dujali | E31: Carmen | F31: City of Panabo | G31: City of Tagum | H31: Island Garden City of Samal | I31: Kapalong | J31: New Corella | K31: San Isidro | L31: Santo Tomas | M31: Talaingod
A32: Davao del Sur | B32: AFHomesCities30 | C32: Bansalan | D32: City of Davao | E32: City of Digos | F32: Hagonoy | G32: Kiblawan | H32: Magsaysay | I32: Malalag | J32: Matanao | K32: Padada | L32: Santa Cruz | M32: Sulop
A33: Dinagat Islands | B33: AFHomesCities31 | C33: Basilisa | D33: Cagdianao | E33: Dinagat | F33: Libjo | G33: Loreto | H33: San Jose | I33: Tubajon
A34: Eastern Samar | B34: AFHomesCities32 | C34: Arteche | D34: Balangiga | E34: Balangkayan | F34: Can-Avid | G34: City of Borongan | H34: Dolores | I34: General Macarthur | J34: Giporlos | K34: Guiuan | L34: Hernani | M34: Jipapad | N34: Lawaan | O34: Llorente | P34: Maslog | Q34: Maydolong | R34: Mercedes | S34: Oras | T34: Quinapondan | U34: Salcedo | V34: San Julian | W34: San Policarpo | X34: Sulat | Y34: Taft
A35: Guimaras | B35: AFHomesCities33 | C35: Buenavista | D35: Jordan | E35: Nueva Valencia | F35: San Lorenzo | G35: Sibunag
A36: Ifugao | B36: AFHomesCities34 | C36: Aguinaldo | D36: Alfonso Lista | E36: Asipulo | F36: Banaue | G36: Hingyon | H36: Hungduan | I36: Kiangan | J36: Lagawe | K36: Lamut | L36: Mayoyao | M36: Tinoc
A37: Ilocos Norte | B37: AFHomesCities35 | C37: Adams | D37: Bacarra | E37: Badoc | F37: Bangui | G37: Banna | H37: Burgos | I37: Carasi | J37: City of Batac | K37: City of Laoag | L37: Currimao | M37: Dingras | N37: Dumalneg | O37: Marcos | P37: Nueva Era | Q37: Pagudpud | R37: Paoay | S37: Pasuquin | T37: Piddig | U37: Pinili | V37: San Nicolas | W37: Sarrat | X37: Solsona | Y37: Vintar
A38: Ilocos Sur | B38: AFHomesCities36 | C38: Alilem | D38: Banayoyo | E38: Bantay | F38: Burgos | G38: Cabugao | H38: Caoayan | I38: Cervantes | J38: City of Candon | K38: City of Vigan | L38: Galimuyod | M38: Gregorio del Pilar | N38: Lidlidda | O38: Magsingal | P38: Nagbukel | Q38: Narvacan | R38: Quirino | S38: Salcedo | T38: San Emilio | U38: San Esteban | V38: San Ildefonso | W38: San Juan | X38: San Vicente | Y38: Santa | Z38: Santa Catalina | AA38: Santa Cruz | AB38: Santa Lucia | AC38: Santa Maria | AD38: Santiago | AE38: Santo Domingo | AF38: Sigay | AG38: Sinait | AH38: Sugpon | AI38: Suyo | AJ38: Tagudin
A39: Iloilo | B39: AFHomesCities37 | C39: Ajuy | D39: Alimodian | E39: Anilao | F39: Badiangan | G39: Balasan | H39: Banate | I39: Barotac Nuevo | J39: Barotac Viejo | K39: Batad | L39: Bingawan | M39: Cabatuan | N39: Calinog | O39: Carles | P39: City of Iloilo | Q39: City of Passi | R39: Concepcion | S39: Dingle | T39: Dueñas | U39: Dumangas | V39: Estancia | W39: Guimbal | X39: Igbaras | Y39: Janiuay | Z39: Lambunao | AA39: Leganes | AB39: Lemery | AC39: Leon | AD39: Maasin | AE39: Miagao | AF39: Mina | AG39: New Lucena | AH39: Oton | AI39: Pavia | AJ39: Pototan | AK39: San Dionisio | AL39: San Enrique | AM39: San Joaquin | AN39: San Miguel | AO39: San Rafael | AP39: Santa Barbara | AQ39: Sara | AR39: Tigbauan | AS39: Tubungan | AT39: Zarraga
A40: Isabela | B40: AFHomesCities38 | C40: Alicia | D40: Angadanan | E40: Aurora | F40: Benito Soliven | G40: Burgos | H40: Cabagan | I40: Cabatuan | J40: City of Cauayan | K40: City of Ilagan | L40: City of Santiago | M40: Cordon | N40: Delfin Albano | O40: Dinapigue | P40: Divilacan | Q40: Echague | R40: Gamu | S40: Jones | T40: Luna | U40: Maconacon | V40: Mallig | W40: Naguilian | X40: Palanan | Y40: Quezon | Z40: Quirino | AA40: Ramon | AB40: Reina Mercedes | AC40: Roxas | AD40: San Agustin | AE40: San Guillermo | AF40: San Isidro | AG40: San Manuel | AH40: San Mariano | AI40: San Mateo | AJ40: San Pablo | AK40: Santa Maria | AL40: Santo Tomas | AM40: Tumauini
...

Sheet Postal Codes
A1: Address | B1: Verified postal code
A2: Abra|Bangued | B2: 2800
A3: Abra|Boliney | B3: 2815
A4: Abra|Bucay | B4: 2805
A5: Abra|Bucloc | B5: 2817
A6: Abra|Daguioman | B6: 2816
A7: Abra|Danglas | B7: 2825
A8: Abra|Dolores | B8: 2801
A9: Abra|La Paz | B9: 2826
A10: Abra|Lacub | B10: 2821
A11: Abra|Lagayan | B11: 2824
A12: Abra|Langiden | B12: 2807
... A1516: Zamboanga del Sur|Tukuran | B1516: 7019
