Workbook

Sheet README
A1: AF HOMES ECOFARM V2 — MEMBERSHIP BULK IMPORT | B1: OPERATING MANUAL | C1: Excel Desktop · Excel Web · Offline · Google Sheets
A2: READ THIS FIRST | B2: This workbook contains personal information. Use a private company copy; do not make the file publicly accessible. | C2: Safe bulk import requires admin preview and approval
A3: DOCUMENT VERSION | B3: 2026-10-16 | 5,000 customer rows per entry tab; one customer always occupies one aligned row across four sheets. | C3: Document only; no code or live database changed
A4: HOW TO START | B4: Complete Primary row 2, matching optional Supplementary row 2, Related row 2 and Package row 2, then continue with row 3. | C4: Do NOT sort, delete or insert one sheet alone
A5: IMPORTANT LIMITATION | B5: Excel validation is only a convenience. Server-side verification of location, identity, status, referral and verified payments is mandatory. | C5: Review the import preview before confirmation
A7: COMPATIBILITY | B7: Native Excel .xlsx recommended. Date calendar, dropdown search, and conversion to Google Sheets differ by app/version. | C7: Macros are NOT built into this workbook
A8: WORKBOOK ENTRY TABS | B8: Primary · Supplementary · Related · Package · PSGC_* lookup sheets (do not edit). | C8: Keep headers and sheet names exactly
A10: APPROVED DROPDOWN VALUES | B10: Use the exact text shown below. These entries are copied from the original README. | C10: Spellings intentionally preserved
A11: STATUS | B11: Active VIP, Fully Paid, Down Payment, Reservation Paid, Partially Paid, Pending, Inactive, Suspended, Expired, Cancelled | C11: Primary!B
A12: SUFFIX | B12: Jr., Sr., II, III, IV, N/A | C12: Primary!F · Supplementary!D
A13: GENDER | B13: Male, Female, | C13: Primary!H · Supplementary!F
A15: CIVIL STATUS | B15: Single, Married, Widowed, Seperated | C15: Primary!K · Supplementary!I (source spelling retained)
... A118: Version scope | B118: Instruction sheet updated 2026-10-16; source spreadsheet remains an entry-and-review aid, not a source of authoritative business approval. | C118: AF Homes Ecofarm V2 only; no JA&D, no NFC
A120: SYSTEM IMPORT SAFEGUARDS | B120: STATUS and Package figures are company statements, not verified money or membership activation. Review in Finance. TIN is omitted from exports. Macros are removed and never run by the importer.

Sheet Primary
A1: RA NO | B1: STATUS | C1: FIRST NAME | D1: LAST NAME | E1: MIDDLE NAME | F1: SUFFIX | G1: BIRTHDAY | H1: GENDER | I1: AGE | J1: CITIZENSHIP | K1: CIVIL STATUS | L1: PERMANENT ADDRESS LINE 1 | M1: PERMANENT ADDRESS LINE 2 | N1: PROVINCE | O1: CITY | P1: BARANGGAY | Q1: POSTAL CODE | R1: LANDLINE | S1: EMAIL | T1: TIN NO. | U1: MOBILE NO. | V1: OCCUPATION / BUSINESS NAME | W1: OFFICE / BUSINESS ADDRESS | X1: EMPLOYED POSITION
I2: =IF(G2="","",IF(OR(NOT(ISNUMBER(G2)),G2>TODAY()),"",DATEDIF(G2,TODAY(),"Y"))) | Q2: =IF(OR(N2="",O2="",P2=""),"",IFERROR(IF(COUNTIF(OFFSET(PSGC_BarangayList!$A$2,INDEX(PSGC_CityIndex!$B$2:$B$1643,MATCH(N2&"|"&O2,PSGC_CityIndex!$A$2:$A$1643,0))-2,0,INDEX(PSGC_CityIndex!$C$2:$C$1643,MATCH(N2&"|"&O2,PSGC_CityIndex!$A$2:$A$1643,0)),1),P2)=0,"",INDEX(PSGC_CityList!$C$2:$C$1643,MATCH(N2&"|"&O2,PSGC_CityIndex!$A$2:$A$1643,0))),""))
I3: =IF(G3="","",IF(OR(NOT(ISNUMBER(G3)),G3>TODAY()),"",DATEDIF(G3,TODAY(),"Y"))) | Q3: =IF(OR(N3="",O3="",P3=""),"",IFERROR(IF(COUNTIF(OFFSET(PSGC_BarangayList!$A$2,INDEX(PSGC_CityIndex!$B$2:$B$1643,MATCH(N3&"|"&O3,PSGC_CityIndex!$A$2:$A$1643,0))-2,0,INDEX(PSGC_CityIndex!$C$2:$C$1643,MATCH(N3&"|"&O3,PSGC_CityIndex!$A$2:$A$1643,0)),1),P3)=0,"",INDEX(PSGC_CityList!$C$2:$C$1643,MATCH(N3&"|"&O3,PSGC_CityIndex!$A$2:$A$1643,0))),""))
I4: =IF(G4="","",IF(OR(NOT(ISNUMBER(G4)),G4>TODAY()),"",DATEDIF(G4,TODAY(),"Y"))) | Q4: =IF(OR(N4="",O4="",P4=""),"",IFERROR(IF(COUNTIF(OFFSET(PSGC_BarangayList!$A$2,INDEX(PSGC_CityIndex!$B$2:$B$1643,MATCH(N4&"|"&O4,PSGC_CityIndex!$A$2:$A$1643,0))-2,0,INDEX(PSGC_CityIndex!$C$2:$C$1643,MATCH(N4&"|"&O4,PSGC_CityIndex!$A$2:$A$1643,0)),1),P4)=0,"",INDEX(PSGC_CityList!$C$2:$C$1643,MATCH(N4&"|"&O4,PSGC_CityIndex!$A$2:$A$1643,0))),""))
I5: =IF(G5="","",IF(OR(NOT(ISNUMBER(G5)),G5>TODAY()),"",DATEDIF(G5,TODAY(),"Y"))) | Q5: =IF(OR(N5="",O5="",P5=""),"",IFERROR(IF(COUNTIF(OFFSET(PSGC_BarangayList!$A$2,INDEX(PSGC_CityIndex!$B$2:$B$1643,MATCH(N5&"|"&O5,PSGC_CityIndex!$A$2:$A$1643,0))-2,0,INDEX(PSGC_CityIndex!$C$2:$C$1643,MATCH(N5&"|"&O5,PSGC_CityIndex!$A$2:$A$1643,0)),1),P5)=0,"",INDEX(PSGC_CityList!$C$2:$C$1643,MATCH(N5&"|"&O5,PSGC_CityIndex!$A$2:$A$1643,0))),""))
I6: =IF(G6="","",IF(OR(NOT(ISNUMBER(G6)),G6>TODAY()),"",DATEDIF(G6,TODAY(),"Y"))) | Q6: =IF(OR(N6="",O6="",P6=""),"",IFERROR(IF(COUNTIF(OFFSET(PSGC_BarangayList!$A$2,INDEX(PSGC_CityIndex!$B$2:$B$1643,MATCH(N6&"|"&O6,PSGC_CityIndex!$A$2:$A$1643,0))-2,0,INDEX(PSGC_CityIndex!$C$2:$C$1643,MATCH(N6&"|"&O6,PSGC_CityIndex!$A$2:$A$1643,0)),1),P6)=0,"",INDEX(PSGC_CityList!$C$2:$C$1643,MATCH(N6&"|"&O6,PSGC_CityIndex!$A$2:$A$1643,0))),""))
I7: =IF(G7="","",IF(OR(NOT(ISNUMBER(G7)),G7>TODAY()),"",DATEDIF(G7,TODAY(),"Y"))) | Q7: =IF(OR(N7="",O7="",P7=""),"",IFERROR(IF(COUNTIF(OFFSET(PSGC_BarangayList!$A$2,INDEX(PSGC_CityIndex!$B$2:$B$1643,MATCH(N7&"|"&O7,PSGC_CityIndex!$A$2:$A$1643,0))-2,0,INDEX(PSGC_CityIndex!$C$2:$C$1643,MATCH(N7&"|"&O7,PSGC_CityIndex!$A$2:$A$1643,0)),1),P7)=0,"",INDEX(PSGC_CityList!$C$2:$C$1643,MATCH(N7&"|"&O7,PSGC_CityIndex!$A$2:$A$1643,0))),""))
I8: =IF(G8="","",IF(OR(NOT(ISNUMBER(G8)),G8>TODAY()),"",DATEDIF(G8,TODAY(),"Y"))) | Q8: =IF(OR(N8="",O8="",P8=""),"",IFERROR(IF(COUNTIF(OFFSET(PSGC_BarangayList!$A$2,INDEX(PSGC_CityIndex!$B$2:$B$1643,MATCH(N8&"|"&O8,PSGC_CityIndex!$A$2:$A$1643,0))-2,0,INDEX(PSGC_CityIndex!$C$2:$C$1643,MATCH(N8&"|"&O8,PSGC_CityIndex!$A$2:$A$1643,0)),1),P8)=0,"",INDEX(PSGC_CityList!$C$2:$C$1643,MATCH(N8&"|"&O8,PSGC_CityIndex!$A$2:$A$1643,0))),""))
I9: =IF(G9="","",IF(OR(NOT(ISNUMBER(G9)),G9>TODAY()),"",DATEDIF(G9,TODAY(),"Y"))) | Q9: =IF(OR(N9="",O9="",P9=""),"",IFERROR(IF(COUNTIF(OFFSET(PSGC_BarangayList!$A$2,INDEX(PSGC_CityIndex!$B$2:$B$1643,MATCH(N9&"|"&O9,PSGC_CityIndex!$A$2:$A$1643,0))-2,0,INDEX(PSGC_CityIndex!$C$2:$C$1643,MATCH(N9&"|"&O9,PSGC_CityIndex!$A$2:$A$1643,0)),1),P9)=0,"",INDEX(PSGC_CityList!$C$2:$C$1643,MATCH(N9&"|"&O9,PSGC_CityIndex!$A$2:$A$1643,0))),""))
I10: =IF(G10="","",IF(OR(NOT(ISNUMBER(G10)),G10>TODAY()),"",DATEDIF(G10,TODAY(),"Y"))) | Q10: =IF(OR(N10="",O10="",P10=""),"",IFERROR(IF(COUNTIF(OFFSET(PSGC_BarangayList!$A$2,INDEX(PSGC_CityIndex!$B$2:$B$1643,MATCH(N10&"|"&O10,PSGC_CityIndex!$A$2:$A$1643,0))-2,0,INDEX(PSGC_CityIndex!$C$2:$C$1643,MATCH(N10&"|"&O10,PSGC_CityIndex!$A$2:$A$1643,0)),1),P10)=0,"",INDEX(PSGC_CityList!$C$2:$C$1643,MATCH(N10&"|"&O10,PSGC_CityIndex!$A$2:$A$1643,0))),""))
I11: =IF(G11="","",IF(OR(NOT(ISNUMBER(G11)),G11>TODAY()),"",DATEDIF(G11,TODAY(),"Y"))) | Q11: =IF(OR(N11="",O11="",P11=""),"",IFERROR(IF(COUNTIF(OFFSET(PSGC_BarangayList!$A$2,INDEX(PSGC_CityIndex!$B$2:$B$1643,MATCH(N11&"|"&O11,PSGC_CityIndex!$A$2:$A$1643,0))-2,0,INDEX(PSGC_CityIndex!$C$2:$C$1643,MATCH(N11&"|"&O11,PSGC_CityIndex!$A$2:$A$1643,0)),1),P11)=0,"",INDEX(PSGC_CityList!$C$2:$C$1643,MATCH(N11&"|"&O11,PSGC_CityIndex!$A$2:$A$1643,0))),""))
I12: =IF(G12="","",IF(OR(NOT(ISNUMBER(G12)),G12>TODAY()),"",DATEDIF(G12,TODAY(),"Y"))) | Q12: =IF(OR(N12="",O12="",P12=""),"",IFERROR(IF(COUNTIF(OFFSET(PSGC_BarangayList!$A$2,INDEX(PSGC_CityIndex!$B$2:$B$1643,MATCH(N12&"|"&O12,PSGC_CityIndex!$A$2:$A$1643,0))-2,0,INDEX(PSGC_CityIndex!$C$2:$C$1643,MATCH(N12&"|"&O12,PSGC_CityIndex!$A$2:$A$1643,0)),1),P12)=0,"",INDEX(PSGC_CityList!$C$2:$C$1643,MATCH(N12&"|"&O12,PSGC_CityIndex!$A$2:$A$1643,0))),""))
I13: =IF(G13="","",IF(OR(NOT(ISNUMBER(G13)),G13>TODAY()),"",DATEDIF(G13,TODAY(),"Y"))) | Q13: =IF(OR(N13="",O13="",P13=""),"",IFERROR(IF(COUNTIF(OFFSET(PSGC_BarangayList!$A$2,INDEX(PSGC_CityIndex!$B$2:$B$1643,MATCH(N13&"|"&O13,PSGC_CityIndex!$A$2:$A$1643,0))-2,0,INDEX(PSGC_CityIndex!$C$2:$C$1643,MATCH(N13&"|"&O13,PSGC_CityIndex!$A$2:$A$1643,0)),1),P13)=0,"",INDEX(PSGC_CityList!$C$2:$C$1643,MATCH(N13&"|"&O13,PSGC_CityIndex!$A$2:$A$1643,0))),""))
... I5001: =IF(G5001="","",IF(OR(NOT(ISNUMBER(G5001)),G5001>TODAY()),"",DATEDIF(G5001,TODAY(),"Y"))) | Q5001: =IF(OR(N5001="",O5001="",P5001=""),"",IFERROR(IF(COUNTIF(OFFSET(PSGC_BarangayList!$A$2,INDEX(PSGC_CityIndex!$B$2:$B$1643,MATCH(N5001&"|"&O5001,PSGC_CityIndex!$A$2:$A$1643,0))-2,0,INDEX(PSGC_CityIndex!$C$2:$C$1643,MATCH(N5001&"|"&O5001,PSGC_CityIndex!$A$2:$A$1643,0)),1),P5001)=0,"",INDEX(PSGC_CityList!$C$2:$C$1643,MATCH(N5001&"|"&O5001,PSGC_CityIndex!$A$2:$A$1643,0))),""))

Sheet Supplementary
A1: FIRST NAME | B1: LAST NAME | C1: MIDDLE NAME | D1: SUFFIX | E1: BIRTHDAY | F1: GENDER | G1: AGE | H1: CITIZENSHIP | I1: CIVIL STATUS | J1: PERMANENT ADDRESS LINE 1 | K1: PERMANENT ADDRESS LINE 2 | L1: PROVINCE | M1: CITY | N1: BARANGGAY | O1: POSTAL CODE | P1: LANDLINE | Q1: EMAIL | R1: TIN NO. | S1: MOBILE NO. | T1: OCCUPATION / BUSINESS NAME | U1: OFFICE / BUSINESS ADDRESS | V1: EMPLOYED POSITION
G2: =IF(E2="","",IF(OR(NOT(ISNUMBER(E2)),E2>TODAY()),"",DATEDIF(E2,TODAY(),"Y"))) | O2: =IF(OR(L2="",M2="",N2=""),"",IFERROR(IF(COUNTIF(OFFSET(PSGC_BarangayList!$A$2,INDEX(PSGC_CityIndex!$B$2:$B$1643,MATCH(L2&"|"&M2,PSGC_CityIndex!$A$2:$A$1643,0))-2,0,INDEX(PSGC_CityIndex!$C$2:$C$1643,MATCH(L2&"|"&M2,PSGC_CityIndex!$A$2:$A$1643,0)),1),N2)=0,"",INDEX(PSGC_CityList!$C$2:$C$1643,MATCH(L2&"|"&M2,PSGC_CityIndex!$A$2:$A$1643,0))),""))
G3: =IF(E3="","",IF(OR(NOT(ISNUMBER(E3)),E3>TODAY()),"",DATEDIF(E3,TODAY(),"Y"))) | O3: =IF(OR(L3="",M3="",N3=""),"",IFERROR(IF(COUNTIF(OFFSET(PSGC_BarangayList!$A$2,INDEX(PSGC_CityIndex!$B$2:$B$1643,MATCH(L3&"|"&M3,PSGC_CityIndex!$A$2:$A$1643,0))-2,0,INDEX(PSGC_CityIndex!$C$2:$C$1643,MATCH(L3&"|"&M3,PSGC_CityIndex!$A$2:$A$1643,0)),1),N3)=0,"",INDEX(PSGC_CityList!$C$2:$C$1643,MATCH(L3&"|"&M3,PSGC_CityIndex!$A$2:$A$1643,0))),""))
G4: =IF(E4="","",IF(OR(NOT(ISNUMBER(E4)),E4>TODAY()),"",DATEDIF(E4,TODAY(),"Y"))) | O4: =IF(OR(L4="",M4="",N4=""),"",IFERROR(IF(COUNTIF(OFFSET(PSGC_BarangayList!$A$2,INDEX(PSGC_CityIndex!$B$2:$B$1643,MATCH(L4&"|"&M4,PSGC_CityIndex!$A$2:$A$1643,0))-2,0,INDEX(PSGC_CityIndex!$C$2:$C$1643,MATCH(L4&"|"&M4,PSGC_CityIndex!$A$2:$A$1643,0)),1),N4)=0,"",INDEX(PSGC_CityList!$C$2:$C$1643,MATCH(L4&"|"&M4,PSGC_CityIndex!$A$2:$A$1643,0))),""))
G5: =IF(E5="","",IF(OR(NOT(ISNUMBER(E5)),E5>TODAY()),"",DATEDIF(E5,TODAY(),"Y"))) | O5: =IF(OR(L5="",M5="",N5=""),"",IFERROR(IF(COUNTIF(OFFSET(PSGC_BarangayList!$A$2,INDEX(PSGC_CityIndex!$B$2:$B$1643,MATCH(L5&"|"&M5,PSGC_CityIndex!$A$2:$A$1643,0))-2,0,INDEX(PSGC_CityIndex!$C$2:$C$1643,MATCH(L5&"|"&M5,PSGC_CityIndex!$A$2:$A$1643,0)),1),N5)=0,"",INDEX(PSGC_CityList!$C$2:$C$1643,MATCH(L5&"|"&M5,PSGC_CityIndex!$A$2:$A$1643,0))),""))
G6: =IF(E6="","",IF(OR(NOT(ISNUMBER(E6)),E6>TODAY()),"",DATEDIF(E6,TODAY(),"Y"))) | O6: =IF(OR(L6="",M6="",N6=""),"",IFERROR(IF(COUNTIF(OFFSET(PSGC_BarangayList!$A$2,INDEX(PSGC_CityIndex!$B$2:$B$1643,MATCH(L6&"|"&M6,PSGC_CityIndex!$A$2:$A$1643,0))-2,0,INDEX(PSGC_CityIndex!$C$2:$C$1643,MATCH(L6&"|"&M6,PSGC_CityIndex!$A$2:$A$1643,0)),1),N6)=0,"",INDEX(PSGC_CityList!$C$2:$C$1643,MATCH(L6&"|"&M6,PSGC_CityIndex!$A$2:$A$1643,0))),""))
G7: =IF(E7="","",IF(OR(NOT(ISNUMBER(E7)),E7>TODAY()),"",DATEDIF(E7,TODAY(),"Y"))) | O7: =IF(OR(L7="",M7="",N7=""),"",IFERROR(IF(COUNTIF(OFFSET(PSGC_BarangayList!$A$2,INDEX(PSGC_CityIndex!$B$2:$B$1643,MATCH(L7&"|"&M7,PSGC_CityIndex!$A$2:$A$1643,0))-2,0,INDEX(PSGC_CityIndex!$C$2:$C$1643,MATCH(L7&"|"&M7,PSGC_CityIndex!$A$2:$A$1643,0)),1),N7)=0,"",INDEX(PSGC_CityList!$C$2:$C$1643,MATCH(L7&"|"&M7,PSGC_CityIndex!$A$2:$A$1643,0))),""))
G8: =IF(E8="","",IF(OR(NOT(ISNUMBER(E8)),E8>TODAY()),"",DATEDIF(E8,TODAY(),"Y"))) | O8: =IF(OR(L8="",M8="",N8=""),"",IFERROR(IF(COUNTIF(OFFSET(PSGC_BarangayList!$A$2,INDEX(PSGC_CityIndex!$B$2:$B$1643,MATCH(L8&"|"&M8,PSGC_CityIndex!$A$2:$A$1643,0))-2,0,INDEX(PSGC_CityIndex!$C$2:$C$1643,MATCH(L8&"|"&M8,PSGC_CityIndex!$A$2:$A$1643,0)),1),N8)=0,"",INDEX(PSGC_CityList!$C$2:$C$1643,MATCH(L8&"|"&M8,PSGC_CityIndex!$A$2:$A$1643,0))),""))
G9: =IF(E9="","",IF(OR(NOT(ISNUMBER(E9)),E9>TODAY()),"",DATEDIF(E9,TODAY(),"Y"))) | O9: =IF(OR(L9="",M9="",N9=""),"",IFERROR(IF(COUNTIF(OFFSET(PSGC_BarangayList!$A$2,INDEX(PSGC_CityIndex!$B$2:$B$1643,MATCH(L9&"|"&M9,PSGC_CityIndex!$A$2:$A$1643,0))-2,0,INDEX(PSGC_CityIndex!$C$2:$C$1643,MATCH(L9&"|"&M9,PSGC_CityIndex!$A$2:$A$1643,0)),1),N9)=0,"",INDEX(PSGC_CityList!$C$2:$C$1643,MATCH(L9&"|"&M9,PSGC_CityIndex!$A$2:$A$1643,0))),""))
G10: =IF(E10="","",IF(OR(NOT(ISNUMBER(E10)),E10>TODAY()),"",DATEDIF(E10,TODAY(),"Y"))) | O10: =IF(OR(L10="",M10="",N10=""),"",IFERROR(IF(COUNTIF(OFFSET(PSGC_BarangayList!$A$2,INDEX(PSGC_CityIndex!$B$2:$B$1643,MATCH(L10&"|"&M10,PSGC_CityIndex!$A$2:$A$1643,0))-2,0,INDEX(PSGC_CityIndex!$C$2:$C$1643,MATCH(L10&"|"&M10,PSGC_CityIndex!$A$2:$A$1643,0)),1),N10)=0,"",INDEX(PSGC_CityList!$C$2:$C$1643,MATCH(L10&"|"&M10,PSGC_CityIndex!$A$2:$A$1643,0))),""))
G11: =IF(E11="","",IF(OR(NOT(ISNUMBER(E11)),E11>TODAY()),"",DATEDIF(E11,TODAY(),"Y"))) | O11: =IF(OR(L11="",M11="",N11=""),"",IFERROR(IF(COUNTIF(OFFSET(PSGC_BarangayList!$A$2,INDEX(PSGC_CityIndex!$B$2:$B$1643,MATCH(L11&"|"&M11,PSGC_CityIndex!$A$2:$A$1643,0))-2,0,INDEX(PSGC_CityIndex!$C$2:$C$1643,MATCH(L11&"|"&M11,PSGC_CityIndex!$A$2:$A$1643,0)),1),N11)=0,"",INDEX(PSGC_CityList!$C$2:$C$1643,MATCH(L11&"|"&M11,PSGC_CityIndex!$A$2:$A$1643,0))),""))
G12: =IF(E12="","",IF(OR(NOT(ISNUMBER(E12)),E12>TODAY()),"",DATEDIF(E12,TODAY(),"Y"))) | O12: =IF(OR(L12="",M12="",N12=""),"",IFERROR(IF(COUNTIF(OFFSET(PSGC_BarangayList!$A$2,INDEX(PSGC_CityIndex!$B$2:$B$1643,MATCH(L12&"|"&M12,PSGC_CityIndex!$A$2:$A$1643,0))-2,0,INDEX(PSGC_CityIndex!$C$2:$C$1643,MATCH(L12&"|"&M12,PSGC_CityIndex!$A$2:$A$1643,0)),1),N12)=0,"",INDEX(PSGC_CityList!$C$2:$C$1643,MATCH(L12&"|"&M12,PSGC_CityIndex!$A$2:$A$1643,0))),""))
G13: =IF(E13="","",IF(OR(NOT(ISNUMBER(E13)),E13>TODAY()),"",DATEDIF(E13,TODAY(),"Y"))) | O13: =IF(OR(L13="",M13="",N13=""),"",IFERROR(IF(COUNTIF(OFFSET(PSGC_BarangayList!$A$2,INDEX(PSGC_CityIndex!$B$2:$B$1643,MATCH(L13&"|"&M13,PSGC_CityIndex!$A$2:$A$1643,0))-2,0,INDEX(PSGC_CityIndex!$C$2:$C$1643,MATCH(L13&"|"&M13,PSGC_CityIndex!$A$2:$A$1643,0)),1),N13)=0,"",INDEX(PSGC_CityList!$C$2:$C$1643,MATCH(L13&"|"&M13,PSGC_CityIndex!$A$2:$A$1643,0))),""))
... G5001: =IF(E5001="","",IF(OR(NOT(ISNUMBER(E5001)),E5001>TODAY()),"",DATEDIF(E5001,TODAY(),"Y"))) | O5001: =IF(OR(L5001="",M5001="",N5001=""),"",IFERROR(IF(COUNTIF(OFFSET(PSGC_BarangayList!$A$2,INDEX(PSGC_CityIndex!$B$2:$B$1643,MATCH(L5001&"|"&M5001,PSGC_CityIndex!$A$2:$A$1643,0))-2,0,INDEX(PSGC_CityIndex!$C$2:$C$1643,MATCH(L5001&"|"&M5001,PSGC_CityIndex!$A$2:$A$1643,0)),1),N5001)=0,"",INDEX(PSGC_CityList!$C$2:$C$1643,MATCH(L5001&"|"&M5001,PSGC_CityIndex!$A$2:$A$1643,0))),""))

Sheet Related
A1: SVD (NAME) | B1: SSM (NAME) | C1: SM (NAME) | D1: REFERRER (NAME) | E1: VIP RECOMMENDER (NAME) | F1: CONTACT NO. | G1: EMAIL ADDRESS

Sheet Package
A1: VIP PACKAGE | B1: PAYMENT TERMS | C1: REGULAR PRICE | D1: DISCOUNT | E1: TOTAL AMOUNT | F1: RF | G1: PAYMENT TYPE | H1: REF NO | I1: DATE

Sheet PSGC_ProvinceList
A1: Province / Region for independent cities
A2: Abra
A3: Agusan del Norte
A4: Agusan del Sur
A5: Aklan
A6: Albay
A7: Antique
A8: Apayao
A9: Aurora
A10: Basilan
A11: Bataan
A12: Batanes
... A99: Zamboanga Sibugay

Sheet PSGC_CityList
A1: Province / region | B1: City / municipality | C1: Postal Code | D1: Postal Source
A2: Abra | B2: Bangued | C2: 2800 | D2: PHLPost
A3: Abra | B3: Boliney | C3: 2815 | D3: PHLPost
A4: Abra | B4: Bucay | C4: 2805 | D4: PHLPost
A5: Abra | B5: Bucloc | C5: 2817 | D5: PHLPost
A6: Abra | B6: Daguioman | C6: 2816 | D6: PHLPost
A7: Abra | B7: Danglas | C7: 2825 | D7: PHLPost
A8: Abra | B8: Dolores | C8: 2801 | D8: PHLPost
A9: Abra | B9: La Paz | C9: 2826 | D9: PHLPost
A10: Abra | B10: Lacub | C10: 2821 | D10: PHLPost
A11: Abra | B11: Lagangilang | C11: 2802 | D11: PHLPost
A12: Abra | B12: Lagayan | C12: 2824 | D12: PHLPost
... A121: Aurora | B121: San Luis | C121: 3201 | D121: PHLPost
A122: Basilan | B122: Akbar | D122: Needs verification
A123: Basilan | B123: Al-Barka | D123: Needs verification
A124: Basilan | B124: City of Lamitan | C124: 7302 | D124: BarangayDirectory
A125: Basilan | B125: Hadji Mohammad Ajul | D125: Needs verification
A126: Basilan | B126: Hadji Muhtamad | D126: Needs verification
A127: Basilan | B127: Lantawan | C127: 7301 | D127: BarangayDirectory
A128: Basilan | B128: Maluso | C128: 7303 | D128: BarangayDirectory
A129: Basilan | B129: Sumisip | C129: 7305 | D129: BarangayDirectory
A130: Basilan | B130: Tabuan-Lasa | D130: Needs verification
A131: Basilan | B131: Tipo-Tipo | C131: 7304 | D131: BarangayDirectory
A132: Basilan | B132: Tuburan | C132: 7306 | D132: BarangayDirectory
A133: Basilan | B133: Ungkaya Pukan | D133: Needs verification
A134: Bataan | B134: Abucay | C134: 2114 | D134: PHLPost
A135: Bataan | B135: Bagac | C135: 2107 | D135: PHLPost
A136: Bataan | B136: City of Balanga | C136: 2100 | D136: PHLPost
A137: Bataan | B137: Dinalupihan | C137: 2110 | D137: PHLPost
A138: Bataan | B138: Hermosa | C138: 2111 | D138: PHLPost
A139: Bataan | B139: Limay | C139: 2103 | D139: PHLPost
A140: Bataan | B140: Mariveles | C140: 2105 | D140: BarangayDirectory
A141: Bataan | B141: Morong | C141: 2108 | D141: BarangayDirectory
A142: Bataan | B142: Orani | C142: 2112 | D142: BarangayDirectory
A143: Bataan | B143: Orion | C143: 2102 | D143: BarangayDirectory
A144: Bataan | B144: Pilar | C144: 2101 | D144: BarangayDirectory
A145: Bataan | B145: Samal | C145: 2113 | D145: BarangayDirectory
... A230: Bohol | B230: Garcia Hernandez | C230: 6307 | D230: BarangayDirectory
A231: Bohol | B231: Getafe | D231: Needs verification
A232: Bohol | B232: Guindulman | C232: 6310 | D232: BarangayDirectory
...

Sheet PSGC_BarangayList
A1: Barangay
A2: Agtangao
A3: Angad
A4: Bangbangar
A5: Bañacao
A6: Cabuloan
A7: Calaba
A8: Cosili East
A9: Cosili West
A10: Dangdangla
A11: Lingtan
A12: Lipcan
... A42011: Upper Tungawan

Sheet PSGC_ProvinceIndex
A1: Province | B1: City list start row | C1: City count
A2: Abra | B2: 2 | C2: 27
A3: Agusan del Norte | B3: 29 | C3: 11
A4: Agusan del Sur | B4: 40 | C4: 14
A5: Aklan | B5: 54 | C5: 17
A6: Albay | B6: 71 | C6: 18
A7: Antique | B7: 89 | C7: 18
A8: Apayao | B8: 107 | C8: 7
A9: Aurora | B9: 114 | C9: 8
A10: Basilan | B10: 122 | C10: 12
A11: Bataan | B11: 134 | C11: 12
A12: Batanes | B12: 146 | C12: 6
A13: Batangas | B13: 152 | C13: 34
... A99: Zamboanga Sibugay | B99: 1628 | C99: 16

Sheet PSGC_CityIndex
A1: Province|City | B1: Barangay list start row | C1: Barangay count
A2: Abra|Bangued | B2: 2 | C2: 31
A3: Abra|Boliney | B3: 33 | C3: 8
A4: Abra|Bucay | B4: 41 | C4: 21
A5: Abra|Bucloc | B5: 62 | C5: 4
A6: Abra|Daguioman | B6: 66 | C6: 4
A7: Abra|Danglas | B7: 70 | C7: 7
A8: Abra|Dolores | B8: 77 | C8: 15
A9: Abra|La Paz | B9: 92 | C9: 12
A10: Abra|Lacub | B10: 104 | C10: 6
A11: Abra|Lagangilang | B11: 110 | C11: 17
A12: Abra|Lagayan | B12: 127 | C12: 5
A13: Abra|Langiden | B13: 132 | C13: 6
... A1643: Zamboanga Sibugay|Tungawan | B1643: 41987 | C1643: 25
