Workbook

Sheet README
A1: AF HOMES ECOFARM / IST BULK IMPORT
A2: Historical IST Data Migration | Official AAI numbers + Team hierarchy | Workbook guide
A3: READ FIRST: This file captures existing company records. Excel does not create accounts, approve genealogy, or issue accreditation numbers.
A5: 01 | IMPORT WORKFLOW
A6: STEP | B6: WHAT TO DO | C6: PRACTICAL NOTE
A7: 1 · Prepare | B7: Copy verified historical IST records from the company source files. Check spelling, phone numbers, AAI numbers and manager names. | C7: Use authentic records; never invent government IDs or registered seller relationships.
A8: 2 · Identity | B8: Enter each person on one row. Supply their original AAI number if already issued; otherwise leave that field blank for a new account. | C8: Row 2 in Identity = row 2 in Team and Details.
A9: 3 · Team | B9: Select Position and choose the correct Head Member Name when required. | C9: VD → no head; SSM → VD; SM → SSM.
A10: 4 · Details | B10: Complete existing government ID type/number, TIN, telephone, employer and Job Position when held in source data. | C10: Job Position is retained; this is not the IST sales hierarchy Position.
A11: 5 · Review | B11: Resolve empty required fields, duplicate AAI numbers, invalid mobile numbers, and Hierarchy Check warnings. | C11: Excel validators can be bypassed by pasting; server validation is mandatory.
A12: 6 · Preview | B12: Upload to the supported IST bulk-import screen and review CREATE / MATCH / CONFLICT decisions before confirming. | C12: A successful spreadsheet upload is not proof of an approved account.
A13: 7 · Confirm | B13: Only an authorized operator should approve migration after reviewing candidate matches and account permissions. | C13: Use a safe test environment with synthetic rows before live imports.
A15: 02 | WHAT EACH TAB IS FOR
A16: TAB | B16: PURPOSE | C16: USAGE
A17: README | B17: Guide, warnings and workbook entry instructions. | C17: No person data goes here.
A18: Identity | B18: Existing AAI Number, names, email, mobile, birthdate, age, gender, marital status and address. | C18: AAI can be entered to preserve historical company-issued IDs.
A19: Team | B19: Applicant Name (auto), Position, Head Member Name, Hierarchy Check (auto), and Search Head Member field. | C19: Head Member is selected as a name, not an email address.
A20: Details | B20: Applicant Name (auto), document information, employment and Job Position. | C20: Same worksheet row as Identity.
A21: Teams | B21: Three-column name list: Vice Directors / Senior Sales Managers / Sales Managers. | C21: Provides candidate names to dropdowns; not an account-registration tab.
A22: Reference tabs | B22: Postal + PSGC Province/City/Barangay/Index sheets are bundled for offline Excel lookup. | C22: Do not delete, rename or sort independently.
A24: 03 | EXISTING AAI IDENTIFIER — IMPORTANT
A25: RULE | B25: EXPECTED BEHAVIOR | C25: EXAMPLE / REMINDER
A26: Historical AAI | B26: Use original uppercase AAIYYMMNNNN, e.g. AAI26100001, or an approved legacy AA- identifier: six letters and six digits in any order after AA-. The system must preserve the actual historic ID. | C26: AAI26100001 / AA-ABC123DEF456 (format examples only)
A27: Preserve the record | B27: The backend must match and retain the genuine existing identifier. Do not generate a replacement for an imported identity. | C27: Existing AAI does not imply a verified, active system account.
A28: New IST | B28: Leave AAI Number blank only if a number truly has not yet been issued; authorized system allocation handles new issuances. | C28: Do not assign an arbitrary number in Excel.
A29: Duplicate AAI | B29: Duplicate official numbers are blocked within this workbook. Server-side ownership and duplicate checks are still mandatory. | C29: Do not overwrite the AAI of a different person.
A30: Uppercase | B30: Only uppercase AAI + 2-digit year + valid month (01-12) + nonzero 4-digit sequence, or an approved issued legacy AA- plus exactly six letters and six digits. Other strings are rejected. | C30: No spaces or lowercase; historical AA- remains eligible only when genuinely issued.
A31: AAI vs UUID | B31: Official AAI is an external identifier; the database UUID remains the internal durable identity. | C31: Do not use AAI as a password, OTP or account authorization token.
A33: 04 | POSITION & HEAD MEMBER SELECTION
A34: POSITION | B34: HEAD MEMBER RULE | C34: WHY
A35: Vice Director | B35: No Head Member required; keep Head Member Name blank. | C35: Top-level team member.
A36: Senior Sales Manager | B36: Choose an existing or previously created Vice Director name. | C36: Must be under one valid VD.
A37: Sales Manager | B37: Choose an existing or previously created Senior Sales Manager name. | C37: The manager’s VD chain must be preserved.
A38: Teams directory | B38: The Teams tab has exactly three columns. Names from rows in this file feed its candidate lists. | C38: Previously registered staff may be added to unused name-list rows.
A39: Search Head Member | B39: Search Head Member in Team!E2; in Microsoft 365 the role-dependent choices may filter using FILTER. The technical _HeadMatches worksheet is hidden. | C39: Clear E2 for the full role list. Search is a convenience, not a live member lookup; use the web preview for ID verification.
A40: Dropdown | B40: Choose Position first, then Head Member Name. Only relevant VD/SSM names appear for that role. | C40: Excel may also support typing to search inside dropdowns, depending on edition.
A41: Missing hierarchy | B41: For a company with no existing digital records, import/approve VD accounts first, then SSM, then SM; or use a reviewed staged dependency workflow. | C41: Do not invent people or automatically approve unregistered head members.
A42: Name collisions | B42: Two people can have identical full names. Backend must resolve a unique staff ID / AAI and require review when ambiguous. | C42: Name alone cannot establish an authenticated team relationship.
A44: 05 | INPUT RESTRICTIONS & AUTO FIELDS
A45: FIELD | B45: EXCEL BEHAVIOR | C45: SYSTEM VALIDATION
...

Sheet Identity
A1: AAI Number | B1: First Name | C1: Middle Name | D1: Last Name | E1: Email Address | F1: Mobile Number | G1: Date of Birth | H1: Age (Auto) | I1: Sex | J1: Civil Status | K1: Province / Region | L1: City / Municipality | M1: Barangay | N1: Permanent Address Line 1 | O1: Postal Code (Auto)
H2: =IF(G2="","",IFERROR(DATEDIF(IF(ISNUMBER(G2),G2,DATEVALUE(G2)),TODAY(),"Y"),"")) | O2: =IF(OR(K2="",L2=""),"",IFERROR(VLOOKUP(K2&"|"&L2,Postal!$A$2:$B$1643,2,FALSE),""))
H3: =IF(G3="","",IFERROR(DATEDIF(IF(ISNUMBER(G3),G3,DATEVALUE(G3)),TODAY(),"Y"),"")) | O3: =IF(OR(K3="",L3=""),"",IFERROR(VLOOKUP(K3&"|"&L3,Postal!$A$2:$B$1643,2,FALSE),""))
H4: =IF(G4="","",IFERROR(DATEDIF(IF(ISNUMBER(G4),G4,DATEVALUE(G4)),TODAY(),"Y"),"")) | O4: =IF(OR(K4="",L4=""),"",IFERROR(VLOOKUP(K4&"|"&L4,Postal!$A$2:$B$1643,2,FALSE),""))
H5: =IF(G5="","",IFERROR(DATEDIF(IF(ISNUMBER(G5),G5,DATEVALUE(G5)),TODAY(),"Y"),"")) | O5: =IF(OR(K5="",L5=""),"",IFERROR(VLOOKUP(K5&"|"&L5,Postal!$A$2:$B$1643,2,FALSE),""))
H6: =IF(G6="","",IFERROR(DATEDIF(IF(ISNUMBER(G6),G6,DATEVALUE(G6)),TODAY(),"Y"),"")) | O6: =IF(OR(K6="",L6=""),"",IFERROR(VLOOKUP(K6&"|"&L6,Postal!$A$2:$B$1643,2,FALSE),""))
H7: =IF(G7="","",IFERROR(DATEDIF(IF(ISNUMBER(G7),G7,DATEVALUE(G7)),TODAY(),"Y"),"")) | O7: =IF(OR(K7="",L7=""),"",IFERROR(VLOOKUP(K7&"|"&L7,Postal!$A$2:$B$1643,2,FALSE),""))
H8: =IF(G8="","",IFERROR(DATEDIF(IF(ISNUMBER(G8),G8,DATEVALUE(G8)),TODAY(),"Y"),"")) | O8: =IF(OR(K8="",L8=""),"",IFERROR(VLOOKUP(K8&"|"&L8,Postal!$A$2:$B$1643,2,FALSE),""))
H9: =IF(G9="","",IFERROR(DATEDIF(IF(ISNUMBER(G9),G9,DATEVALUE(G9)),TODAY(),"Y"),"")) | O9: =IF(OR(K9="",L9=""),"",IFERROR(VLOOKUP(K9&"|"&L9,Postal!$A$2:$B$1643,2,FALSE),""))
H10: =IF(G10="","",IFERROR(DATEDIF(IF(ISNUMBER(G10),G10,DATEVALUE(G10)),TODAY(),"Y"),"")) | O10: =IF(OR(K10="",L10=""),"",IFERROR(VLOOKUP(K10&"|"&L10,Postal!$A$2:$B$1643,2,FALSE),""))
H11: =IF(G11="","",IFERROR(DATEDIF(IF(ISNUMBER(G11),G11,DATEVALUE(G11)),TODAY(),"Y"),"")) | O11: =IF(OR(K11="",L11=""),"",IFERROR(VLOOKUP(K11&"|"&L11,Postal!$A$2:$B$1643,2,FALSE),""))
H12: =IF(G12="","",IFERROR(DATEDIF(IF(ISNUMBER(G12),G12,DATEVALUE(G12)),TODAY(),"Y"),"")) | O12: =IF(OR(K12="",L12=""),"",IFERROR(VLOOKUP(K12&"|"&L12,Postal!$A$2:$B$1643,2,FALSE),""))
H13: =IF(G13="","",IFERROR(DATEDIF(IF(ISNUMBER(G13),G13,DATEVALUE(G13)),TODAY(),"Y"),"")) | O13: =IF(OR(K13="",L13=""),"",IFERROR(VLOOKUP(K13&"|"&L13,Postal!$A$2:$B$1643,2,FALSE),""))
... H501: =IF(G501="","",IFERROR(DATEDIF(IF(ISNUMBER(G501),G501,DATEVALUE(G501)),TODAY(),"Y"),"")) | O501: =IF(OR(K501="",L501=""),"",IFERROR(VLOOKUP(K501&"|"&L501,Postal!$A$2:$B$1643,2,FALSE),""))

Sheet Team
A1: Applicant Name (Auto) | B1: Position | C1: Head Member Name | D1: Hierarchy Check (Auto) | E1: Search Head Member (All Rows)
A2: =IF(OR(Identity!B2="",Identity!D2=""),"",TRIM(Identity!B2&" "&Identity!C2&" "&Identity!D2)) | D2: =IF(A2="","",IF(B2="","Select Position",IF(B2="Vice Director",IF(C2="","Ready - No Head Needed","Clear Head Member"),IF(C2="","Select Head Member",IF(C2=A2,"Invalid - Same Applicant",IF(B2="Senior Sales Manager",IF(COUNTIF(Teams!$A$2:$A$1001,C2)=1,"VD selected - Verify ID","Missing/Ambiguous VD"),IF(B2="Sales Manager",IF(COUNTIF(Teams!$B$2:$B$1001,C2)=1,"SSM selected - Verify ID","Missing/Ambiguous SSM"),"Invalid Position")))))))
A3: =IF(OR(Identity!B3="",Identity!D3=""),"",TRIM(Identity!B3&" "&Identity!C3&" "&Identity!D3)) | D3: =IF(A3="","",IF(B3="","Select Position",IF(B3="Vice Director",IF(C3="","Ready - No Head Needed","Clear Head Member"),IF(C3="","Select Head Member",IF(C3=A3,"Invalid - Same Applicant",IF(B3="Senior Sales Manager",IF(COUNTIF(Teams!$A$2:$A$1001,C3)=1,"VD selected - Verify ID","Missing/Ambiguous VD"),IF(B3="Sales Manager",IF(COUNTIF(Teams!$B$2:$B$1001,C3)=1,"SSM selected - Verify ID","Missing/Ambiguous SSM"),"Invalid Position")))))))
A4: =IF(OR(Identity!B4="",Identity!D4=""),"",TRIM(Identity!B4&" "&Identity!C4&" "&Identity!D4)) | D4: =IF(A4="","",IF(B4="","Select Position",IF(B4="Vice Director",IF(C4="","Ready - No Head Needed","Clear Head Member"),IF(C4="","Select Head Member",IF(C4=A4,"Invalid - Same Applicant",IF(B4="Senior Sales Manager",IF(COUNTIF(Teams!$A$2:$A$1001,C4)=1,"VD selected - Verify ID","Missing/Ambiguous VD"),IF(B4="Sales Manager",IF(COUNTIF(Teams!$B$2:$B$1001,C4)=1,"SSM selected - Verify ID","Missing/Ambiguous SSM"),"Invalid Position")))))))
A5: =IF(OR(Identity!B5="",Identity!D5=""),"",TRIM(Identity!B5&" "&Identity!C5&" "&Identity!D5)) | D5: =IF(A5="","",IF(B5="","Select Position",IF(B5="Vice Director",IF(C5="","Ready - No Head Needed","Clear Head Member"),IF(C5="","Select Head Member",IF(C5=A5,"Invalid - Same Applicant",IF(B5="Senior Sales Manager",IF(COUNTIF(Teams!$A$2:$A$1001,C5)=1,"VD selected - Verify ID","Missing/Ambiguous VD"),IF(B5="Sales Manager",IF(COUNTIF(Teams!$B$2:$B$1001,C5)=1,"SSM selected - Verify ID","Missing/Ambiguous SSM"),"Invalid Position")))))))
A6: =IF(OR(Identity!B6="",Identity!D6=""),"",TRIM(Identity!B6&" "&Identity!C6&" "&Identity!D6)) | D6: =IF(A6="","",IF(B6="","Select Position",IF(B6="Vice Director",IF(C6="","Ready - No Head Needed","Clear Head Member"),IF(C6="","Select Head Member",IF(C6=A6,"Invalid - Same Applicant",IF(B6="Senior Sales Manager",IF(COUNTIF(Teams!$A$2:$A$1001,C6)=1,"VD selected - Verify ID","Missing/Ambiguous VD"),IF(B6="Sales Manager",IF(COUNTIF(Teams!$B$2:$B$1001,C6)=1,"SSM selected - Verify ID","Missing/Ambiguous SSM"),"Invalid Position")))))))
A7: =IF(OR(Identity!B7="",Identity!D7=""),"",TRIM(Identity!B7&" "&Identity!C7&" "&Identity!D7)) | D7: =IF(A7="","",IF(B7="","Select Position",IF(B7="Vice Director",IF(C7="","Ready - No Head Needed","Clear Head Member"),IF(C7="","Select Head Member",IF(C7=A7,"Invalid - Same Applicant",IF(B7="Senior Sales Manager",IF(COUNTIF(Teams!$A$2:$A$1001,C7)=1,"VD selected - Verify ID","Missing/Ambiguous VD"),IF(B7="Sales Manager",IF(COUNTIF(Teams!$B$2:$B$1001,C7)=1,"SSM selected - Verify ID","Missing/Ambiguous SSM"),"Invalid Position")))))))
A8: =IF(OR(Identity!B8="",Identity!D8=""),"",TRIM(Identity!B8&" "&Identity!C8&" "&Identity!D8)) | D8: =IF(A8="","",IF(B8="","Select Position",IF(B8="Vice Director",IF(C8="","Ready - No Head Needed","Clear Head Member"),IF(C8="","Select Head Member",IF(C8=A8,"Invalid - Same Applicant",IF(B8="Senior Sales Manager",IF(COUNTIF(Teams!$A$2:$A$1001,C8)=1,"VD selected - Verify ID","Missing/Ambiguous VD"),IF(B8="Sales Manager",IF(COUNTIF(Teams!$B$2:$B$1001,C8)=1,"SSM selected - Verify ID","Missing/Ambiguous SSM"),"Invalid Position")))))))
A9: =IF(OR(Identity!B9="",Identity!D9=""),"",TRIM(Identity!B9&" "&Identity!C9&" "&Identity!D9)) | D9: =IF(A9="","",IF(B9="","Select Position",IF(B9="Vice Director",IF(C9="","Ready - No Head Needed","Clear Head Member"),IF(C9="","Select Head Member",IF(C9=A9,"Invalid - Same Applicant",IF(B9="Senior Sales Manager",IF(COUNTIF(Teams!$A$2:$A$1001,C9)=1,"VD selected - Verify ID","Missing/Ambiguous VD"),IF(B9="Sales Manager",IF(COUNTIF(Teams!$B$2:$B$1001,C9)=1,"SSM selected - Verify ID","Missing/Ambiguous SSM"),"Invalid Position")))))))
A10: =IF(OR(Identity!B10="",Identity!D10=""),"",TRIM(Identity!B10&" "&Identity!C10&" "&Identity!D10)) | D10: =IF(A10="","",IF(B10="","Select Position",IF(B10="Vice Director",IF(C10="","Ready - No Head Needed","Clear Head Member"),IF(C10="","Select Head Member",IF(C10=A10,"Invalid - Same Applicant",IF(B10="Senior Sales Manager",IF(COUNTIF(Teams!$A$2:$A$1001,C10)=1,"VD selected - Verify ID","Missing/Ambiguous VD"),IF(B10="Sales Manager",IF(COUNTIF(Teams!$B$2:$B$1001,C10)=1,"SSM selected - Verify ID","Missing/Ambiguous SSM"),"Invalid Position")))))))
A11: =IF(OR(Identity!B11="",Identity!D11=""),"",TRIM(Identity!B11&" "&Identity!C11&" "&Identity!D11)) | D11: =IF(A11="","",IF(B11="","Select Position",IF(B11="Vice Director",IF(C11="","Ready - No Head Needed","Clear Head Member"),IF(C11="","Select Head Member",IF(C11=A11,"Invalid - Same Applicant",IF(B11="Senior Sales Manager",IF(COUNTIF(Teams!$A$2:$A$1001,C11)=1,"VD selected - Verify ID","Missing/Ambiguous VD"),IF(B11="Sales Manager",IF(COUNTIF(Teams!$B$2:$B$1001,C11)=1,"SSM selected - Verify ID","Missing/Ambiguous SSM"),"Invalid Position")))))))
A12: =IF(OR(Identity!B12="",Identity!D12=""),"",TRIM(Identity!B12&" "&Identity!C12&" "&Identity!D12)) | D12: =IF(A12="","",IF(B12="","Select Position",IF(B12="Vice Director",IF(C12="","Ready - No Head Needed","Clear Head Member"),IF(C12="","Select Head Member",IF(C12=A12,"Invalid - Same Applicant",IF(B12="Senior Sales Manager",IF(COUNTIF(Teams!$A$2:$A$1001,C12)=1,"VD selected - Verify ID","Missing/Ambiguous VD"),IF(B12="Sales Manager",IF(COUNTIF(Teams!$B$2:$B$1001,C12)=1,"SSM selected - Verify ID","Missing/Ambiguous SSM"),"Invalid Position")))))))
A13: =IF(OR(Identity!B13="",Identity!D13=""),"",TRIM(Identity!B13&" "&Identity!C13&" "&Identity!D13)) | D13: =IF(A13="","",IF(B13="","Select Position",IF(B13="Vice Director",IF(C13="","Ready - No Head Needed","Clear Head Member"),IF(C13="","Select Head Member",IF(C13=A13,"Invalid - Same Applicant",IF(B13="Senior Sales Manager",IF(COUNTIF(Teams!$A$2:$A$1001,C13)=1,"VD selected - Verify ID","Missing/Ambiguous VD"),IF(B13="Sales Manager",IF(COUNTIF(Teams!$B$2:$B$1001,C13)=1,"SSM selected - Verify ID","Missing/Ambiguous SSM"),"Invalid Position")))))))
... A501: =IF(OR(Identity!B501="",Identity!D501=""),"",TRIM(Identity!B501&" "&Identity!C501&" "&Identity!D501)) | D501: =IF(A501="","",IF(B501="","Select Position",IF(B501="Vice Director",IF(C501="","Ready - No Head Needed","Clear Head Member"),IF(C501="","Select Head Member",IF(C501=A501,"Invalid - Same Applicant",IF(B501="Senior Sales Manager",IF(COUNTIF(Teams!$A$2:$A$1001,C501)=1,"VD selected - Verify ID","Missing/Ambiguous VD"),IF(B501="Sales Manager",IF(COUNTIF(Teams!$B$2:$B$1001,C501)=1,"SSM selected - Verify ID","Missing/Ambiguous SSM"),"Invalid Position")))))))

Sheet Details
A1: Applicant Name (Auto) | B1: Government ID Type | C1: Government ID Number | D1: TIN | E1: Telephone | F1: Messenger | G1: Employer Name | H1: Employer Address | I1: Job Position
A2: =IF(OR(Identity!B2="",Identity!D2=""),"",TRIM(Identity!B2&" "&Identity!C2&" "&Identity!D2))
A3: =IF(OR(Identity!B3="",Identity!D3=""),"",TRIM(Identity!B3&" "&Identity!C3&" "&Identity!D3))
A4: =IF(OR(Identity!B4="",Identity!D4=""),"",TRIM(Identity!B4&" "&Identity!C4&" "&Identity!D4))
A5: =IF(OR(Identity!B5="",Identity!D5=""),"",TRIM(Identity!B5&" "&Identity!C5&" "&Identity!D5))
A6: =IF(OR(Identity!B6="",Identity!D6=""),"",TRIM(Identity!B6&" "&Identity!C6&" "&Identity!D6))
A7: =IF(OR(Identity!B7="",Identity!D7=""),"",TRIM(Identity!B7&" "&Identity!C7&" "&Identity!D7))
A8: =IF(OR(Identity!B8="",Identity!D8=""),"",TRIM(Identity!B8&" "&Identity!C8&" "&Identity!D8))
A9: =IF(OR(Identity!B9="",Identity!D9=""),"",TRIM(Identity!B9&" "&Identity!C9&" "&Identity!D9))
A10: =IF(OR(Identity!B10="",Identity!D10=""),"",TRIM(Identity!B10&" "&Identity!C10&" "&Identity!D10))
A11: =IF(OR(Identity!B11="",Identity!D11=""),"",TRIM(Identity!B11&" "&Identity!C11&" "&Identity!D11))
A12: =IF(OR(Identity!B12="",Identity!D12=""),"",TRIM(Identity!B12&" "&Identity!C12&" "&Identity!D12))
A13: =IF(OR(Identity!B13="",Identity!D13=""),"",TRIM(Identity!B13&" "&Identity!C13&" "&Identity!D13))
... A501: =IF(OR(Identity!B501="",Identity!D501=""),"",TRIM(Identity!B501&" "&Identity!C501&" "&Identity!D501))

Sheet Teams
A1: Vice Director Names | B1: Senior Sales Manager Names | C1: Sales Manager Names
A2: =IF(Team!$B2="Vice Director",Team!$A2,"") | B2: =IF(Team!$B2="Senior Sales Manager",Team!$A2,"") | C2: =IF(Team!$B2="Sales Manager",Team!$A2,"")
A3: =IF(Team!$B3="Vice Director",Team!$A3,"") | B3: =IF(Team!$B3="Senior Sales Manager",Team!$A3,"") | C3: =IF(Team!$B3="Sales Manager",Team!$A3,"")
A4: =IF(Team!$B4="Vice Director",Team!$A4,"") | B4: =IF(Team!$B4="Senior Sales Manager",Team!$A4,"") | C4: =IF(Team!$B4="Sales Manager",Team!$A4,"")
A5: =IF(Team!$B5="Vice Director",Team!$A5,"") | B5: =IF(Team!$B5="Senior Sales Manager",Team!$A5,"") | C5: =IF(Team!$B5="Sales Manager",Team!$A5,"")
A6: =IF(Team!$B6="Vice Director",Team!$A6,"") | B6: =IF(Team!$B6="Senior Sales Manager",Team!$A6,"") | C6: =IF(Team!$B6="Sales Manager",Team!$A6,"")
A7: =IF(Team!$B7="Vice Director",Team!$A7,"") | B7: =IF(Team!$B7="Senior Sales Manager",Team!$A7,"") | C7: =IF(Team!$B7="Sales Manager",Team!$A7,"")
A8: =IF(Team!$B8="Vice Director",Team!$A8,"") | B8: =IF(Team!$B8="Senior Sales Manager",Team!$A8,"") | C8: =IF(Team!$B8="Sales Manager",Team!$A8,"")
A9: =IF(Team!$B9="Vice Director",Team!$A9,"") | B9: =IF(Team!$B9="Senior Sales Manager",Team!$A9,"") | C9: =IF(Team!$B9="Sales Manager",Team!$A9,"")
A10: =IF(Team!$B10="Vice Director",Team!$A10,"") | B10: =IF(Team!$B10="Senior Sales Manager",Team!$A10,"") | C10: =IF(Team!$B10="Sales Manager",Team!$A10,"")
A11: =IF(Team!$B11="Vice Director",Team!$A11,"") | B11: =IF(Team!$B11="Senior Sales Manager",Team!$A11,"") | C11: =IF(Team!$B11="Sales Manager",Team!$A11,"")
A12: =IF(Team!$B12="Vice Director",Team!$A12,"") | B12: =IF(Team!$B12="Senior Sales Manager",Team!$A12,"") | C12: =IF(Team!$B12="Sales Manager",Team!$A12,"")
A13: =IF(Team!$B13="Vice Director",Team!$A13,"") | B13: =IF(Team!$B13="Senior Sales Manager",Team!$A13,"") | C13: =IF(Team!$B13="Sales Manager",Team!$A13,"")
... A501: =IF(Team!$B501="Vice Director",Team!$A501,"") | B501: =IF(Team!$B501="Senior Sales Manager",Team!$A501,"") | C501: =IF(Team!$B501="Sales Manager",Team!$A501,"")

Sheet _HeadMatches
A2: =IF(Team!$E$2="","",IFERROR(_xlfn._xlws.FILTER(Teams!$A$2:$A$1001,(Teams!$A$2:$A$1001<>"")*ISNUMBER(SEARCH(Team!$E$2,Teams!$A$2:$A$1001))),"")) | B2: =IF(Team!$E$2="","",IFERROR(_xlfn._xlws.FILTER(Teams!$B$2:$B$1001,(Teams!$B$2:$B$1001<>"")*ISNUMBER(SEARCH(Team!$E$2,Teams!$B$2:$B$1001))),"")) | D2: =IF(Identity!$A2="",TRUE,IFERROR(AND(ISTEXT(Identity!$A2),EXACT(Identity!$A2,UPPER(Identity!$A2)),COUNTIF(Identity!$A$2:$A$501,Identity!$A2)=1,OR(AND(LEFT(Identity!$A2,3)="AAI",LEN(Identity!$A2)=11,SUMPRODUCT(--ISNUMBER(FIND(MID(Identity!$A2,ROW($4:$11),1),"0123456789")))=8,IFERROR(VALUE(MID(Identity!$A2,6,2)),0)>=1,IFERROR(VALUE(MID(Identity!$A2,6,2)),0)<=12,RIGHT(Identity!$A2,4)<>"0000"),AND(LEFT(Identity!$A2,3)="AA-",LEN(Identity!$A2)=15,SUMPRODUCT(--ISNUMBER(FIND(MID(Identity!$A2,ROW($4:$15),1),"ABCDEFGHIJKLMNOPQRSTUVWXYZ")))=6,SUMPRODUCT(--ISNUMBER(FIND(MID(Identity!$A2,ROW($4:$15),1),"0123456789")))=6))),FALSE))
D3: =IF(Identity!$A3="",TRUE,IFERROR(AND(ISTEXT(Identity!$A3),EXACT(Identity!$A3,UPPER(Identity!$A3)),COUNTIF(Identity!$A$2:$A$501,Identity!$A3)=1,OR(AND(LEFT(Identity!$A3,3)="AAI",LEN(Identity!$A3)=11,SUMPRODUCT(--ISNUMBER(FIND(MID(Identity!$A3,ROW($4:$11),1),"0123456789")))=8,IFERROR(VALUE(MID(Identity!$A3,6,2)),0)>=1,IFERROR(VALUE(MID(Identity!$A3,6,2)),0)<=12,RIGHT(Identity!$A3,4)<>"0000"),AND(LEFT(Identity!$A3,3)="AA-",LEN(Identity!$A3)=15,SUMPRODUCT(--ISNUMBER(FIND(MID(Identity!$A3,ROW($4:$15),1),"ABCDEFGHIJKLMNOPQRSTUVWXYZ")))=6,SUMPRODUCT(--ISNUMBER(FIND(MID(Identity!$A3,ROW($4:$15),1),"0123456789")))=6))),FALSE))
D4: =IF(Identity!$A4="",TRUE,IFERROR(AND(ISTEXT(Identity!$A4),EXACT(Identity!$A4,UPPER(Identity!$A4)),COUNTIF(Identity!$A$2:$A$501,Identity!$A4)=1,OR(AND(LEFT(Identity!$A4,3)="AAI",LEN(Identity!$A4)=11,SUMPRODUCT(--ISNUMBER(FIND(MID(Identity!$A4,ROW($4:$11),1),"0123456789")))=8,IFERROR(VALUE(MID(Identity!$A4,6,2)),0)>=1,IFERROR(VALUE(MID(Identity!$A4,6,2)),0)<=12,RIGHT(Identity!$A4,4)<>"0000"),AND(LEFT(Identity!$A4,3)="AA-",LEN(Identity!$A4)=15,SUMPRODUCT(--ISNUMBER(FIND(MID(Identity!$A4,ROW($4:$15),1),"ABCDEFGHIJKLMNOPQRSTUVWXYZ")))=6,SUMPRODUCT(--ISNUMBER(FIND(MID(Identity!$A4,ROW($4:$15),1),"0123456789")))=6))),FALSE))
D5: =IF(Identity!$A5="",TRUE,IFERROR(AND(ISTEXT(Identity!$A5),EXACT(Identity!$A5,UPPER(Identity!$A5)),COUNTIF(Identity!$A$2:$A$501,Identity!$A5)=1,OR(AND(LEFT(Identity!$A5,3)="AAI",LEN(Identity!$A5)=11,SUMPRODUCT(--ISNUMBER(FIND(MID(Identity!$A5,ROW($4:$11),1),"0123456789")))=8,IFERROR(VALUE(MID(Identity!$A5,6,2)),0)>=1,IFERROR(VALUE(MID(Identity!$A5,6,2)),0)<=12,RIGHT(Identity!$A5,4)<>"0000"),AND(LEFT(Identity!$A5,3)="AA-",LEN(Identity!$A5)=15,SUMPRODUCT(--ISNUMBER(FIND(MID(Identity!$A5,ROW($4:$15),1),"ABCDEFGHIJKLMNOPQRSTUVWXYZ")))=6,SUMPRODUCT(--ISNUMBER(FIND(MID(Identity!$A5,ROW($4:$15),1),"0123456789")))=6))),FALSE))
D6: =IF(Identity!$A6="",TRUE,IFERROR(AND(ISTEXT(Identity!$A6),EXACT(Identity!$A6,UPPER(Identity!$A6)),COUNTIF(Identity!$A$2:$A$501,Identity!$A6)=1,OR(AND(LEFT(Identity!$A6,3)="AAI",LEN(Identity!$A6)=11,SUMPRODUCT(--ISNUMBER(FIND(MID(Identity!$A6,ROW($4:$11),1),"0123456789")))=8,IFERROR(VALUE(MID(Identity!$A6,6,2)),0)>=1,IFERROR(VALUE(MID(Identity!$A6,6,2)),0)<=12,RIGHT(Identity!$A6,4)<>"0000"),AND(LEFT(Identity!$A6,3)="AA-",LEN(Identity!$A6)=15,SUMPRODUCT(--ISNUMBER(FIND(MID(Identity!$A6,ROW($4:$15),1),"ABCDEFGHIJKLMNOPQRSTUVWXYZ")))=6,SUMPRODUCT(--ISNUMBER(FIND(MID(Identity!$A6,ROW($4:$15),1),"0123456789")))=6))),FALSE))
D7: =IF(Identity!$A7="",TRUE,IFERROR(AND(ISTEXT(Identity!$A7),EXACT(Identity!$A7,UPPER(Identity!$A7)),COUNTIF(Identity!$A$2:$A$501,Identity!$A7)=1,OR(AND(LEFT(Identity!$A7,3)="AAI",LEN(Identity!$A7)=11,SUMPRODUCT(--ISNUMBER(FIND(MID(Identity!$A7,ROW($4:$11),1),"0123456789")))=8,IFERROR(VALUE(MID(Identity!$A7,6,2)),0)>=1,IFERROR(VALUE(MID(Identity!$A7,6,2)),0)<=12,RIGHT(Identity!$A7,4)<>"0000"),AND(LEFT(Identity!$A7,3)="AA-",LEN(Identity!$A7)=15,SUMPRODUCT(--ISNUMBER(FIND(MID(Identity!$A7,ROW($4:$15),1),"ABCDEFGHIJKLMNOPQRSTUVWXYZ")))=6,SUMPRODUCT(--ISNUMBER(FIND(MID(Identity!$A7,ROW($4:$15),1),"0123456789")))=6))),FALSE))
D8: =IF(Identity!$A8="",TRUE,IFERROR(AND(ISTEXT(Identity!$A8),EXACT(Identity!$A8,UPPER(Identity!$A8)),COUNTIF(Identity!$A$2:$A$501,Identity!$A8)=1,OR(AND(LEFT(Identity!$A8,3)="AAI",LEN(Identity!$A8)=11,SUMPRODUCT(--ISNUMBER(FIND(MID(Identity!$A8,ROW($4:$11),1),"0123456789")))=8,IFERROR(VALUE(MID(Identity!$A8,6,2)),0)>=1,IFERROR(VALUE(MID(Identity!$A8,6,2)),0)<=12,RIGHT(Identity!$A8,4)<>"0000"),AND(LEFT(Identity!$A8,3)="AA-",LEN(Identity!$A8)=15,SUMPRODUCT(--ISNUMBER(FIND(MID(Identity!$A8,ROW($4:$15),1),"ABCDEFGHIJKLMNOPQRSTUVWXYZ")))=6,SUMPRODUCT(--ISNUMBER(FIND(MID(Identity!$A8,ROW($4:$15),1),"0123456789")))=6))),FALSE))
D9: =IF(Identity!$A9="",TRUE,IFERROR(AND(ISTEXT(Identity!$A9),EXACT(Identity!$A9,UPPER(Identity!$A9)),COUNTIF(Identity!$A$2:$A$501,Identity!$A9)=1,OR(AND(LEFT(Identity!$A9,3)="AAI",LEN(Identity!$A9)=11,SUMPRODUCT(--ISNUMBER(FIND(MID(Identity!$A9,ROW($4:$11),1),"0123456789")))=8,IFERROR(VALUE(MID(Identity!$A9,6,2)),0)>=1,IFERROR(VALUE(MID(Identity!$A9,6,2)),0)<=12,RIGHT(Identity!$A9,4)<>"0000"),AND(LEFT(Identity!$A9,3)="AA-",LEN(Identity!$A9)=15,SUMPRODUCT(--ISNUMBER(FIND(MID(Identity!$A9,ROW($4:$15),1),"ABCDEFGHIJKLMNOPQRSTUVWXYZ")))=6,SUMPRODUCT(--ISNUMBER(FIND(MID(Identity!$A9,ROW($4:$15),1),"0123456789")))=6))),FALSE))
D10: =IF(Identity!$A10="",TRUE,IFERROR(AND(ISTEXT(Identity!$A10),EXACT(Identity!$A10,UPPER(Identity!$A10)),COUNTIF(Identity!$A$2:$A$501,Identity!$A10)=1,OR(AND(LEFT(Identity!$A10,3)="AAI",LEN(Identity!$A10)=11,SUMPRODUCT(--ISNUMBER(FIND(MID(Identity!$A10,ROW($4:$11),1),"0123456789")))=8,IFERROR(VALUE(MID(Identity!$A10,6,2)),0)>=1,IFERROR(VALUE(MID(Identity!$A10,6,2)),0)<=12,RIGHT(Identity!$A10,4)<>"0000"),AND(LEFT(Identity!$A10,3)="AA-",LEN(Identity!$A10)=15,SUMPRODUCT(--ISNUMBER(FIND(MID(Identity!$A10,ROW($4:$15),1),"ABCDEFGHIJKLMNOPQRSTUVWXYZ")))=6,SUMPRODUCT(--ISNUMBER(FIND(MID(Identity!$A10,ROW($4:$15),1),"0123456789")))=6))),FALSE))
D11: =IF(Identity!$A11="",TRUE,IFERROR(AND(ISTEXT(Identity!$A11),EXACT(Identity!$A11,UPPER(Identity!$A11)),COUNTIF(Identity!$A$2:$A$501,Identity!$A11)=1,OR(AND(LEFT(Identity!$A11,3)="AAI",LEN(Identity!$A11)=11,SUMPRODUCT(--ISNUMBER(FIND(MID(Identity!$A11,ROW($4:$11),1),"0123456789")))=8,IFERROR(VALUE(MID(Identity!$A11,6,2)),0)>=1,IFERROR(VALUE(MID(Identity!$A11,6,2)),0)<=12,RIGHT(Identity!$A11,4)<>"0000"),AND(LEFT(Identity!$A11,3)="AA-",LEN(Identity!$A11)=15,SUMPRODUCT(--ISNUMBER(FIND(MID(Identity!$A11,ROW($4:$15),1),"ABCDEFGHIJKLMNOPQRSTUVWXYZ")))=6,SUMPRODUCT(--ISNUMBER(FIND(MID(Identity!$A11,ROW($4:$15),1),"0123456789")))=6))),FALSE))
D12: =IF(Identity!$A12="",TRUE,IFERROR(AND(ISTEXT(Identity!$A12),EXACT(Identity!$A12,UPPER(Identity!$A12)),COUNTIF(Identity!$A$2:$A$501,Identity!$A12)=1,OR(AND(LEFT(Identity!$A12,3)="AAI",LEN(Identity!$A12)=11,SUMPRODUCT(--ISNUMBER(FIND(MID(Identity!$A12,ROW($4:$11),1),"0123456789")))=8,IFERROR(VALUE(MID(Identity!$A12,6,2)),0)>=1,IFERROR(VALUE(MID(Identity!$A12,6,2)),0)<=12,RIGHT(Identity!$A12,4)<>"0000"),AND(LEFT(Identity!$A12,3)="AA-",LEN(Identity!$A12)=15,SUMPRODUCT(--ISNUMBER(FIND(MID(Identity!$A12,ROW($4:$15),1),"ABCDEFGHIJKLMNOPQRSTUVWXYZ")))=6,SUMPRODUCT(--ISNUMBER(FIND(MID(Identity!$A12,ROW($4:$15),1),"0123456789")))=6))),FALSE))
D13: =IF(Identity!$A13="",TRUE,IFERROR(AND(ISTEXT(Identity!$A13),EXACT(Identity!$A13,UPPER(Identity!$A13)),COUNTIF(Identity!$A$2:$A$501,Identity!$A13)=1,OR(AND(LEFT(Identity!$A13,3)="AAI",LEN(Identity!$A13)=11,SUMPRODUCT(--ISNUMBER(FIND(MID(Identity!$A13,ROW($4:$11),1),"0123456789")))=8,IFERROR(VALUE(MID(Identity!$A13,6,2)),0)>=1,IFERROR(VALUE(MID(Identity!$A13,6,2)),0)<=12,RIGHT(Identity!$A13,4)<>"0000"),AND(LEFT(Identity!$A13,3)="AA-",LEN(Identity!$A13)=15,SUMPRODUCT(--ISNUMBER(FIND(MID(Identity!$A13,ROW($4:$15),1),"ABCDEFGHIJKLMNOPQRSTUVWXYZ")))=6,SUMPRODUCT(--ISNUMBER(FIND(MID(Identity!$A13,ROW($4:$15),1),"0123456789")))=6))),FALSE))
D14: =IF(Identity!$A14="",TRUE,IFERROR(AND(ISTEXT(Identity!$A14),EXACT(Identity!$A14,UPPER(Identity!$A14)),COUNTIF(Identity!$A$2:$A$501,Identity!$A14)=1,OR(AND(LEFT(Identity!$A14,3)="AAI",LEN(Identity!$A14)=11,SUMPRODUCT(--ISNUMBER(FIND(MID(Identity!$A14,ROW($4:$11),1),"0123456789")))=8,IFERROR(VALUE(MID(Identity!$A14,6,2)),0)>=1,IFERROR(VALUE(MID(Identity!$A14,6,2)),0)<=12,RIGHT(Identity!$A14,4)<>"0000"),AND(LEFT(Identity!$A14,3)="AA-",LEN(Identity!$A14)=15,SUMPRODUCT(--ISNUMBER(FIND(MID(Identity!$A14,ROW($4:$15),1),"ABCDEFGHIJKLMNOPQRSTUVWXYZ")))=6,SUMPRODUCT(--ISNUMBER(FIND(MID(Identity!$A14,ROW($4:$15),1),"0123456789")))=6))),FALSE))
... D501: =IF(Identity!$A501="",TRUE,IFERROR(AND(ISTEXT(Identity!$A501),EXACT(Identity!$A501,UPPER(Identity!$A501)),COUNTIF(Identity!$A$2:$A$501,Identity!$A501)=1,OR(AND(LEFT(Identity!$A501,3)="AAI",LEN(Identity!$A501)=11,SUMPRODUCT(--ISNUMBER(FIND(MID(Identity!$A501,ROW($4:$11),1),"0123456789")))=8,IFERROR(VALUE(MID(Identity!$A501,6,2)),0)>=1,IFERROR(VALUE(MID(Identity!$A501,6,2)),0)<=12,RIGHT(Identity!$A501,4)<>"0000"),AND(LEFT(Identity!$A501,3)="AA-",LEN(Identity!$A501)=15,SUMPRODUCT(--ISNUMBER(FIND(MID(Identity!$A501,ROW($4:$15),1),"ABCDEFGHIJKLMNOPQRSTUVWXYZ")))=6,SUMPRODUCT(--ISNUMBER(FIND(MID(Identity!$A501,ROW($4:$15),1),"0123456789")))=6))),FALSE))

Sheet Postal
A1: Province|City | B1: ZIP
A2: Abra|Bangued | B2: 2800
A3: Abra|Boliney | B3: 2815
A4: Abra|Bucay | B4: 2805
A5: Abra|Bucloc | B5: 2817
A6: Abra|Daguioman | B6: 2816
A7: Abra|Danglas | B7: 2825
A8: Abra|Dolores | B8: 2801
A9: Abra|La Paz | B9: 2826
A10: Abra|Lacub | B10: 2821
A11: Abra|Lagangilang | B11: 2802
A12: Abra|Lagayan | B12: 2824
... A121: Aurora|San Luis | B121: 3201
A122: Basilan|Akbar
A123: Basilan|Al-Barka
A124: Basilan|City of Lamitan | B124: 7302
A125: Basilan|Hadji Mohammad Ajul
A126: Basilan|Hadji Muhtamad
A127: Basilan|Lantawan | B127: 7301
A128: Basilan|Maluso | B128: 7303
A129: Basilan|Sumisip | B129: 7305
A130: Basilan|Tabuan-Lasa
A131: Basilan|Tipo-Tipo | B131: 7304
A132: Basilan|Tuburan | B132: 7306
A133: Basilan|Ungkaya Pukan
A134: Bataan|Abucay | B134: 2114
A135: Bataan|Bagac | B135: 2107
A136: Bataan|City of Balanga | B136: 2100
A137: Bataan|Dinalupihan | B137: 2110
A138: Bataan|Hermosa | B138: 2111
A139: Bataan|Limay | B139: 2103
A140: Bataan|Mariveles | B140: 2105
A141: Bataan|Morong | B141: 2108
A142: Bataan|Orani | B142: 2112
A143: Bataan|Orion | B143: 2102
A144: Bataan|Pilar | B144: 2101
A145: Bataan|Samal | B145: 2113
... A230: Bohol|Garcia Hernandez | B230: 6307
A231: Bohol|Getafe
A232: Bohol|Guindulman | B232: 6310
...

Sheet PSGC_ProvinceList
A1: Province / Region for independent cities
A2: Abra
A3: Agusan del Norte
A4: Agusan del Sur
A5: Aklan
A6: Albay
A7: Antique
A8: Apayao
A9: Aurora
A10: Basilan
A11: Bataan
A12: Batanes
... A99: Zamboanga Sibugay

Sheet PSGC_CityList
A1: Province / region | B1: City / municipality | C1: Postal Code | D1: Postal Source
A2: Abra | B2: Bangued | C2: 2800 | D2: PHLPost
A3: Abra | B3: Boliney | C3: 2815 | D3: PHLPost
A4: Abra | B4: Bucay | C4: 2805 | D4: PHLPost
A5: Abra | B5: Bucloc | C5: 2817 | D5: PHLPost
A6: Abra | B6: Daguioman | C6: 2816 | D6: PHLPost
A7: Abra | B7: Danglas | C7: 2825 | D7: PHLPost
A8: Abra | B8: Dolores | C8: 2801 | D8: PHLPost
A9: Abra | B9: La Paz | C9: 2826 | D9: PHLPost
A10: Abra | B10: Lacub | C10: 2821 | D10: PHLPost
A11: Abra | B11: Lagangilang | C11: 2802 | D11: PHLPost
A12: Abra | B12: Lagayan | C12: 2824 | D12: PHLPost
... A121: Aurora | B121: San Luis | C121: 3201 | D121: PHLPost
A122: Basilan | B122: Akbar | D122: Needs verification
A123: Basilan | B123: Al-Barka | D123: Needs verification
A124: Basilan | B124: City of Lamitan | C124: 7302 | D124: BarangayDirectory
A125: Basilan | B125: Hadji Mohammad Ajul | D125: Needs verification
A126: Basilan | B126: Hadji Muhtamad | D126: Needs verification
A127: Basilan | B127: Lantawan | C127: 7301 | D127: BarangayDirectory
A128: Basilan | B128: Maluso | C128: 7303 | D128: BarangayDirectory
A129: Basilan | B129: Sumisip | C129: 7305 | D129: BarangayDirectory
A130: Basilan | B130: Tabuan-Lasa | D130: Needs verification
A131: Basilan | B131: Tipo-Tipo | C131: 7304 | D131: BarangayDirectory
A132: Basilan | B132: Tuburan | C132: 7306 | D132: BarangayDirectory
A133: Basilan | B133: Ungkaya Pukan | D133: Needs verification
A134: Bataan | B134: Abucay | C134: 2114 | D134: PHLPost
A135: Bataan | B135: Bagac | C135: 2107 | D135: PHLPost
A136: Bataan | B136: City of Balanga | C136: 2100 | D136: PHLPost
A137: Bataan | B137: Dinalupihan | C137: 2110 | D137: PHLPost
A138: Bataan | B138: Hermosa | C138: 2111 | D138: PHLPost
A139: Bataan | B139: Limay | C139: 2103 | D139: PHLPost
A140: Bataan | B140: Mariveles | C140: 2105 | D140: BarangayDirectory
A141: Bataan | B141: Morong | C141: 2108 | D141: BarangayDirectory
A142: Bataan | B142: Orani | C142: 2112 | D142: BarangayDirectory
A143: Bataan | B143: Orion | C143: 2102 | D143: BarangayDirectory
A144: Bataan | B144: Pilar | C144: 2101 | D144: BarangayDirectory
A145: Bataan | B145: Samal | C145: 2113 | D145: BarangayDirectory
... A230: Bohol | B230: Garcia Hernandez | C230: 6307 | D230: BarangayDirectory
A231: Bohol | B231: Getafe | D231: Needs verification
A232: Bohol | B232: Guindulman | C232: 6310 | D232: BarangayDirectory
...

Sheet PSGC_BarangayList
A1: Barangay
A2: Agtangao
A3: Angad
A4: Bangbangar
A5: Bañacao
A6: Cabuloan
A7: Calaba
A8: Cosili East
A9: Cosili West
A10: Dangdangla
A11: Lingtan
A12: Lipcan
... A42011: Upper Tungawan

Sheet PSGC_ProvinceIndex
A1: Province | B1: City list start row | C1: City count
A2: Abra | B2: 2 | C2: 27
A3: Agusan del Norte | B3: 29 | C3: 11
A4: Agusan del Sur | B4: 40 | C4: 14
A5: Aklan | B5: 54 | C5: 17
A6: Albay | B6: 71 | C6: 18
A7: Antique | B7: 89 | C7: 18
A8: Apayao | B8: 107 | C8: 7
A9: Aurora | B9: 114 | C9: 8
A10: Basilan | B10: 122 | C10: 12
A11: Bataan | B11: 134 | C11: 12
A12: Batanes | B12: 146 | C12: 6
A13: Batangas | B13: 152 | C13: 34
... A99: Zamboanga Sibugay | B99: 1628 | C99: 16

Sheet PSGC_CityIndex
A1: Province|City | B1: Barangay list start row | C1: Barangay count
A2: Abra|Bangued | B2: 2 | C2: 31
A3: Abra|Boliney | B3: 33 | C3: 8
A4: Abra|Bucay | B4: 41 | C4: 21
A5: Abra|Bucloc | B5: 62 | C5: 4
A6: Abra|Daguioman | B6: 66 | C6: 4
A7: Abra|Danglas | B7: 70 | C7: 7
A8: Abra|Dolores | B8: 77 | C8: 15
A9: Abra|La Paz | B9: 92 | C9: 12
A10: Abra|Lacub | B10: 104 | C10: 6
A11: Abra|Lagangilang | B11: 110 | C11: 17
A12: Abra|Lagayan | B12: 127 | C12: 5
A13: Abra|Langiden | B13: 132 | C13: 6
... A1643: Zamboanga Sibugay|Tungawan | B1643: 41987 | C1643: 25

Sheet Date Helper
A1: AF HOMES OST | DATE ENTRY HELPER | J1: Month List | L1: Year List | N1: Day List
A2: Choose Year, Month and Day. Copy the Date Result as a VALUE into any date field. | J2: January | L2: 1900 | N2: 1
J3: February | L3: 1901 | N3: 2
A4: Year | J4: March | L4: 1902 | N4: 3
A5: Month | J5: April | L5: 1903 | N5: 4
A6: Day | J6: May | L6: 1904 | N6: 5
J7: June | L7: 1905 | N7: 6
A8: Date Result (copy) | B8: =IF(OR(B4="",B5="",B6=""),"",IF(OR(B6<1,B6>DAY(EOMONTH(DATE(B4,MATCH(B5,$J$2:$J$13,0),1),0))),"INVALID DAY",DATE(B4,MATCH(B5,$J$2:$J$13,0),B6))) | J8: July | L8: 1906 | N8: 7
J9: August | L9: 1907 | N9: 8
A10: CALENDAR PREVIEW — select the day above; this grid is for reference. | J10: September | L10: 1908 | N10: 9
A11: Mon | B11: Tue | C11: Wed | D11: Thu | E11: Fri | F11: Sat | G11: Sun | J11: October | L11: 1909 | N11: 10
A12: =IF(OR($B$4="",$B$5=""),"",IF(MONTH(DATE($B$4,MATCH($B$5,$J$2:$J$13,0),1)-WEEKDAY(DATE($B$4,MATCH($B$5,$J$2:$J$13,0),1),2)+1+0)<>MATCH($B$5,$J$2:$J$13,0),"",DAY(DATE($B$4,MATCH($B$5,$J$2:$J$13,0),1)-WEEKDAY(DATE($B$4,MATCH($B$5,$J$2:$J$13,0),1),2)+1+0))) | B12: =IF(OR($B$4="",$B$5=""),"",IF(MONTH(DATE($B$4,MATCH($B$5,$J$2:$J$13,0),1)-WEEKDAY(DATE($B$4,MATCH($B$5,$J$2:$J$13,0),1),2)+1+1)<>MATCH($B$5,$J$2:$J$13,0),"",DAY(DATE($B$4,MATCH($B$5,$J$2:$J$13,0),1)-WEEKDAY(DATE($B$4,MATCH($B$5,$J$2:$J$13,0),1),2)+1+1))) | C12: =IF(OR($B$4="",$B$5=""),"",IF(MONTH(DATE($B$4,MATCH($B$5,$J$2:$J$13,0),1)-WEEKDAY(DATE($B$4,MATCH($B$5,$J$2:$J$13,0),1),2)+1+2)<>MATCH($B$5,$J$2:$J$13,0),"",DAY(DATE($B$4,MATCH($B$5,$J$2:$J$13,0),1)-WEEKDAY(DATE($B$4,MATCH($B$5,$J$2:$J$13,0),1),2)+1+2))) | D12: =IF(OR($B$4="",$B$5=""),"",IF(MONTH(DATE($B$4,MATCH($B$5,$J$2:$J$13,0),1)-WEEKDAY(DATE($B$4,MATCH($B$5,$J$2:$J$13,0),1),2)+1+3)<>MATCH($B$5,$J$2:$J$13,0),"",DAY(DATE($B$4,MATCH($B$5,$J$2:$J$13,0),1)-WEEKDAY(DATE($B$4,MATCH($B$5,$J$2:$J$13,0),1),2)+1+3))) | E12: =IF(OR($B$4="",$B$5=""),"",IF(MONTH(DATE($B$4,MATCH($B$5,$J$2:$J$13,0),1)-WEEKDAY(DATE($B$4,MATCH($B$5,$J$2:$J$13,0),1),2)+1+4)<>MATCH($B$5,$J$2:$J$13,0),"",DAY(DATE($B$4,MATCH($B$5,$J$2:$J$13,0),1)-WEEKDAY(DATE($B$4,MATCH($B$5,$J$2:$J$13,0),1),2)+1+4))) | F12: =IF(OR($B$4="",$B$5=""),"",IF(MONTH(DATE($B$4,MATCH($B$5,$J$2:$J$13,0),1)-WEEKDAY(DATE($B$4,MATCH($B$5,$J$2:$J$13,0),1),2)+1+5)<>MATCH($B$5,$J$2:$J$13,0),"",DAY(DATE($B$4,MATCH($B$5,$J$2:$J$13,0),1)-WEEKDAY(DATE($B$4,MATCH($B$5,$J$2:$J$13,0),1),2)+1+5))) | G12: =IF(OR($B$4="",$B$5=""),"",IF(MONTH(DATE($B$4,MATCH($B$5,$J$2:$J$13,0),1)-WEEKDAY(DATE($B$4,MATCH($B$5,$J$2:$J$13,0),1),2)+1+6)<>MATCH($B$5,$J$2:$J$13,0),"",DAY(DATE($B$4,MATCH($B$5,$J$2:$J$13,0),1)-WEEKDAY(DATE($B$4,MATCH($B$5,$J$2:$J$13,0),1),2)+1+6))) | J12: November | L12: 1910 | N12: 11
A13: =IF(OR($B$4="",$B$5=""),"",IF(MONTH(DATE($B$4,MATCH($B$5,$J$2:$J$13,0),1)-WEEKDAY(DATE($B$4,MATCH($B$5,$J$2:$J$13,0),1),2)+1+7)<>MATCH($B$5,$J$2:$J$13,0),"",DAY(DATE($B$4,MATCH($B$5,$J$2:$J$13,0),1)-WEEKDAY(DATE($B$4,MATCH($B$5,$J$2:$J$13,0),1),2)+1+7))) | B13: =IF(OR($B$4="",$B$5=""),"",IF(MONTH(DATE($B$4,MATCH($B$5,$J$2:$J$13,0),1)-WEEKDAY(DATE($B$4,MATCH($B$5,$J$2:$J$13,0),1),2)+1+8)<>MATCH($B$5,$J$2:$J$13,0),"",DAY(DATE($B$4,MATCH($B$5,$J$2:$J$13,0),1)-WEEKDAY(DATE($B$4,MATCH($B$5,$J$2:$J$13,0),1),2)+1+8))) | C13: =IF(OR($B$4="",$B$5=""),"",IF(MONTH(DATE($B$4,MATCH($B$5,$J$2:$J$13,0),1)-WEEKDAY(DATE($B$4,MATCH($B$5,$J$2:$J$13,0),1),2)+1+9)<>MATCH($B$5,$J$2:$J$13,0),"",DAY(DATE($B$4,MATCH($B$5,$J$2:$J$13,0),1)-WEEKDAY(DATE($B$4,MATCH($B$5,$J$2:$J$13,0),1),2)+1+9))) | D13: =IF(OR($B$4="",$B$5=""),"",IF(MONTH(DATE($B$4,MATCH($B$5,$J$2:$J$13,0),1)-WEEKDAY(DATE($B$4,MATCH($B$5,$J$2:$J$13,0),1),2)+1+10)<>MATCH($B$5,$J$2:$J$13,0),"",DAY(DATE($B$4,MATCH($B$5,$J$2:$J$13,0),1)-WEEKDAY(DATE($B$4,MATCH($B$5,$J$2:$J$13,0),1),2)+1+10))) | E13: =IF(OR($B$4="",$B$5=""),"",IF(MONTH(DATE($B$4,MATCH($B$5,$J$2:$J$13,0),1)-WEEKDAY(DATE($B$4,MATCH($B$5,$J$2:$J$13,0),1),2)+1+11)<>MATCH($B$5,$J$2:$J$13,0),"",DAY(DATE($B$4,MATCH($B$5,$J$2:$J$13,0),1)-WEEKDAY(DATE($B$4,MATCH($B$5,$J$2:$J$13,0),1),2)+1+11))) | F13: =IF(OR($B$4="",$B$5=""),"",IF(MONTH(DATE($B$4,MATCH($B$5,$J$2:$J$13,0),1)-WEEKDAY(DATE($B$4,MATCH($B$5,$J$2:$J$13,0),1),2)+1+12)<>MATCH($B$5,$J$2:$J$13,0),"",DAY(DATE($B$4,MATCH($B$5,$J$2:$J$13,0),1)-WEEKDAY(DATE($B$4,MATCH($B$5,$J$2:$J$13,0),1),2)+1+12))) | G13: =IF(OR($B$4="",$B$5=""),"",IF(MONTH(DATE($B$4,MATCH($B$5,$J$2:$J$13,0),1)-WEEKDAY(DATE($B$4,MATCH($B$5,$J$2:$J$13,0),1),2)+1+13)<>MATCH($B$5,$J$2:$J$13,0),"",DAY(DATE($B$4,MATCH($B$5,$J$2:$J$13,0),1)-WEEKDAY(DATE($B$4,MATCH($B$5,$J$2:$J$13,0),1),2)+1+13))) | J13: December | L13: 1911 | N13: 12
A14: =IF(OR($B$4="",$B$5=""),"",IF(MONTH(DATE($B$4,MATCH($B$5,$J$2:$J$13,0),1)-WEEKDAY(DATE($B$4,MATCH($B$5,$J$2:$J$13,0),1),2)+1+14)<>MATCH($B$5,$J$2:$J$13,0),"",DAY(DATE($B$4,MATCH($B$5,$J$2:$J$13,0),1)-WEEKDAY(DATE($B$4,MATCH($B$5,$J$2:$J$13,0),1),2)+1+14))) | B14: =IF(OR($B$4="",$B$5=""),"",IF(MONTH(DATE($B$4,MATCH($B$5,$J$2:$J$13,0),1)-WEEKDAY(DATE($B$4,MATCH($B$5,$J$2:$J$13,0),1),2)+1+15)<>MATCH($B$5,$J$2:$J$13,0),"",DAY(DATE($B$4,MATCH($B$5,$J$2:$J$13,0),1)-WEEKDAY(DATE($B$4,MATCH($B$5,$J$2:$J$13,0),1),2)+1+15))) | C14: =IF(OR($B$4="",$B$5=""),"",IF(MONTH(DATE($B$4,MATCH($B$5,$J$2:$J$13,0),1)-WEEKDAY(DATE($B$4,MATCH($B$5,$J$2:$J$13,0),1),2)+1+16)<>MATCH($B$5,$J$2:$J$13,0),"",DAY(DATE($B$4,MATCH($B$5,$J$2:$J$13,0),1)-WEEKDAY(DATE($B$4,MATCH($B$5,$J$2:$J$13,0),1),2)+1+16))) | D14: =IF(OR($B$4="",$B$5=""),"",IF(MONTH(DATE($B$4,MATCH($B$5,$J$2:$J$13,0),1)-WEEKDAY(DATE($B$4,MATCH($B$5,$J$2:$J$13,0),1),2)+1+17)<>MATCH($B$5,$J$2:$J$13,0),"",DAY(DATE($B$4,MATCH($B$5,$J$2:$J$13,0),1)-WEEKDAY(DATE($B$4,MATCH($B$5,$J$2:$J$13,0),1),2)+1+17))) | E14: =IF(OR($B$4="",$B$5=""),"",IF(MONTH(DATE($B$4,MATCH($B$5,$J$2:$J$13,0),1)-WEEKDAY(DATE($B$4,MATCH($B$5,$J$2:$J$13,0),1),2)+1+18)<>MATCH($B$5,$J$2:$J$13,0),"",DAY(DATE($B$4,MATCH($B$5,$J$2:$J$13,0),1)-WEEKDAY(DATE($B$4,MATCH($B$5,$J$2:$J$13,0),1),2)+1+18))) | F14: =IF(OR($B$4="",$B$5=""),"",IF(MONTH(DATE($B$4,MATCH($B$5,$J$2:$J$13,0),1)-WEEKDAY(DATE($B$4,MATCH($B$5,$J$2:$J$13,0),1),2)+1+19)<>MATCH($B$5,$J$2:$J$13,0),"",DAY(DATE($B$4,MATCH($B$5,$J$2:$J$13,0),1)-WEEKDAY(DATE($B$4,MATCH($B$5,$J$2:$J$13,0),1),2)+1+19))) | G14: =IF(OR($B$4="",$B$5=""),"",IF(MONTH(DATE($B$4,MATCH($B$5,$J$2:$J$13,0),1)-WEEKDAY(DATE($B$4,MATCH($B$5,$J$2:$J$13,0),1),2)+1+20)<>MATCH($B$5,$J$2:$J$13,0),"",DAY(DATE($B$4,MATCH($B$5,$J$2:$J$13,0),1)-WEEKDAY(DATE($B$4,MATCH($B$5,$J$2:$J$13,0),1),2)+1+20))) | L14: 1912 | N14: 13
A15: =IF(OR($B$4="",$B$5=""),"",IF(MONTH(DATE($B$4,MATCH($B$5,$J$2:$J$13,0),1)-WEEKDAY(DATE($B$4,MATCH($B$5,$J$2:$J$13,0),1),2)+1+21)<>MATCH($B$5,$J$2:$J$13,0),"",DAY(DATE($B$4,MATCH($B$5,$J$2:$J$13,0),1)-WEEKDAY(DATE($B$4,MATCH($B$5,$J$2:$J$13,0),1),2)+1+21))) | B15: =IF(OR($B$4="",$B$5=""),"",IF(MONTH(DATE($B$4,MATCH($B$5,$J$2:$J$13,0),1)-WEEKDAY(DATE($B$4,MATCH($B$5,$J$2:$J$13,0),1),2)+1+22)<>MATCH($B$5,$J$2:$J$13,0),"",DAY(DATE($B$4,MATCH($B$5,$J$2:$J$13,0),1)-WEEKDAY(DATE($B$4,MATCH($B$5,$J$2:$J$13,0),1),2)+1+22))) | C15: =IF(OR($B$4="",$B$5=""),"",IF(MONTH(DATE($B$4,MATCH($B$5,$J$2:$J$13,0),1)-WEEKDAY(DATE($B$4,MATCH($B$5,$J$2:$J$13,0),1),2)+1+23)<>MATCH($B$5,$J$2:$J$13,0),"",DAY(DATE($B$4,MATCH($B$5,$J$2:$J$13,0),1)-WEEKDAY(DATE($B$4,MATCH($B$5,$J$2:$J$13,0),1),2)+1+23))) | D15: =IF(OR($B$4="",$B$5=""),"",IF(MONTH(DATE($B$4,MATCH($B$5,$J$2:$J$13,0),1)-WEEKDAY(DATE($B$4,MATCH($B$5,$J$2:$J$13,0),1),2)+1+24)<>MATCH($B$5,$J$2:$J$13,0),"",DAY(DATE($B$4,MATCH($B$5,$J$2:$J$13,0),1)-WEEKDAY(DATE($B$4,MATCH($B$5,$J$2:$J$13,0),1),2)+1+24))) | E15: =IF(OR($B$4="",$B$5=""),"",IF(MONTH(DATE($B$4,MATCH($B$5,$J$2:$J$13,0),1)-WEEKDAY(DATE($B$4,MATCH($B$5,$J$2:$J$13,0),1),2)+1+25)<>MATCH($B$5,$J$2:$J$13,0),"",DAY(DATE($B$4,MATCH($B$5,$J$2:$J$13,0),1)-WEEKDAY(DATE($B$4,MATCH($B$5,$J$2:$J$13,0),1),2)+1+25))) | F15: =IF(OR($B$4="",$B$5=""),"",IF(MONTH(DATE($B$4,MATCH($B$5,$J$2:$J$13,0),1)-WEEKDAY(DATE($B$4,MATCH($B$5,$J$2:$J$13,0),1),2)+1+26)<>MATCH($B$5,$J$2:$J$13,0),"",DAY(DATE($B$4,MATCH($B$5,$J$2:$J$13,0),1)-WEEKDAY(DATE($B$4,MATCH($B$5,$J$2:$J$13,0),1),2)+1+26))) | G15: =IF(OR($B$4="",$B$5=""),"",IF(MONTH(DATE($B$4,MATCH($B$5,$J$2:$J$13,0),1)-WEEKDAY(DATE($B$4,MATCH($B$5,$J$2:$J$13,0),1),2)+1+27)<>MATCH($B$5,$J$2:$J$13,0),"",DAY(DATE($B$4,MATCH($B$5,$J$2:$J$13,0),1)-WEEKDAY(DATE($B$4,MATCH($B$5,$J$2:$J$13,0),1),2)+1+27))) | L15: 1913 | N15: 14
A16: =IF(OR($B$4="",$B$5=""),"",IF(MONTH(DATE($B$4,MATCH($B$5,$J$2:$J$13,0),1)-WEEKDAY(DATE($B$4,MATCH($B$5,$J$2:$J$13,0),1),2)+1+28)<>MATCH($B$5,$J$2:$J$13,0),"",DAY(DATE($B$4,MATCH($B$5,$J$2:$J$13,0),1)-WEEKDAY(DATE($B$4,MATCH($B$5,$J$2:$J$13,0),1),2)+1+28))) | B16: =IF(OR($B$4="",$B$5=""),"",IF(MONTH(DATE($B$4,MATCH($B$5,$J$2:$J$13,0),1)-WEEKDAY(DATE($B$4,MATCH($B$5,$J$2:$J$13,0),1),2)+1+29)<>MATCH($B$5,$J$2:$J$13,0),"",DAY(DATE($B$4,MATCH($B$5,$J$2:$J$13,0),1)-WEEKDAY(DATE($B$4,MATCH($B$5,$J$2:$J$13,0),1),2)+1+29))) | C16: =IF(OR($B$4="",$B$5=""),"",IF(MONTH(DATE($B$4,MATCH($B$5,$J$2:$J$13,0),1)-WEEKDAY(DATE($B$4,MATCH($B$5,$J$2:$J$13,0),1),2)+1+30)<>MATCH($B$5,$J$2:$J$13,0),"",DAY(DATE($B$4,MATCH($B$5,$J$2:$J$13,0),1)-WEEKDAY(DATE($B$4,MATCH($B$5,$J$2:$J$13,0),1),2)+1+30))) | D16: =IF(OR($B$4="",$B$5=""),"",IF(MONTH(DATE($B$4,MATCH($B$5,$J$2:$J$13,0),1)-WEEKDAY(DATE($B$4,MATCH($B$5,$J$2:$J$13,0),1),2)+1+31)<>MATCH($B$5,$J$2:$J$13,0),"",DAY(DATE($B$4,MATCH($B$5,$J$2:$J$13,0),1)-WEEKDAY(DATE($B$4,MATCH($B$5,$J$2:$J$13,0),1),2)+1+31))) | E16: =IF(OR($B$4="",$B$5=""),"",IF(MONTH(DATE($B$4,MATCH($B$5,$J$2:$J$13,0),1)-WEEKDAY(DATE($B$4,MATCH($B$5,$J$2:$J$13,0),1),2)+1+32)<>MATCH($B$5,$J$2:$J$13,0),"",DAY(DATE($B$4,MATCH($B$5,$J$2:$J$13,0),1)-WEEKDAY(DATE($B$4,MATCH($B$5,$J$2:$J$13,0),1),2)+1+32))) | F16: =IF(OR($B$4="",$B$5=""),"",IF(MONTH(DATE($B$4,MATCH($B$5,$J$2:$J$13,0),1)-WEEKDAY(DATE($B$4,MATCH($B$5,$J$2:$J$13,0),1),2)+1+33)<>MATCH($B$5,$J$2:$J$13,0),"",DAY(DATE($B$4,MATCH($B$5,$J$2:$J$13,0),1)-WEEKDAY(DATE($B$4,MATCH($B$5,$J$2:$J$13,0),1),2)+1+33))) | G16: =IF(OR($B$4="",$B$5=""),"",IF(MONTH(DATE($B$4,MATCH($B$5,$J$2:$J$13,0),1)-WEEKDAY(DATE($B$4,MATCH($B$5,$J$2:$J$13,0),1),2)+1+34)<>MATCH($B$5,$J$2:$J$13,0),"",DAY(DATE($B$4,MATCH($B$5,$J$2:$J$13,0),1)-WEEKDAY(DATE($B$4,MATCH($B$5,$J$2:$J$13,0),1),2)+1+34))) | L16: 1914 | N16: 15
A17: =IF(OR($B$4="",$B$5=""),"",IF(MONTH(DATE($B$4,MATCH($B$5,$J$2:$J$13,0),1)-WEEKDAY(DATE($B$4,MATCH($B$5,$J$2:$J$13,0),1),2)+1+35)<>MATCH($B$5,$J$2:$J$13,0),"",DAY(DATE($B$4,MATCH($B$5,$J$2:$J$13,0),1)-WEEKDAY(DATE($B$4,MATCH($B$5,$J$2:$J$13,0),1),2)+1+35))) | B17: =IF(OR($B$4="",$B$5=""),"",IF(MONTH(DATE($B$4,MATCH($B$5,$J$2:$J$13,0),1)-WEEKDAY(DATE($B$4,MATCH($B$5,$J$2:$J$13,0),1),2)+1+36)<>MATCH($B$5,$J$2:$J$13,0),"",DAY(DATE($B$4,MATCH($B$5,$J$2:$J$13,0),1)-WEEKDAY(DATE($B$4,MATCH($B$5,$J$2:$J$13,0),1),2)+1+36))) | C17: =IF(OR($B$4="",$B$5=""),"",IF(MONTH(DATE($B$4,MATCH($B$5,$J$2:$J$13,0),1)-WEEKDAY(DATE($B$4,MATCH($B$5,$J$2:$J$13,0),1),2)+1+37)<>MATCH($B$5,$J$2:$J$13,0),"",DAY(DATE($B$4,MATCH($B$5,$J$2:$J$13,0),1)-WEEKDAY(DATE($B$4,MATCH($B$5,$J$2:$J$13,0),1),2)+1+37))) | D17: =IF(OR($B$4="",$B$5=""),"",IF(MONTH(DATE($B$4,MATCH($B$5,$J$2:$J$13,0),1)-WEEKDAY(DATE($B$4,MATCH($B$5,$J$2:$J$13,0),1),2)+1+38)<>MATCH($B$5,$J$2:$J$13,0),"",DAY(DATE($B$4,MATCH($B$5,$J$2:$J$13,0),1)-WEEKDAY(DATE($B$4,MATCH($B$5,$J$2:$J$13,0),1),2)+1+38))) | E17: =IF(OR($B$4="",$B$5=""),"",IF(MONTH(DATE($B$4,MATCH($B$5,$J$2:$J$13,0),1)-WEEKDAY(DATE($B$4,MATCH($B$5,$J$2:$J$13,0),1),2)+1+39)<>MATCH($B$5,$J$2:$J$13,0),"",DAY(DATE($B$4,MATCH($B$5,$J$2:$J$13,0),1)-WEEKDAY(DATE($B$4,MATCH($B$5,$J$2:$J$13,0),1),2)+1+39))) | F17: =IF(OR($B$4="",$B$5=""),"",IF(MONTH(DATE($B$4,MATCH($B$5,$J$2:$J$13,0),1)-WEEKDAY(DATE($B$4,MATCH($B$5,$J$2:$J$13,0),1),2)+1+40)<>MATCH($B$5,$J$2:$J$13,0),"",DAY(DATE($B$4,MATCH($B$5,$J$2:$J$13,0),1)-WEEKDAY(DATE($B$4,MATCH($B$5,$J$2:$J$13,0),1),2)+1+40))) | G17: =IF(OR($B$4="",$B$5=""),"",IF(MONTH(DATE($B$4,MATCH($B$5,$J$2:$J$13,0),1)-WEEKDAY(DATE($B$4,MATCH($B$5,$J$2:$J$13,0),1),2)+1+41)<>MATCH($B$5,$J$2:$J$13,0),"",DAY(DATE($B$4,MATCH($B$5,$J$2:$J$13,0),1)-WEEKDAY(DATE($B$4,MATCH($B$5,$J$2:$J$13,0),1),2)+1+41))) | L17: 1915 | N17: 16
L18: 1916 | N18: 17
A19: Tip: Excel for the web may display a built-in date picker for Identity/Accreditation date cells. | L19: 1917 | N19: 18
A20: Desktop Excel: select date parts above, copy B8, then Paste Special → Values into target date cell. | L20: 1918 | N20: 19
A21: Pasting values may bypass workbook input validation: use the admin import preview to verify all dates. | L21: 1919 | N21: 20
L22: 1920 | N22: 21
L23: 1921 | N23: 22
L24: 1922 | N24: 23
L25: 1923 | N25: 24
L26: 1924 | N26: 25
L27: 1925 | N27: 26
L28: 1926 | N28: 27
L29: 1927 | N29: 28
L30: 1928 | N30: 29
L31: 1929 | N31: 30
L32: 1930 | N32: 31
L33: 1931
L34: 1932
L35: 1933
L36: 1934
L37: 1935
L38: 1936
L39: 1937
L40: 1938
...
