Workbook

Sheet README
A1: AF HOMES ECOFARM / OST BULK IMPORT
A2: Historical OST Migration | Existing AAO numbers, sponsorship & annual accreditation
A3: READ FIRST: Import authentic company data. The workbook does not create approvals, validate payments, or prove head-member identity.
A5: 01 | MIGRATION WORKFLOW
A6: STEP | B6: WHAT TO DO | C6: EXAMPLE / SAFEGUARD
A7: 1 · Gather records | B7: Copy existing OST records from the company source spreadsheets. Verify names, AAO numbers, birthdates, phone numbers and head-member details. | C7: Never use fictitious IDs or contact details for a real import.
A8: 2 · Identity | B8: Enter one OST person per numbered row in Identity. Include the authentic existing AAO Number when available. | C8: Identity row 2 = Team row 2 = Details row 2 = Accreditation row 2.
A9: 3 · Team | B9: Choose the Head Member Role (VD, SSM or SM), then select the Head Member Name from that role’s list. | C9: OST may report directly to VD, SSM or SM; do not invent a missing manager.
A10: 4 · Details | B10: Enter any actual government ID, TIN, telephone, messenger and employer details you are authorized to migrate. | C10: OST does not require IST Position or Job Position in this template.
A11: 5 · Accreditation | B11: Enter the authentic accreditation start date, optional application and signature dates; expiry is calculated one calendar year from start. | C11: Expiry is informational until independently verified in the backend.
A12: 6 · Validate | B12: Correct duplicate AAO numbers, mobile-format errors, invalid dates, ZIP conflicts and missing head members. | C12: Paste can bypass Excel input validation; the server must validate too.
A13: 7 · Preview and confirm | B13: Upload through a compatible OST import screen and review row-level matching, warnings and conflicts before authorized confirmation. | C13: Do not confirm historical Excel values as verified payments or approved identities.
A15: 02 | WORKSHEET GUIDE
A16: TAB | B16: PURPOSE | C16: USER INSTRUCTIONS
A17: README | B17: Migration instructions, field definitions, and warnings. | C17: No customer or staff rows are imported from README.
A18: Identity | B18: AAO Number, personal identity, 11-digit mobile, DOB, age and structured Philippine address. | C18: Keep an already issued company AAO; do not replace it with a newly generated number.
A19: Team | B19: Applicant Name (Auto), Head Member Role, Head Member Name, Match Check (Auto), and Search Head Member. | C19: The head dropdown is names, not emails; the system must resolve a unique staff ID.
A20: Details | B20: Applicant Name (Auto), ID/TIN and employment/contact details. | C20: The same row belongs to the same OST as Identity.
A21: Accreditation | B21: Start, Expiry (Auto), Date Applied, program/tier and signature status/dates. | C21: Only actually documented dates and signature states should be entered.
A22: Teams | B22: Exactly three manager-name columns: Vice Directors, Senior Sales Managers, Sales Managers. | C22: Paste VERIFIED existing registered names here or download a system-prefilled template.
A23: _HeadMatches | B23: Technical helper for modern Excel searchable head dropdowns. | C23: Do not edit or delete the helper; its list formulas may need Microsoft 365.
A24: PSGC / Postal | B24: Nationwide province/city/barangay and ZIP lookup sheets. | C24: Keep these reference tabs unmodified; backend always re-verifies.
A26: 03 | EXISTING AAO IDENTIFIERS
A27: RULE | B27: REQUIRED BEHAVIOR | C27: WHY IT MATTERS
A28: Existing OST with AAO | B28: Enter an authentic, company-issued historical AAOYYMMNNNN (e.g., AAO26100001) or approved AA- legacy number. Keep the original uppercase identifier. | C28: Example: AAO26100001 — examples are not authorized new numbers.
A29: New OST without issued AAO | B29: Leave AAO Number blank; the authorized backend allocator issues a new AAO for newly created members when permitted. | C29: Never fabricate or self-assign numbers from Excel.
A30: Duplicate AAO | B30: The Excel rule flags ordinary duplicate typing; server must detect duplicates across current OSTs and historical records. | C30: Same AAO pointing to different people is a blocking conflict.
A31: Historical format | B31: Excel validates AAOYYMMNNNN (valid 01-12 month, nonzero sequence) and supported 15-character AA- legacy identifiers with six uppercase letters and six digits. | C31: Unsupported older formats require separate review. Never overwrite or guess a genuine company number.
A32: Identity / role | B32: AAO Number, system account UUID, OST number, and seller accreditation are different identities. | C32: AAO never grants account access or proves eligibility.
A34: 04 | HEAD MEMBER / SALES TREE
A35: HEAD ROLE | B35: WHO TO SELECT | C35: WHAT TO CHECK
A36: Vice Director | B36: Only choose a Vice Director when MATCHING an already registered, authorized direct VD-referral OST. NOT allowed for a NEW manual OST CREATE. | C36: Existing-record MATCH only; importer verifies registered identity and keeps existing genealogy without rewriting it.
A37: Senior Sales Manager | B37: Only choose a Senior Sales Manager when MATCHING an already registered, authorized direct SSM-referral OST. NOT allowed for a NEW manual OST CREATE. | C37: Existing-record MATCH only; importer checks the recorded SSM/VD chain and never fabricates a Sales Manager.
A38: Sales Manager | B38: For NEW manually sponsored OST CREATE, choose an existing ACTIVE Sales Manager by name. The manager must have a complete active SSM -> VD chain. | C38: New manual creation is Sales Manager ONLY; the server must recheck active status, manager ID and upperline.
A39: No registered managers yet | B39: Register / approve managers through the authorized IST/staff workflow first, starting with VD → SSM → SM. | C39: The Teams tab is a lookup list, not automatic registration of managers.
A40: Names in Teams | B40: Teams is a three-column local candidate list; system-downloaded template fills eligible names. Its static blank source cannot independently query Supabase. | C40: The static workbook cannot independently fetch live Supabase staff.
A41: Search Head Member | B41: Type part of a head name in Team!E2. Excel with FILTER support can narrow options. Clear E2 to restore all. Pick only the name for the selected Head Member Role. | C41: Clear E2 to restore all candidates; older Excel may use the unfiltered role list.
A42: Name collision | B42: Even a correct name is not a unique database key. | C42: Backend must resolve exact ID/AA number and hold ambiguous matches.
A44: 05 | INPUT RULES & AUTOMATIC FIELDS
A45: FIELD | B45: EXCEL RULE | C45: SYSTEM REQUIREMENT
...

Sheet Identity
A1: AAO Number | B1: First Name | C1: Middle Name | D1: Last Name | E1: Email Address | F1: Mobile Number | G1: Date of Birth | H1: Age (Auto) | I1: Sex | J1: Civil Status | K1: Province / Region | L1: City / Municipality | M1: Barangay | N1: Permanent Address Line 1 | O1: Postal Code (Auto)
H2: =IF(G2="","",IFERROR(DATEDIF(IF(ISNUMBER(G2),G2,DATEVALUE(G2)),TODAY(),"Y"),"")) | O2: =IF(OR(K2="",L2=""),"",IFERROR(VLOOKUP(K2&"|"&L2,Postal!$A$2:$B$1643,2,FALSE),""))
H3: =IF(G3="","",IFERROR(DATEDIF(IF(ISNUMBER(G3),G3,DATEVALUE(G3)),TODAY(),"Y"),"")) | O3: =IF(OR(K3="",L3=""),"",IFERROR(VLOOKUP(K3&"|"&L3,Postal!$A$2:$B$1643,2,FALSE),""))
H4: =IF(G4="","",IFERROR(DATEDIF(IF(ISNUMBER(G4),G4,DATEVALUE(G4)),TODAY(),"Y"),"")) | O4: =IF(OR(K4="",L4=""),"",IFERROR(VLOOKUP(K4&"|"&L4,Postal!$A$2:$B$1643,2,FALSE),""))
H5: =IF(G5="","",IFERROR(DATEDIF(IF(ISNUMBER(G5),G5,DATEVALUE(G5)),TODAY(),"Y"),"")) | O5: =IF(OR(K5="",L5=""),"",IFERROR(VLOOKUP(K5&"|"&L5,Postal!$A$2:$B$1643,2,FALSE),""))
H6: =IF(G6="","",IFERROR(DATEDIF(IF(ISNUMBER(G6),G6,DATEVALUE(G6)),TODAY(),"Y"),"")) | O6: =IF(OR(K6="",L6=""),"",IFERROR(VLOOKUP(K6&"|"&L6,Postal!$A$2:$B$1643,2,FALSE),""))
H7: =IF(G7="","",IFERROR(DATEDIF(IF(ISNUMBER(G7),G7,DATEVALUE(G7)),TODAY(),"Y"),"")) | O7: =IF(OR(K7="",L7=""),"",IFERROR(VLOOKUP(K7&"|"&L7,Postal!$A$2:$B$1643,2,FALSE),""))
H8: =IF(G8="","",IFERROR(DATEDIF(IF(ISNUMBER(G8),G8,DATEVALUE(G8)),TODAY(),"Y"),"")) | O8: =IF(OR(K8="",L8=""),"",IFERROR(VLOOKUP(K8&"|"&L8,Postal!$A$2:$B$1643,2,FALSE),""))
H9: =IF(G9="","",IFERROR(DATEDIF(IF(ISNUMBER(G9),G9,DATEVALUE(G9)),TODAY(),"Y"),"")) | O9: =IF(OR(K9="",L9=""),"",IFERROR(VLOOKUP(K9&"|"&L9,Postal!$A$2:$B$1643,2,FALSE),""))
H10: =IF(G10="","",IFERROR(DATEDIF(IF(ISNUMBER(G10),G10,DATEVALUE(G10)),TODAY(),"Y"),"")) | O10: =IF(OR(K10="",L10=""),"",IFERROR(VLOOKUP(K10&"|"&L10,Postal!$A$2:$B$1643,2,FALSE),""))
H11: =IF(G11="","",IFERROR(DATEDIF(IF(ISNUMBER(G11),G11,DATEVALUE(G11)),TODAY(),"Y"),"")) | O11: =IF(OR(K11="",L11=""),"",IFERROR(VLOOKUP(K11&"|"&L11,Postal!$A$2:$B$1643,2,FALSE),""))
H12: =IF(G12="","",IFERROR(DATEDIF(IF(ISNUMBER(G12),G12,DATEVALUE(G12)),TODAY(),"Y"),"")) | O12: =IF(OR(K12="",L12=""),"",IFERROR(VLOOKUP(K12&"|"&L12,Postal!$A$2:$B$1643,2,FALSE),""))
H13: =IF(G13="","",IFERROR(DATEDIF(IF(ISNUMBER(G13),G13,DATEVALUE(G13)),TODAY(),"Y"),"")) | O13: =IF(OR(K13="",L13=""),"",IFERROR(VLOOKUP(K13&"|"&L13,Postal!$A$2:$B$1643,2,FALSE),""))
... H501: =IF(G501="","",IFERROR(DATEDIF(IF(ISNUMBER(G501),G501,DATEVALUE(G501)),TODAY(),"Y"),"")) | O501: =IF(OR(K501="",L501=""),"",IFERROR(VLOOKUP(K501&"|"&L501,Postal!$A$2:$B$1643,2,FALSE),""))

Sheet Team
A1: Applicant Name (Auto) | B1: Head Member Role | C1: Head Member Name | D1: Head Member Check (Auto) | E1: Search Head Member (All Rows)
A2: =IF(OR(Identity!B2="",Identity!D2=""),"",TRIM(Identity!B2&" "&Identity!C2&" "&Identity!D2)) | D2: =IF(A2="","",IF(B2="","Select Head Member Role",IF(C2="","Select Head Member",IF(C2=A2,"Invalid - Self Referral",IF(B2="Sales Manager",IF(COUNTIF(Teams!$C$2:$C$501,C2)=1,"SM selected - verify chain","Missing/Ambiguous SM"),IF(B2="Senior Sales Manager",IF(COUNTIF(Teams!$B$2:$B$501,C2)=1,"Existing MATCH only - review","Missing/Ambiguous SSM"),IF(B2="Vice Director",IF(COUNTIF(Teams!$A$2:$A$501,C2)=1,"Existing MATCH only - review","Missing/Ambiguous VD"),"Invalid Role")))))))
A3: =IF(OR(Identity!B3="",Identity!D3=""),"",TRIM(Identity!B3&" "&Identity!C3&" "&Identity!D3)) | D3: =IF(A3="","",IF(B3="","Select Head Member Role",IF(C3="","Select Head Member",IF(C3=A3,"Invalid - Self Referral",IF(B3="Sales Manager",IF(COUNTIF(Teams!$C$2:$C$501,C3)=1,"SM selected - verify chain","Missing/Ambiguous SM"),IF(B3="Senior Sales Manager",IF(COUNTIF(Teams!$B$2:$B$501,C3)=1,"Existing MATCH only - review","Missing/Ambiguous SSM"),IF(B3="Vice Director",IF(COUNTIF(Teams!$A$2:$A$501,C3)=1,"Existing MATCH only - review","Missing/Ambiguous VD"),"Invalid Role")))))))
A4: =IF(OR(Identity!B4="",Identity!D4=""),"",TRIM(Identity!B4&" "&Identity!C4&" "&Identity!D4)) | D4: =IF(A4="","",IF(B4="","Select Head Member Role",IF(C4="","Select Head Member",IF(C4=A4,"Invalid - Self Referral",IF(B4="Sales Manager",IF(COUNTIF(Teams!$C$2:$C$501,C4)=1,"SM selected - verify chain","Missing/Ambiguous SM"),IF(B4="Senior Sales Manager",IF(COUNTIF(Teams!$B$2:$B$501,C4)=1,"Existing MATCH only - review","Missing/Ambiguous SSM"),IF(B4="Vice Director",IF(COUNTIF(Teams!$A$2:$A$501,C4)=1,"Existing MATCH only - review","Missing/Ambiguous VD"),"Invalid Role")))))))
A5: =IF(OR(Identity!B5="",Identity!D5=""),"",TRIM(Identity!B5&" "&Identity!C5&" "&Identity!D5)) | D5: =IF(A5="","",IF(B5="","Select Head Member Role",IF(C5="","Select Head Member",IF(C5=A5,"Invalid - Self Referral",IF(B5="Sales Manager",IF(COUNTIF(Teams!$C$2:$C$501,C5)=1,"SM selected - verify chain","Missing/Ambiguous SM"),IF(B5="Senior Sales Manager",IF(COUNTIF(Teams!$B$2:$B$501,C5)=1,"Existing MATCH only - review","Missing/Ambiguous SSM"),IF(B5="Vice Director",IF(COUNTIF(Teams!$A$2:$A$501,C5)=1,"Existing MATCH only - review","Missing/Ambiguous VD"),"Invalid Role")))))))
A6: =IF(OR(Identity!B6="",Identity!D6=""),"",TRIM(Identity!B6&" "&Identity!C6&" "&Identity!D6)) | D6: =IF(A6="","",IF(B6="","Select Head Member Role",IF(C6="","Select Head Member",IF(C6=A6,"Invalid - Self Referral",IF(B6="Sales Manager",IF(COUNTIF(Teams!$C$2:$C$501,C6)=1,"SM selected - verify chain","Missing/Ambiguous SM"),IF(B6="Senior Sales Manager",IF(COUNTIF(Teams!$B$2:$B$501,C6)=1,"Existing MATCH only - review","Missing/Ambiguous SSM"),IF(B6="Vice Director",IF(COUNTIF(Teams!$A$2:$A$501,C6)=1,"Existing MATCH only - review","Missing/Ambiguous VD"),"Invalid Role")))))))
A7: =IF(OR(Identity!B7="",Identity!D7=""),"",TRIM(Identity!B7&" "&Identity!C7&" "&Identity!D7)) | D7: =IF(A7="","",IF(B7="","Select Head Member Role",IF(C7="","Select Head Member",IF(C7=A7,"Invalid - Self Referral",IF(B7="Sales Manager",IF(COUNTIF(Teams!$C$2:$C$501,C7)=1,"SM selected - verify chain","Missing/Ambiguous SM"),IF(B7="Senior Sales Manager",IF(COUNTIF(Teams!$B$2:$B$501,C7)=1,"Existing MATCH only - review","Missing/Ambiguous SSM"),IF(B7="Vice Director",IF(COUNTIF(Teams!$A$2:$A$501,C7)=1,"Existing MATCH only - review","Missing/Ambiguous VD"),"Invalid Role")))))))
A8: =IF(OR(Identity!B8="",Identity!D8=""),"",TRIM(Identity!B8&" "&Identity!C8&" "&Identity!D8)) | D8: =IF(A8="","",IF(B8="","Select Head Member Role",IF(C8="","Select Head Member",IF(C8=A8,"Invalid - Self Referral",IF(B8="Sales Manager",IF(COUNTIF(Teams!$C$2:$C$501,C8)=1,"SM selected - verify chain","Missing/Ambiguous SM"),IF(B8="Senior Sales Manager",IF(COUNTIF(Teams!$B$2:$B$501,C8)=1,"Existing MATCH only - review","Missing/Ambiguous SSM"),IF(B8="Vice Director",IF(COUNTIF(Teams!$A$2:$A$501,C8)=1,"Existing MATCH only - review","Missing/Ambiguous VD"),"Invalid Role")))))))
A9: =IF(OR(Identity!B9="",Identity!D9=""),"",TRIM(Identity!B9&" "&Identity!C9&" "&Identity!D9)) | D9: =IF(A9="","",IF(B9="","Select Head Member Role",IF(C9="","Select Head Member",IF(C9=A9,"Invalid - Self Referral",IF(B9="Sales Manager",IF(COUNTIF(Teams!$C$2:$C$501,C9)=1,"SM selected - verify chain","Missing/Ambiguous SM"),IF(B9="Senior Sales Manager",IF(COUNTIF(Teams!$B$2:$B$501,C9)=1,"Existing MATCH only - review","Missing/Ambiguous SSM"),IF(B9="Vice Director",IF(COUNTIF(Teams!$A$2:$A$501,C9)=1,"Existing MATCH only - review","Missing/Ambiguous VD"),"Invalid Role")))))))
A10: =IF(OR(Identity!B10="",Identity!D10=""),"",TRIM(Identity!B10&" "&Identity!C10&" "&Identity!D10)) | D10: =IF(A10="","",IF(B10="","Select Head Member Role",IF(C10="","Select Head Member",IF(C10=A10,"Invalid - Self Referral",IF(B10="Sales Manager",IF(COUNTIF(Teams!$C$2:$C$501,C10)=1,"SM selected - verify chain","Missing/Ambiguous SM"),IF(B10="Senior Sales Manager",IF(COUNTIF(Teams!$B$2:$B$501,C10)=1,"Existing MATCH only - review","Missing/Ambiguous SSM"),IF(B10="Vice Director",IF(COUNTIF(Teams!$A$2:$A$501,C10)=1,"Existing MATCH only - review","Missing/Ambiguous VD"),"Invalid Role")))))))
A11: =IF(OR(Identity!B11="",Identity!D11=""),"",TRIM(Identity!B11&" "&Identity!C11&" "&Identity!D11)) | D11: =IF(A11="","",IF(B11="","Select Head Member Role",IF(C11="","Select Head Member",IF(C11=A11,"Invalid - Self Referral",IF(B11="Sales Manager",IF(COUNTIF(Teams!$C$2:$C$501,C11)=1,"SM selected - verify chain","Missing/Ambiguous SM"),IF(B11="Senior Sales Manager",IF(COUNTIF(Teams!$B$2:$B$501,C11)=1,"Existing MATCH only - review","Missing/Ambiguous SSM"),IF(B11="Vice Director",IF(COUNTIF(Teams!$A$2:$A$501,C11)=1,"Existing MATCH only - review","Missing/Ambiguous VD"),"Invalid Role")))))))
A12: =IF(OR(Identity!B12="",Identity!D12=""),"",TRIM(Identity!B12&" "&Identity!C12&" "&Identity!D12)) | D12: =IF(A12="","",IF(B12="","Select Head Member Role",IF(C12="","Select Head Member",IF(C12=A12,"Invalid - Self Referral",IF(B12="Sales Manager",IF(COUNTIF(Teams!$C$2:$C$501,C12)=1,"SM selected - verify chain","Missing/Ambiguous SM"),IF(B12="Senior Sales Manager",IF(COUNTIF(Teams!$B$2:$B$501,C12)=1,"Existing MATCH only - review","Missing/Ambiguous SSM"),IF(B12="Vice Director",IF(COUNTIF(Teams!$A$2:$A$501,C12)=1,"Existing MATCH only - review","Missing/Ambiguous VD"),"Invalid Role")))))))
A13: =IF(OR(Identity!B13="",Identity!D13=""),"",TRIM(Identity!B13&" "&Identity!C13&" "&Identity!D13)) | D13: =IF(A13="","",IF(B13="","Select Head Member Role",IF(C13="","Select Head Member",IF(C13=A13,"Invalid - Self Referral",IF(B13="Sales Manager",IF(COUNTIF(Teams!$C$2:$C$501,C13)=1,"SM selected - verify chain","Missing/Ambiguous SM"),IF(B13="Senior Sales Manager",IF(COUNTIF(Teams!$B$2:$B$501,C13)=1,"Existing MATCH only - review","Missing/Ambiguous SSM"),IF(B13="Vice Director",IF(COUNTIF(Teams!$A$2:$A$501,C13)=1,"Existing MATCH only - review","Missing/Ambiguous VD"),"Invalid Role")))))))
... A501: =IF(OR(Identity!B501="",Identity!D501=""),"",TRIM(Identity!B501&" "&Identity!C501&" "&Identity!D501)) | D501: =IF(A501="","",IF(B501="","Select Head Member Role",IF(C501="","Select Head Member",IF(C501=A501,"Invalid - Self Referral",IF(B501="Sales Manager",IF(COUNTIF(Teams!$C$2:$C$501,C501)=1,"SM selected - verify chain","Missing/Ambiguous SM"),IF(B501="Senior Sales Manager",IF(COUNTIF(Teams!$B$2:$B$501,C501)=1,"Existing MATCH only - review","Missing/Ambiguous SSM"),IF(B501="Vice Director",IF(COUNTIF(Teams!$A$2:$A$501,C501)=1,"Existing MATCH only - review","Missing/Ambiguous VD"),"Invalid Role")))))))

Sheet Details
A1: Applicant Name (Auto) | B1: Government ID Type | C1: Government ID Number | D1: TIN | E1: Telephone | F1: Messenger | G1: Employer Name | H1: Employer Address
A2: =IF(OR(Identity!B2="",Identity!D2=""),"",TRIM(Identity!B2&" "&Identity!C2&" "&Identity!D2))
A3: =IF(OR(Identity!B3="",Identity!D3=""),"",TRIM(Identity!B3&" "&Identity!C3&" "&Identity!D3))
A4: =IF(OR(Identity!B4="",Identity!D4=""),"",TRIM(Identity!B4&" "&Identity!C4&" "&Identity!D4))
A5: =IF(OR(Identity!B5="",Identity!D5=""),"",TRIM(Identity!B5&" "&Identity!C5&" "&Identity!D5))
A6: =IF(OR(Identity!B6="",Identity!D6=""),"",TRIM(Identity!B6&" "&Identity!C6&" "&Identity!D6))
A7: =IF(OR(Identity!B7="",Identity!D7=""),"",TRIM(Identity!B7&" "&Identity!C7&" "&Identity!D7))
A8: =IF(OR(Identity!B8="",Identity!D8=""),"",TRIM(Identity!B8&" "&Identity!C8&" "&Identity!D8))
A9: =IF(OR(Identity!B9="",Identity!D9=""),"",TRIM(Identity!B9&" "&Identity!C9&" "&Identity!D9))
A10: =IF(OR(Identity!B10="",Identity!D10=""),"",TRIM(Identity!B10&" "&Identity!C10&" "&Identity!D10))
A11: =IF(OR(Identity!B11="",Identity!D11=""),"",TRIM(Identity!B11&" "&Identity!C11&" "&Identity!D11))
A12: =IF(OR(Identity!B12="",Identity!D12=""),"",TRIM(Identity!B12&" "&Identity!C12&" "&Identity!D12))
A13: =IF(OR(Identity!B13="",Identity!D13=""),"",TRIM(Identity!B13&" "&Identity!C13&" "&Identity!D13))
... A501: =IF(OR(Identity!B501="",Identity!D501=""),"",TRIM(Identity!B501&" "&Identity!C501&" "&Identity!D501))

Sheet Accreditation
A1: Applicant Name (Auto) | B1: Accreditation Start Date | C1: Accreditation Expiry Date (Auto) | D1: Date Applied | E1: Program Category | F1: VIP Card Type | G1: Applicant Signature | H1: Referrer Signature | I1: Applicant Signed On | J1: Referrer Signed On
A2: =IF(OR(Identity!B2="",Identity!D2=""),"",TRIM(Identity!B2&" "&Identity!C2&" "&Identity!D2)) | C2: =IF(B2="","",IFERROR(EDATE(IF(ISNUMBER(B2),B2,DATEVALUE(B2)),12),""))
A3: =IF(OR(Identity!B3="",Identity!D3=""),"",TRIM(Identity!B3&" "&Identity!C3&" "&Identity!D3)) | C3: =IF(B3="","",IFERROR(EDATE(IF(ISNUMBER(B3),B3,DATEVALUE(B3)),12),""))
A4: =IF(OR(Identity!B4="",Identity!D4=""),"",TRIM(Identity!B4&" "&Identity!C4&" "&Identity!D4)) | C4: =IF(B4="","",IFERROR(EDATE(IF(ISNUMBER(B4),B4,DATEVALUE(B4)),12),""))
A5: =IF(OR(Identity!B5="",Identity!D5=""),"",TRIM(Identity!B5&" "&Identity!C5&" "&Identity!D5)) | C5: =IF(B5="","",IFERROR(EDATE(IF(ISNUMBER(B5),B5,DATEVALUE(B5)),12),""))
A6: =IF(OR(Identity!B6="",Identity!D6=""),"",TRIM(Identity!B6&" "&Identity!C6&" "&Identity!D6)) | C6: =IF(B6="","",IFERROR(EDATE(IF(ISNUMBER(B6),B6,DATEVALUE(B6)),12),""))
A7: =IF(OR(Identity!B7="",Identity!D7=""),"",TRIM(Identity!B7&" "&Identity!C7&" "&Identity!D7)) | C7: =IF(B7="","",IFERROR(EDATE(IF(ISNUMBER(B7),B7,DATEVALUE(B7)),12),""))
A8: =IF(OR(Identity!B8="",Identity!D8=""),"",TRIM(Identity!B8&" "&Identity!C8&" "&Identity!D8)) | C8: =IF(B8="","",IFERROR(EDATE(IF(ISNUMBER(B8),B8,DATEVALUE(B8)),12),""))
A9: =IF(OR(Identity!B9="",Identity!D9=""),"",TRIM(Identity!B9&" "&Identity!C9&" "&Identity!D9)) | C9: =IF(B9="","",IFERROR(EDATE(IF(ISNUMBER(B9),B9,DATEVALUE(B9)),12),""))
A10: =IF(OR(Identity!B10="",Identity!D10=""),"",TRIM(Identity!B10&" "&Identity!C10&" "&Identity!D10)) | C10: =IF(B10="","",IFERROR(EDATE(IF(ISNUMBER(B10),B10,DATEVALUE(B10)),12),""))
A11: =IF(OR(Identity!B11="",Identity!D11=""),"",TRIM(Identity!B11&" "&Identity!C11&" "&Identity!D11)) | C11: =IF(B11="","",IFERROR(EDATE(IF(ISNUMBER(B11),B11,DATEVALUE(B11)),12),""))
A12: =IF(OR(Identity!B12="",Identity!D12=""),"",TRIM(Identity!B12&" "&Identity!C12&" "&Identity!D12)) | C12: =IF(B12="","",IFERROR(EDATE(IF(ISNUMBER(B12),B12,DATEVALUE(B12)),12),""))
A13: =IF(OR(Identity!B13="",Identity!D13=""),"",TRIM(Identity!B13&" "&Identity!C13&" "&Identity!D13)) | C13: =IF(B13="","",IFERROR(EDATE(IF(ISNUMBER(B13),B13,DATEVALUE(B13)),12),""))
... A501: =IF(OR(Identity!B501="",Identity!D501=""),"",TRIM(Identity!B501&" "&Identity!C501&" "&Identity!D501)) | C501: =IF(B501="","",IFERROR(EDATE(IF(ISNUMBER(B501),B501,DATEVALUE(B501)),12),""))

Sheet Teams
A1: Vice Director Names | B1: Senior Sales Manager Names | C1: Sales Manager Names

Sheet Postal
A1: Province|City | B1: ZIP
A2: Abra|Bangued | B2: 2800
A3: Abra|Boliney | B3: 2815
A4: Abra|Bucay | B4: 2805
A5: Abra|Bucloc | B5: 2817
A6: Abra|Daguioman | B6: 2816
A7: Abra|Danglas | B7: 2825
A8: Abra|Dolores | B8: 2801
A9: Abra|La Paz | B9: 2826
A10: Abra|Lacub | B10: 2821
A11: Abra|Lagangilang | B11: 2802
A12: Abra|Lagayan | B12: 2824
... A121: Aurora|San Luis | B121: 3201
A122: Basilan|Akbar
A123: Basilan|Al-Barka
A124: Basilan|City of Lamitan | B124: 7302
A125: Basilan|Hadji Mohammad Ajul
A126: Basilan|Hadji Muhtamad
A127: Basilan|Lantawan | B127: 7301
A128: Basilan|Maluso | B128: 7303
A129: Basilan|Sumisip | B129: 7305
A130: Basilan|Tabuan-Lasa
A131: Basilan|Tipo-Tipo | B131: 7304
A132: Basilan|Tuburan | B132: 7306
A133: Basilan|Ungkaya Pukan
A134: Bataan|Abucay | B134: 2114
A135: Bataan|Bagac | B135: 2107
A136: Bataan|City of Balanga | B136: 2100
A137: Bataan|Dinalupihan | B137: 2110
A138: Bataan|Hermosa | B138: 2111
A139: Bataan|Limay | B139: 2103
A140: Bataan|Mariveles | B140: 2105
A141: Bataan|Morong | B141: 2108
A142: Bataan|Orani | B142: 2112
A143: Bataan|Orion | B143: 2102
A144: Bataan|Pilar | B144: 2101
A145: Bataan|Samal | B145: 2113
... A230: Bohol|Garcia Hernandez | B230: 6307
A231: Bohol|Getafe
A232: Bohol|Guindulman | B232: 6310
...

Sheet PSGC_ProvinceList
A1: Province / Region for independent cities
A2: Abra
A3: Agusan del Norte
A4: Agusan del Sur
A5: Aklan
A6: Albay
A7: Antique
A8: Apayao
A9: Aurora
A10: Basilan
A11: Bataan
A12: Batanes
... A99: Zamboanga Sibugay

Sheet PSGC_CityList
A1: Province / region | B1: City / municipality | C1: Postal Code | D1: Postal Source
A2: Abra | B2: Bangued | C2: 2800 | D2: PHLPost
A3: Abra | B3: Boliney | C3: 2815 | D3: PHLPost
A4: Abra | B4: Bucay | C4: 2805 | D4: PHLPost
A5: Abra | B5: Bucloc | C5: 2817 | D5: PHLPost
A6: Abra | B6: Daguioman | C6: 2816 | D6: PHLPost
A7: Abra | B7: Danglas | C7: 2825 | D7: PHLPost
A8: Abra | B8: Dolores | C8: 2801 | D8: PHLPost
A9: Abra | B9: La Paz | C9: 2826 | D9: PHLPost
A10: Abra | B10: Lacub | C10: 2821 | D10: PHLPost
A11: Abra | B11: Lagangilang | C11: 2802 | D11: PHLPost
A12: Abra | B12: Lagayan | C12: 2824 | D12: PHLPost
... A121: Aurora | B121: San Luis | C121: 3201 | D121: PHLPost
A122: Basilan | B122: Akbar | D122: Needs verification
A123: Basilan | B123: Al-Barka | D123: Needs verification
A124: Basilan | B124: City of Lamitan | C124: 7302 | D124: BarangayDirectory
A125: Basilan | B125: Hadji Mohammad Ajul | D125: Needs verification
A126: Basilan | B126: Hadji Muhtamad | D126: Needs verification
A127: Basilan | B127: Lantawan | C127: 7301 | D127: BarangayDirectory
A128: Basilan | B128: Maluso | C128: 7303 | D128: BarangayDirectory
A129: Basilan | B129: Sumisip | C129: 7305 | D129: BarangayDirectory
A130: Basilan | B130: Tabuan-Lasa | D130: Needs verification
A131: Basilan | B131: Tipo-Tipo | C131: 7304 | D131: BarangayDirectory
A132: Basilan | B132: Tuburan | C132: 7306 | D132: BarangayDirectory
A133: Basilan | B133: Ungkaya Pukan | D133: Needs verification
A134: Bataan | B134: Abucay | C134: 2114 | D134: PHLPost
A135: Bataan | B135: Bagac | C135: 2107 | D135: PHLPost
A136: Bataan | B136: City of Balanga | C136: 2100 | D136: PHLPost
A137: Bataan | B137: Dinalupihan | C137: 2110 | D137: PHLPost
A138: Bataan | B138: Hermosa | C138: 2111 | D138: PHLPost
A139: Bataan | B139: Limay | C139: 2103 | D139: PHLPost
A140: Bataan | B140: Mariveles | C140: 2105 | D140: BarangayDirectory
A141: Bataan | B141: Morong | C141: 2108 | D141: BarangayDirectory
A142: Bataan | B142: Orani | C142: 2112 | D142: BarangayDirectory
A143: Bataan | B143: Orion | C143: 2102 | D143: BarangayDirectory
A144: Bataan | B144: Pilar | C144: 2101 | D144: BarangayDirectory
A145: Bataan | B145: Samal | C145: 2113 | D145: BarangayDirectory
... A230: Bohol | B230: Garcia Hernandez | C230: 6307 | D230: BarangayDirectory
A231: Bohol | B231: Getafe | D231: Needs verification
A232: Bohol | B232: Guindulman | C232: 6310 | D232: BarangayDirectory
...

Sheet PSGC_BarangayList
A1: Barangay
A2: Agtangao
A3: Angad
A4: Bangbangar
A5: Bañacao
A6: Cabuloan
A7: Calaba
A8: Cosili East
A9: Cosili West
A10: Dangdangla
A11: Lingtan
A12: Lipcan
... A42011: Upper Tungawan

Sheet PSGC_ProvinceIndex
A1: Province | B1: City list start row | C1: City count
A2: Abra | B2: 2 | C2: 27
A3: Agusan del Norte | B3: 29 | C3: 11
A4: Agusan del Sur | B4: 40 | C4: 14
A5: Aklan | B5: 54 | C5: 17
A6: Albay | B6: 71 | C6: 18
A7: Antique | B7: 89 | C7: 18
A8: Apayao | B8: 107 | C8: 7
A9: Aurora | B9: 114 | C9: 8
A10: Basilan | B10: 122 | C10: 12
A11: Bataan | B11: 134 | C11: 12
A12: Batanes | B12: 146 | C12: 6
A13: Batangas | B13: 152 | C13: 34
... A99: Zamboanga Sibugay | B99: 1628 | C99: 16

Sheet PSGC_CityIndex
A1: Province|City | B1: Barangay list start row | C1: Barangay count
A2: Abra|Bangued | B2: 2 | C2: 31
A3: Abra|Boliney | B3: 33 | C3: 8
A4: Abra|Bucay | B4: 41 | C4: 21
A5: Abra|Bucloc | B5: 62 | C5: 4
A6: Abra|Daguioman | B6: 66 | C6: 4
A7: Abra|Danglas | B7: 70 | C7: 7
A8: Abra|Dolores | B8: 77 | C8: 15
A9: Abra|La Paz | B9: 92 | C9: 12
A10: Abra|Lacub | B10: 104 | C10: 6
A11: Abra|Lagangilang | B11: 110 | C11: 17
A12: Abra|Lagayan | B12: 127 | C12: 5
A13: Abra|Langiden | B13: 132 | C13: 6
... A1643: Zamboanga Sibugay|Tungawan | B1643: 41987 | C1643: 25

Sheet _HeadMatches
A2: =IF(Team!$E$2="","",IFERROR(_xlfn._xlws.FILTER(Teams!$A$2:$A$501,(Teams!$A$2:$A$501<>"")*ISNUMBER(SEARCH(Team!$E$2,Teams!$A$2:$A$501))),"")) | B2: =IF(Team!$E$2="","",IFERROR(_xlfn._xlws.FILTER(Teams!$B$2:$B$501,(Teams!$B$2:$B$501<>"")*ISNUMBER(SEARCH(Team!$E$2,Teams!$B$2:$B$501))),"")) | C2: =IF(Team!$E$2="","",IFERROR(_xlfn._xlws.FILTER(Teams!$C$2:$C$501,(Teams!$C$2:$C$501<>"")*ISNUMBER(SEARCH(Team!$E$2,Teams!$C$2:$C$501))),"")) | D2: =IF(Identity!$A2="",TRUE,IFERROR(AND(ISTEXT(Identity!$A2),EXACT(Identity!$A2,UPPER(Identity!$A2)),COUNTIF(Identity!$A$2:$A$501,Identity!$A2)=1,OR(AND(LEFT(Identity!$A2,3)="AAO",LEN(Identity!$A2)=11,SUMPRODUCT(--ISNUMBER(FIND(MID(Identity!$A2,ROW($4:$11),1),"0123456789")))=8,IFERROR(VALUE(MID(Identity!$A2,6,2)),0)>=1,IFERROR(VALUE(MID(Identity!$A2,6,2)),0)<=12,RIGHT(Identity!$A2,4)<>"0000"),AND(LEFT(Identity!$A2,3)="AA-",LEN(Identity!$A2)=15,SUMPRODUCT(--ISNUMBER(FIND(MID(Identity!$A2,ROW($4:$15),1),"ABCDEFGHIJKLMNOPQRSTUVWXYZ")))=6,SUMPRODUCT(--ISNUMBER(FIND(MID(Identity!$A2,ROW($4:$15),1),"0123456789")))=6))),FALSE))
D3: =IF(Identity!$A3="",TRUE,IFERROR(AND(ISTEXT(Identity!$A3),EXACT(Identity!$A3,UPPER(Identity!$A3)),COUNTIF(Identity!$A$2:$A$501,Identity!$A3)=1,OR(AND(LEFT(Identity!$A3,3)="AAO",LEN(Identity!$A3)=11,SUMPRODUCT(--ISNUMBER(FIND(MID(Identity!$A3,ROW($4:$11),1),"0123456789")))=8,IFERROR(VALUE(MID(Identity!$A3,6,2)),0)>=1,IFERROR(VALUE(MID(Identity!$A3,6,2)),0)<=12,RIGHT(Identity!$A3,4)<>"0000"),AND(LEFT(Identity!$A3,3)="AA-",LEN(Identity!$A3)=15,SUMPRODUCT(--ISNUMBER(FIND(MID(Identity!$A3,ROW($4:$15),1),"ABCDEFGHIJKLMNOPQRSTUVWXYZ")))=6,SUMPRODUCT(--ISNUMBER(FIND(MID(Identity!$A3,ROW($4:$15),1),"0123456789")))=6))),FALSE))
D4: =IF(Identity!$A4="",TRUE,IFERROR(AND(ISTEXT(Identity!$A4),EXACT(Identity!$A4,UPPER(Identity!$A4)),COUNTIF(Identity!$A$2:$A$501,Identity!$A4)=1,OR(AND(LEFT(Identity!$A4,3)="AAO",LEN(Identity!$A4)=11,SUMPRODUCT(--ISNUMBER(FIND(MID(Identity!$A4,ROW($4:$11),1),"0123456789")))=8,IFERROR(VALUE(MID(Identity!$A4,6,2)),0)>=1,IFERROR(VALUE(MID(Identity!$A4,6,2)),0)<=12,RIGHT(Identity!$A4,4)<>"0000"),AND(LEFT(Identity!$A4,3)="AA-",LEN(Identity!$A4)=15,SUMPRODUCT(--ISNUMBER(FIND(MID(Identity!$A4,ROW($4:$15),1),"ABCDEFGHIJKLMNOPQRSTUVWXYZ")))=6,SUMPRODUCT(--ISNUMBER(FIND(MID(Identity!$A4,ROW($4:$15),1),"0123456789")))=6))),FALSE))
D5: =IF(Identity!$A5="",TRUE,IFERROR(AND(ISTEXT(Identity!$A5),EXACT(Identity!$A5,UPPER(Identity!$A5)),COUNTIF(Identity!$A$2:$A$501,Identity!$A5)=1,OR(AND(LEFT(Identity!$A5,3)="AAO",LEN(Identity!$A5)=11,SUMPRODUCT(--ISNUMBER(FIND(MID(Identity!$A5,ROW($4:$11),1),"0123456789")))=8,IFERROR(VALUE(MID(Identity!$A5,6,2)),0)>=1,IFERROR(VALUE(MID(Identity!$A5,6,2)),0)<=12,RIGHT(Identity!$A5,4)<>"0000"),AND(LEFT(Identity!$A5,3)="AA-",LEN(Identity!$A5)=15,SUMPRODUCT(--ISNUMBER(FIND(MID(Identity!$A5,ROW($4:$15),1),"ABCDEFGHIJKLMNOPQRSTUVWXYZ")))=6,SUMPRODUCT(--ISNUMBER(FIND(MID(Identity!$A5,ROW($4:$15),1),"0123456789")))=6))),FALSE))
D6: =IF(Identity!$A6="",TRUE,IFERROR(AND(ISTEXT(Identity!$A6),EXACT(Identity!$A6,UPPER(Identity!$A6)),COUNTIF(Identity!$A$2:$A$501,Identity!$A6)=1,OR(AND(LEFT(Identity!$A6,3)="AAO",LEN(Identity!$A6)=11,SUMPRODUCT(--ISNUMBER(FIND(MID(Identity!$A6,ROW($4:$11),1),"0123456789")))=8,IFERROR(VALUE(MID(Identity!$A6,6,2)),0)>=1,IFERROR(VALUE(MID(Identity!$A6,6,2)),0)<=12,RIGHT(Identity!$A6,4)<>"0000"),AND(LEFT(Identity!$A6,3)="AA-",LEN(Identity!$A6)=15,SUMPRODUCT(--ISNUMBER(FIND(MID(Identity!$A6,ROW($4:$15),1),"ABCDEFGHIJKLMNOPQRSTUVWXYZ")))=6,SUMPRODUCT(--ISNUMBER(FIND(MID(Identity!$A6,ROW($4:$15),1),"0123456789")))=6))),FALSE))
D7: =IF(Identity!$A7="",TRUE,IFERROR(AND(ISTEXT(Identity!$A7),EXACT(Identity!$A7,UPPER(Identity!$A7)),COUNTIF(Identity!$A$2:$A$501,Identity!$A7)=1,OR(AND(LEFT(Identity!$A7,3)="AAO",LEN(Identity!$A7)=11,SUMPRODUCT(--ISNUMBER(FIND(MID(Identity!$A7,ROW($4:$11),1),"0123456789")))=8,IFERROR(VALUE(MID(Identity!$A7,6,2)),0)>=1,IFERROR(VALUE(MID(Identity!$A7,6,2)),0)<=12,RIGHT(Identity!$A7,4)<>"0000"),AND(LEFT(Identity!$A7,3)="AA-",LEN(Identity!$A7)=15,SUMPRODUCT(--ISNUMBER(FIND(MID(Identity!$A7,ROW($4:$15),1),"ABCDEFGHIJKLMNOPQRSTUVWXYZ")))=6,SUMPRODUCT(--ISNUMBER(FIND(MID(Identity!$A7,ROW($4:$15),1),"0123456789")))=6))),FALSE))
D8: =IF(Identity!$A8="",TRUE,IFERROR(AND(ISTEXT(Identity!$A8),EXACT(Identity!$A8,UPPER(Identity!$A8)),COUNTIF(Identity!$A$2:$A$501,Identity!$A8)=1,OR(AND(LEFT(Identity!$A8,3)="AAO",LEN(Identity!$A8)=11,SUMPRODUCT(--ISNUMBER(FIND(MID(Identity!$A8,ROW($4:$11),1),"0123456789")))=8,IFERROR(VALUE(MID(Identity!$A8,6,2)),0)>=1,IFERROR(VALUE(MID(Identity!$A8,6,2)),0)<=12,RIGHT(Identity!$A8,4)<>"0000"),AND(LEFT(Identity!$A8,3)="AA-",LEN(Identity!$A8)=15,SUMPRODUCT(--ISNUMBER(FIND(MID(Identity!$A8,ROW($4:$15),1),"ABCDEFGHIJKLMNOPQRSTUVWXYZ")))=6,SUMPRODUCT(--ISNUMBER(FIND(MID(Identity!$A8,ROW($4:$15),1),"0123456789")))=6))),FALSE))
D9: =IF(Identity!$A9="",TRUE,IFERROR(AND(ISTEXT(Identity!$A9),EXACT(Identity!$A9,UPPER(Identity!$A9)),COUNTIF(Identity!$A$2:$A$501,Identity!$A9)=1,OR(AND(LEFT(Identity!$A9,3)="AAO",LEN(Identity!$A9)=11,SUMPRODUCT(--ISNUMBER(FIND(MID(Identity!$A9,ROW($4:$11),1),"0123456789")))=8,IFERROR(VALUE(MID(Identity!$A9,6,2)),0)>=1,IFERROR(VALUE(MID(Identity!$A9,6,2)),0)<=12,RIGHT(Identity!$A9,4)<>"0000"),AND(LEFT(Identity!$A9,3)="AA-",LEN(Identity!$A9)=15,SUMPRODUCT(--ISNUMBER(FIND(MID(Identity!$A9,ROW($4:$15),1),"ABCDEFGHIJKLMNOPQRSTUVWXYZ")))=6,SUMPRODUCT(--ISNUMBER(FIND(MID(Identity!$A9,ROW($4:$15),1),"0123456789")))=6))),FALSE))
D10: =IF(Identity!$A10="",TRUE,IFERROR(AND(ISTEXT(Identity!$A10),EXACT(Identity!$A10,UPPER(Identity!$A10)),COUNTIF(Identity!$A$2:$A$501,Identity!$A10)=1,OR(AND(LEFT(Identity!$A10,3)="AAO",LEN(Identity!$A10)=11,SUMPRODUCT(--ISNUMBER(FIND(MID(Identity!$A10,ROW($4:$11),1),"0123456789")))=8,IFERROR(VALUE(MID(Identity!$A10,6,2)),0)>=1,IFERROR(VALUE(MID(Identity!$A10,6,2)),0)<=12,RIGHT(Identity!$A10,4)<>"0000"),AND(LEFT(Identity!$A10,3)="AA-",LEN(Identity!$A10)=15,SUMPRODUCT(--ISNUMBER(FIND(MID(Identity!$A10,ROW($4:$15),1),"ABCDEFGHIJKLMNOPQRSTUVWXYZ")))=6,SUMPRODUCT(--ISNUMBER(FIND(MID(Identity!$A10,ROW($4:$15),1),"0123456789")))=6))),FALSE))
D11: =IF(Identity!$A11="",TRUE,IFERROR(AND(ISTEXT(Identity!$A11),EXACT(Identity!$A11,UPPER(Identity!$A11)),COUNTIF(Identity!$A$2:$A$501,Identity!$A11)=1,OR(AND(LEFT(Identity!$A11,3)="AAO",LEN(Identity!$A11)=11,SUMPRODUCT(--ISNUMBER(FIND(MID(Identity!$A11,ROW($4:$11),1),"0123456789")))=8,IFERROR(VALUE(MID(Identity!$A11,6,2)),0)>=1,IFERROR(VALUE(MID(Identity!$A11,6,2)),0)<=12,RIGHT(Identity!$A11,4)<>"0000"),AND(LEFT(Identity!$A11,3)="AA-",LEN(Identity!$A11)=15,SUMPRODUCT(--ISNUMBER(FIND(MID(Identity!$A11,ROW($4:$15),1),"ABCDEFGHIJKLMNOPQRSTUVWXYZ")))=6,SUMPRODUCT(--ISNUMBER(FIND(MID(Identity!$A11,ROW($4:$15),1),"0123456789")))=6))),FALSE))
D12: =IF(Identity!$A12="",TRUE,IFERROR(AND(ISTEXT(Identity!$A12),EXACT(Identity!$A12,UPPER(Identity!$A12)),COUNTIF(Identity!$A$2:$A$501,Identity!$A12)=1,OR(AND(LEFT(Identity!$A12,3)="AAO",LEN(Identity!$A12)=11,SUMPRODUCT(--ISNUMBER(FIND(MID(Identity!$A12,ROW($4:$11),1),"0123456789")))=8,IFERROR(VALUE(MID(Identity!$A12,6,2)),0)>=1,IFERROR(VALUE(MID(Identity!$A12,6,2)),0)<=12,RIGHT(Identity!$A12,4)<>"0000"),AND(LEFT(Identity!$A12,3)="AA-",LEN(Identity!$A12)=15,SUMPRODUCT(--ISNUMBER(FIND(MID(Identity!$A12,ROW($4:$15),1),"ABCDEFGHIJKLMNOPQRSTUVWXYZ")))=6,SUMPRODUCT(--ISNUMBER(FIND(MID(Identity!$A12,ROW($4:$15),1),"0123456789")))=6))),FALSE))
D13: =IF(Identity!$A13="",TRUE,IFERROR(AND(ISTEXT(Identity!$A13),EXACT(Identity!$A13,UPPER(Identity!$A13)),COUNTIF(Identity!$A$2:$A$501,Identity!$A13)=1,OR(AND(LEFT(Identity!$A13,3)="AAO",LEN(Identity!$A13)=11,SUMPRODUCT(--ISNUMBER(FIND(MID(Identity!$A13,ROW($4:$11),1),"0123456789")))=8,IFERROR(VALUE(MID(Identity!$A13,6,2)),0)>=1,IFERROR(VALUE(MID(Identity!$A13,6,2)),0)<=12,RIGHT(Identity!$A13,4)<>"0000"),AND(LEFT(Identity!$A13,3)="AA-",LEN(Identity!$A13)=15,SUMPRODUCT(--ISNUMBER(FIND(MID(Identity!$A13,ROW($4:$15),1),"ABCDEFGHIJKLMNOPQRSTUVWXYZ")))=6,SUMPRODUCT(--ISNUMBER(FIND(MID(Identity!$A13,ROW($4:$15),1),"0123456789")))=6))),FALSE))
D14: =IF(Identity!$A14="",TRUE,IFERROR(AND(ISTEXT(Identity!$A14),EXACT(Identity!$A14,UPPER(Identity!$A14)),COUNTIF(Identity!$A$2:$A$501,Identity!$A14)=1,OR(AND(LEFT(Identity!$A14,3)="AAO",LEN(Identity!$A14)=11,SUMPRODUCT(--ISNUMBER(FIND(MID(Identity!$A14,ROW($4:$11),1),"0123456789")))=8,IFERROR(VALUE(MID(Identity!$A14,6,2)),0)>=1,IFERROR(VALUE(MID(Identity!$A14,6,2)),0)<=12,RIGHT(Identity!$A14,4)<>"0000"),AND(LEFT(Identity!$A14,3)="AA-",LEN(Identity!$A14)=15,SUMPRODUCT(--ISNUMBER(FIND(MID(Identity!$A14,ROW($4:$15),1),"ABCDEFGHIJKLMNOPQRSTUVWXYZ")))=6,SUMPRODUCT(--ISNUMBER(FIND(MID(Identity!$A14,ROW($4:$15),1),"0123456789")))=6))),FALSE))
... D501: =IF(Identity!$A501="",TRUE,IFERROR(AND(ISTEXT(Identity!$A501),EXACT(Identity!$A501,UPPER(Identity!$A501)),COUNTIF(Identity!$A$2:$A$501,Identity!$A501)=1,OR(AND(LEFT(Identity!$A501,3)="AAO",LEN(Identity!$A501)=11,SUMPRODUCT(--ISNUMBER(FIND(MID(Identity!$A501,ROW($4:$11),1),"0123456789")))=8,IFERROR(VALUE(MID(Identity!$A501,6,2)),0)>=1,IFERROR(VALUE(MID(Identity!$A501,6,2)),0)<=12,RIGHT(Identity!$A501,4)<>"0000"),AND(LEFT(Identity!$A501,3)="AA-",LEN(Identity!$A501)=15,SUMPRODUCT(--ISNUMBER(FIND(MID(Identity!$A501,ROW($4:$15),1),"ABCDEFGHIJKLMNOPQRSTUVWXYZ")))=6,SUMPRODUCT(--ISNUMBER(FIND(MID(Identity!$A501,ROW($4:$15),1),"0123456789")))=6))),FALSE))

Sheet Date Helper
A1: AF HOMES OST | DATE ENTRY HELPER | J1: Month List | L1: Year List | N1: Day List
A2: Choose Year, Month and Day. Copy the Date Result as a VALUE into any date field. | J2: January | L2: 1900 | N2: 1
J3: February | L3: 1901 | N3: 2
A4: Year | J4: March | L4: 1902 | N4: 3
A5: Month | J5: April | L5: 1903 | N5: 4
A6: Day | J6: May | L6: 1904 | N6: 5
J7: June | L7: 1905 | N7: 6
A8: Date Result (copy) | B8: =IF(OR(B4="",B5="",B6=""),"",IF(OR(B6<1,B6>DAY(EOMONTH(DATE(B4,MATCH(B5,$J$2:$J$13,0),1),0))),"INVALID DAY",DATE(B4,MATCH(B5,$J$2:$J$13,0),B6))) | J8: July | L8: 1906 | N8: 7
J9: August | L9: 1907 | N9: 8
A10: CALENDAR PREVIEW — select the day above; this grid is for reference. | J10: September | L10: 1908 | N10: 9
A11: Mon | B11: Tue | C11: Wed | D11: Thu | E11: Fri | F11: Sat | G11: Sun | J11: October | L11: 1909 | N11: 10
A12: =IF(OR($B$4="",$B$5=""),"",IF(MONTH(DATE($B$4,MATCH($B$5,$J$2:$J$13,0),1)-WEEKDAY(DATE($B$4,MATCH($B$5,$J$2:$J$13,0),1),2)+1+0)<>MATCH($B$5,$J$2:$J$13,0),"",DAY(DATE($B$4,MATCH($B$5,$J$2:$J$13,0),1)-WEEKDAY(DATE($B$4,MATCH($B$5,$J$2:$J$13,0),1),2)+1+0))) | B12: =IF(OR($B$4="",$B$5=""),"",IF(MONTH(DATE($B$4,MATCH($B$5,$J$2:$J$13,0),1)-WEEKDAY(DATE($B$4,MATCH($B$5,$J$2:$J$13,0),1),2)+1+1)<>MATCH($B$5,$J$2:$J$13,0),"",DAY(DATE($B$4,MATCH($B$5,$J$2:$J$13,0),1)-WEEKDAY(DATE($B$4,MATCH($B$5,$J$2:$J$13,0),1),2)+1+1))) | C12: =IF(OR($B$4="",$B$5=""),"",IF(MONTH(DATE($B$4,MATCH($B$5,$J$2:$J$13,0),1)-WEEKDAY(DATE($B$4,MATCH($B$5,$J$2:$J$13,0),1),2)+1+2)<>MATCH($B$5,$J$2:$J$13,0),"",DAY(DATE($B$4,MATCH($B$5,$J$2:$J$13,0),1)-WEEKDAY(DATE($B$4,MATCH($B$5,$J$2:$J$13,0),1),2)+1+2))) | D12: =IF(OR($B$4="",$B$5=""),"",IF(MONTH(DATE($B$4,MATCH($B$5,$J$2:$J$13,0),1)-WEEKDAY(DATE($B$4,MATCH($B$5,$J$2:$J$13,0),1),2)+1+3)<>MATCH($B$5,$J$2:$J$13,0),"",DAY(DATE($B$4,MATCH($B$5,$J$2:$J$13,0),1)-WEEKDAY(DATE($B$4,MATCH($B$5,$J$2:$J$13,0),1),2)+1+3))) | E12: =IF(OR($B$4="",$B$5=""),"",IF(MONTH(DATE($B$4,MATCH($B$5,$J$2:$J$13,0),1)-WEEKDAY(DATE($B$4,MATCH($B$5,$J$2:$J$13,0),1),2)+1+4)<>MATCH($B$5,$J$2:$J$13,0),"",DAY(DATE($B$4,MATCH($B$5,$J$2:$J$13,0),1)-WEEKDAY(DATE($B$4,MATCH($B$5,$J$2:$J$13,0),1),2)+1+4))) | F12: =IF(OR($B$4="",$B$5=""),"",IF(MONTH(DATE($B$4,MATCH($B$5,$J$2:$J$13,0),1)-WEEKDAY(DATE($B$4,MATCH($B$5,$J$2:$J$13,0),1),2)+1+5)<>MATCH($B$5,$J$2:$J$13,0),"",DAY(DATE($B$4,MATCH($B$5,$J$2:$J$13,0),1)-WEEKDAY(DATE($B$4,MATCH($B$5,$J$2:$J$13,0),1),2)+1+5))) | G12: =IF(OR($B$4="",$B$5=""),"",IF(MONTH(DATE($B$4,MATCH($B$5,$J$2:$J$13,0),1)-WEEKDAY(DATE($B$4,MATCH($B$5,$J$2:$J$13,0),1),2)+1+6)<>MATCH($B$5,$J$2:$J$13,0),"",DAY(DATE($B$4,MATCH($B$5,$J$2:$J$13,0),1)-WEEKDAY(DATE($B$4,MATCH($B$5,$J$2:$J$13,0),1),2)+1+6))) | J12: November | L12: 1910 | N12: 11
A13: =IF(OR($B$4="",$B$5=""),"",IF(MONTH(DATE($B$4,MATCH($B$5,$J$2:$J$13,0),1)-WEEKDAY(DATE($B$4,MATCH($B$5,$J$2:$J$13,0),1),2)+1+7)<>MATCH($B$5,$J$2:$J$13,0),"",DAY(DATE($B$4,MATCH($B$5,$J$2:$J$13,0),1)-WEEKDAY(DATE($B$4,MATCH($B$5,$J$2:$J$13,0),1),2)+1+7))) | B13: =IF(OR($B$4="",$B$5=""),"",IF(MONTH(DATE($B$4,MATCH($B$5,$J$2:$J$13,0),1)-WEEKDAY(DATE($B$4,MATCH($B$5,$J$2:$J$13,0),1),2)+1+8)<>MATCH($B$5,$J$2:$J$13,0),"",DAY(DATE($B$4,MATCH($B$5,$J$2:$J$13,0),1)-WEEKDAY(DATE($B$4,MATCH($B$5,$J$2:$J$13,0),1),2)+1+8))) | C13: =IF(OR($B$4="",$B$5=""),"",IF(MONTH(DATE($B$4,MATCH($B$5,$J$2:$J$13,0),1)-WEEKDAY(DATE($B$4,MATCH($B$5,$J$2:$J$13,0),1),2)+1+9)<>MATCH($B$5,$J$2:$J$13,0),"",DAY(DATE($B$4,MATCH($B$5,$J$2:$J$13,0),1)-WEEKDAY(DATE($B$4,MATCH($B$5,$J$2:$J$13,0),1),2)+1+9))) | D13: =IF(OR($B$4="",$B$5=""),"",IF(MONTH(DATE($B$4,MATCH($B$5,$J$2:$J$13,0),1)-WEEKDAY(DATE($B$4,MATCH($B$5,$J$2:$J$13,0),1),2)+1+10)<>MATCH($B$5,$J$2:$J$13,0),"",DAY(DATE($B$4,MATCH($B$5,$J$2:$J$13,0),1)-WEEKDAY(DATE($B$4,MATCH($B$5,$J$2:$J$13,0),1),2)+1+10))) | E13: =IF(OR($B$4="",$B$5=""),"",IF(MONTH(DATE($B$4,MATCH($B$5,$J$2:$J$13,0),1)-WEEKDAY(DATE($B$4,MATCH($B$5,$J$2:$J$13,0),1),2)+1+11)<>MATCH($B$5,$J$2:$J$13,0),"",DAY(DATE($B$4,MATCH($B$5,$J$2:$J$13,0),1)-WEEKDAY(DATE($B$4,MATCH($B$5,$J$2:$J$13,0),1),2)+1+11))) | F13: =IF(OR($B$4="",$B$5=""),"",IF(MONTH(DATE($B$4,MATCH($B$5,$J$2:$J$13,0),1)-WEEKDAY(DATE($B$4,MATCH($B$5,$J$2:$J$13,0),1),2)+1+12)<>MATCH($B$5,$J$2:$J$13,0),"",DAY(DATE($B$4,MATCH($B$5,$J$2:$J$13,0),1)-WEEKDAY(DATE($B$4,MATCH($B$5,$J$2:$J$13,0),1),2)+1+12))) | G13: =IF(OR($B$4="",$B$5=""),"",IF(MONTH(DATE($B$4,MATCH($B$5,$J$2:$J$13,0),1)-WEEKDAY(DATE($B$4,MATCH($B$5,$J$2:$J$13,0),1),2)+1+13)<>MATCH($B$5,$J$2:$J$13,0),"",DAY(DATE($B$4,MATCH($B$5,$J$2:$J$13,0),1)-WEEKDAY(DATE($B$4,MATCH($B$5,$J$2:$J$13,0),1),2)+1+13))) | J13: December | L13: 1911 | N13: 12
A14: =IF(OR($B$4="",$B$5=""),"",IF(MONTH(DATE($B$4,MATCH($B$5,$J$2:$J$13,0),1)-WEEKDAY(DATE($B$4,MATCH($B$5,$J$2:$J$13,0),1),2)+1+14)<>MATCH($B$5,$J$2:$J$13,0),"",DAY(DATE($B$4,MATCH($B$5,$J$2:$J$13,0),1)-WEEKDAY(DATE($B$4,MATCH($B$5,$J$2:$J$13,0),1),2)+1+14))) | B14: =IF(OR($B$4="",$B$5=""),"",IF(MONTH(DATE($B$4,MATCH($B$5,$J$2:$J$13,0),1)-WEEKDAY(DATE($B$4,MATCH($B$5,$J$2:$J$13,0),1),2)+1+15)<>MATCH($B$5,$J$2:$J$13,0),"",DAY(DATE($B$4,MATCH($B$5,$J$2:$J$13,0),1)-WEEKDAY(DATE($B$4,MATCH($B$5,$J$2:$J$13,0),1),2)+1+15))) | C14: =IF(OR($B$4="",$B$5=""),"",IF(MONTH(DATE($B$4,MATCH($B$5,$J$2:$J$13,0),1)-WEEKDAY(DATE($B$4,MATCH($B$5,$J$2:$J$13,0),1),2)+1+16)<>MATCH($B$5,$J$2:$J$13,0),"",DAY(DATE($B$4,MATCH($B$5,$J$2:$J$13,0),1)-WEEKDAY(DATE($B$4,MATCH($B$5,$J$2:$J$13,0),1),2)+1+16))) | D14: =IF(OR($B$4="",$B$5=""),"",IF(MONTH(DATE($B$4,MATCH($B$5,$J$2:$J$13,0),1)-WEEKDAY(DATE($B$4,MATCH($B$5,$J$2:$J$13,0),1),2)+1+17)<>MATCH($B$5,$J$2:$J$13,0),"",DAY(DATE($B$4,MATCH($B$5,$J$2:$J$13,0),1)-WEEKDAY(DATE($B$4,MATCH($B$5,$J$2:$J$13,0),1),2)+1+17))) | E14: =IF(OR($B$4="",$B$5=""),"",IF(MONTH(DATE($B$4,MATCH($B$5,$J$2:$J$13,0),1)-WEEKDAY(DATE($B$4,MATCH($B$5,$J$2:$J$13,0),1),2)+1+18)<>MATCH($B$5,$J$2:$J$13,0),"",DAY(DATE($B$4,MATCH($B$5,$J$2:$J$13,0),1)-WEEKDAY(DATE($B$4,MATCH($B$5,$J$2:$J$13,0),1),2)+1+18))) | F14: =IF(OR($B$4="",$B$5=""),"",IF(MONTH(DATE($B$4,MATCH($B$5,$J$2:$J$13,0),1)-WEEKDAY(DATE($B$4,MATCH($B$5,$J$2:$J$13,0),1),2)+1+19)<>MATCH($B$5,$J$2:$J$13,0),"",DAY(DATE($B$4,MATCH($B$5,$J$2:$J$13,0),1)-WEEKDAY(DATE($B$4,MATCH($B$5,$J$2:$J$13,0),1),2)+1+19))) | G14: =IF(OR($B$4="",$B$5=""),"",IF(MONTH(DATE($B$4,MATCH($B$5,$J$2:$J$13,0),1)-WEEKDAY(DATE($B$4,MATCH($B$5,$J$2:$J$13,0),1),2)+1+20)<>MATCH($B$5,$J$2:$J$13,0),"",DAY(DATE($B$4,MATCH($B$5,$J$2:$J$13,0),1)-WEEKDAY(DATE($B$4,MATCH($B$5,$J$2:$J$13,0),1),2)+1+20))) | L14: 1912 | N14: 13
A15: =IF(OR($B$4="",$B$5=""),"",IF(MONTH(DATE($B$4,MATCH($B$5,$J$2:$J$13,0),1)-WEEKDAY(DATE($B$4,MATCH($B$5,$J$2:$J$13,0),1),2)+1+21)<>MATCH($B$5,$J$2:$J$13,0),"",DAY(DATE($B$4,MATCH($B$5,$J$2:$J$13,0),1)-WEEKDAY(DATE($B$4,MATCH($B$5,$J$2:$J$13,0),1),2)+1+21))) | B15: =IF(OR($B$4="",$B$5=""),"",IF(MONTH(DATE($B$4,MATCH($B$5,$J$2:$J$13,0),1)-WEEKDAY(DATE($B$4,MATCH($B$5,$J$2:$J$13,0),1),2)+1+22)<>MATCH($B$5,$J$2:$J$13,0),"",DAY(DATE($B$4,MATCH($B$5,$J$2:$J$13,0),1)-WEEKDAY(DATE($B$4,MATCH($B$5,$J$2:$J$13,0),1),2)+1+22))) | C15: =IF(OR($B$4="",$B$5=""),"",IF(MONTH(DATE($B$4,MATCH($B$5,$J$2:$J$13,0),1)-WEEKDAY(DATE($B$4,MATCH($B$5,$J$2:$J$13,0),1),2)+1+23)<>MATCH($B$5,$J$2:$J$13,0),"",DAY(DATE($B$4,MATCH($B$5,$J$2:$J$13,0),1)-WEEKDAY(DATE($B$4,MATCH($B$5,$J$2:$J$13,0),1),2)+1+23))) | D15: =IF(OR($B$4="",$B$5=""),"",IF(MONTH(DATE($B$4,MATCH($B$5,$J$2:$J$13,0),1)-WEEKDAY(DATE($B$4,MATCH($B$5,$J$2:$J$13,0),1),2)+1+24)<>MATCH($B$5,$J$2:$J$13,0),"",DAY(DATE($B$4,MATCH($B$5,$J$2:$J$13,0),1)-WEEKDAY(DATE($B$4,MATCH($B$5,$J$2:$J$13,0),1),2)+1+24))) | E15: =IF(OR($B$4="",$B$5=""),"",IF(MONTH(DATE($B$4,MATCH($B$5,$J$2:$J$13,0),1)-WEEKDAY(DATE($B$4,MATCH($B$5,$J$2:$J$13,0),1),2)+1+25)<>MATCH($B$5,$J$2:$J$13,0),"",DAY(DATE($B$4,MATCH($B$5,$J$2:$J$13,0),1)-WEEKDAY(DATE($B$4,MATCH($B$5,$J$2:$J$13,0),1),2)+1+25))) | F15: =IF(OR($B$4="",$B$5=""),"",IF(MONTH(DATE($B$4,MATCH($B$5,$J$2:$J$13,0),1)-WEEKDAY(DATE($B$4,MATCH($B$5,$J$2:$J$13,0),1),2)+1+26)<>MATCH($B$5,$J$2:$J$13,0),"",DAY(DATE($B$4,MATCH($B$5,$J$2:$J$13,0),1)-WEEKDAY(DATE($B$4,MATCH($B$5,$J$2:$J$13,0),1),2)+1+26))) | G15: =IF(OR($B$4="",$B$5=""),"",IF(MONTH(DATE($B$4,MATCH($B$5,$J$2:$J$13,0),1)-WEEKDAY(DATE($B$4,MATCH($B$5,$J$2:$J$13,0),1),2)+1+27)<>MATCH($B$5,$J$2:$J$13,0),"",DAY(DATE($B$4,MATCH($B$5,$J$2:$J$13,0),1)-WEEKDAY(DATE($B$4,MATCH($B$5,$J$2:$J$13,0),1),2)+1+27))) | L15: 1913 | N15: 14
A16: =IF(OR($B$4="",$B$5=""),"",IF(MONTH(DATE($B$4,MATCH($B$5,$J$2:$J$13,0),1)-WEEKDAY(DATE($B$4,MATCH($B$5,$J$2:$J$13,0),1),2)+1+28)<>MATCH($B$5,$J$2:$J$13,0),"",DAY(DATE($B$4,MATCH($B$5,$J$2:$J$13,0),1)-WEEKDAY(DATE($B$4,MATCH($B$5,$J$2:$J$13,0),1),2)+1+28))) | B16: =IF(OR($B$4="",$B$5=""),"",IF(MONTH(DATE($B$4,MATCH($B$5,$J$2:$J$13,0),1)-WEEKDAY(DATE($B$4,MATCH($B$5,$J$2:$J$13,0),1),2)+1+29)<>MATCH($B$5,$J$2:$J$13,0),"",DAY(DATE($B$4,MATCH($B$5,$J$2:$J$13,0),1)-WEEKDAY(DATE($B$4,MATCH($B$5,$J$2:$J$13,0),1),2)+1+29))) | C16: =IF(OR($B$4="",$B$5=""),"",IF(MONTH(DATE($B$4,MATCH($B$5,$J$2:$J$13,0),1)-WEEKDAY(DATE($B$4,MATCH($B$5,$J$2:$J$13,0),1),2)+1+30)<>MATCH($B$5,$J$2:$J$13,0),"",DAY(DATE($B$4,MATCH($B$5,$J$2:$J$13,0),1)-WEEKDAY(DATE($B$4,MATCH($B$5,$J$2:$J$13,0),1),2)+1+30))) | D16: =IF(OR($B$4="",$B$5=""),"",IF(MONTH(DATE($B$4,MATCH($B$5,$J$2:$J$13,0),1)-WEEKDAY(DATE($B$4,MATCH($B$5,$J$2:$J$13,0),1),2)+1+31)<>MATCH($B$5,$J$2:$J$13,0),"",DAY(DATE($B$4,MATCH($B$5,$J$2:$J$13,0),1)-WEEKDAY(DATE($B$4,MATCH($B$5,$J$2:$J$13,0),1),2)+1+31))) | E16: =IF(OR($B$4="",$B$5=""),"",IF(MONTH(DATE($B$4,MATCH($B$5,$J$2:$J$13,0),1)-WEEKDAY(DATE($B$4,MATCH($B$5,$J$2:$J$13,0),1),2)+1+32)<>MATCH($B$5,$J$2:$J$13,0),"",DAY(DATE($B$4,MATCH($B$5,$J$2:$J$13,0),1)-WEEKDAY(DATE($B$4,MATCH($B$5,$J$2:$J$13,0),1),2)+1+32))) | F16: =IF(OR($B$4="",$B$5=""),"",IF(MONTH(DATE($B$4,MATCH($B$5,$J$2:$J$13,0),1)-WEEKDAY(DATE($B$4,MATCH($B$5,$J$2:$J$13,0),1),2)+1+33)<>MATCH($B$5,$J$2:$J$13,0),"",DAY(DATE($B$4,MATCH($B$5,$J$2:$J$13,0),1)-WEEKDAY(DATE($B$4,MATCH($B$5,$J$2:$J$13,0),1),2)+1+33))) | G16: =IF(OR($B$4="",$B$5=""),"",IF(MONTH(DATE($B$4,MATCH($B$5,$J$2:$J$13,0),1)-WEEKDAY(DATE($B$4,MATCH($B$5,$J$2:$J$13,0),1),2)+1+34)<>MATCH($B$5,$J$2:$J$13,0),"",DAY(DATE($B$4,MATCH($B$5,$J$2:$J$13,0),1)-WEEKDAY(DATE($B$4,MATCH($B$5,$J$2:$J$13,0),1),2)+1+34))) | L16: 1914 | N16: 15
A17: =IF(OR($B$4="",$B$5=""),"",IF(MONTH(DATE($B$4,MATCH($B$5,$J$2:$J$13,0),1)-WEEKDAY(DATE($B$4,MATCH($B$5,$J$2:$J$13,0),1),2)+1+35)<>MATCH($B$5,$J$2:$J$13,0),"",DAY(DATE($B$4,MATCH($B$5,$J$2:$J$13,0),1)-WEEKDAY(DATE($B$4,MATCH($B$5,$J$2:$J$13,0),1),2)+1+35))) | B17: =IF(OR($B$4="",$B$5=""),"",IF(MONTH(DATE($B$4,MATCH($B$5,$J$2:$J$13,0),1)-WEEKDAY(DATE($B$4,MATCH($B$5,$J$2:$J$13,0),1),2)+1+36)<>MATCH($B$5,$J$2:$J$13,0),"",DAY(DATE($B$4,MATCH($B$5,$J$2:$J$13,0),1)-WEEKDAY(DATE($B$4,MATCH($B$5,$J$2:$J$13,0),1),2)+1+36))) | C17: =IF(OR($B$4="",$B$5=""),"",IF(MONTH(DATE($B$4,MATCH($B$5,$J$2:$J$13,0),1)-WEEKDAY(DATE($B$4,MATCH($B$5,$J$2:$J$13,0),1),2)+1+37)<>MATCH($B$5,$J$2:$J$13,0),"",DAY(DATE($B$4,MATCH($B$5,$J$2:$J$13,0),1)-WEEKDAY(DATE($B$4,MATCH($B$5,$J$2:$J$13,0),1),2)+1+37))) | D17: =IF(OR($B$4="",$B$5=""),"",IF(MONTH(DATE($B$4,MATCH($B$5,$J$2:$J$13,0),1)-WEEKDAY(DATE($B$4,MATCH($B$5,$J$2:$J$13,0),1),2)+1+38)<>MATCH($B$5,$J$2:$J$13,0),"",DAY(DATE($B$4,MATCH($B$5,$J$2:$J$13,0),1)-WEEKDAY(DATE($B$4,MATCH($B$5,$J$2:$J$13,0),1),2)+1+38))) | E17: =IF(OR($B$4="",$B$5=""),"",IF(MONTH(DATE($B$4,MATCH($B$5,$J$2:$J$13,0),1)-WEEKDAY(DATE($B$4,MATCH($B$5,$J$2:$J$13,0),1),2)+1+39)<>MATCH($B$5,$J$2:$J$13,0),"",DAY(DATE($B$4,MATCH($B$5,$J$2:$J$13,0),1)-WEEKDAY(DATE($B$4,MATCH($B$5,$J$2:$J$13,0),1),2)+1+39))) | F17: =IF(OR($B$4="",$B$5=""),"",IF(MONTH(DATE($B$4,MATCH($B$5,$J$2:$J$13,0),1)-WEEKDAY(DATE($B$4,MATCH($B$5,$J$2:$J$13,0),1),2)+1+40)<>MATCH($B$5,$J$2:$J$13,0),"",DAY(DATE($B$4,MATCH($B$5,$J$2:$J$13,0),1)-WEEKDAY(DATE($B$4,MATCH($B$5,$J$2:$J$13,0),1),2)+1+40))) | G17: =IF(OR($B$4="",$B$5=""),"",IF(MONTH(DATE($B$4,MATCH($B$5,$J$2:$J$13,0),1)-WEEKDAY(DATE($B$4,MATCH($B$5,$J$2:$J$13,0),1),2)+1+41)<>MATCH($B$5,$J$2:$J$13,0),"",DAY(DATE($B$4,MATCH($B$5,$J$2:$J$13,0),1)-WEEKDAY(DATE($B$4,MATCH($B$5,$J$2:$J$13,0),1),2)+1+41))) | L17: 1915 | N17: 16
L18: 1916 | N18: 17
A19: Tip: Excel for the web may display a built-in date picker for Identity/Accreditation date cells. | L19: 1917 | N19: 18
A20: Desktop Excel: select date parts above, copy B8, then Paste Special → Values into target date cell. | L20: 1918 | N20: 19
A21: Pasting values may bypass workbook input validation: use the admin import preview to verify all dates. | L21: 1919 | N21: 20
L22: 1920 | N22: 21
L23: 1921 | N23: 22
L24: 1922 | N24: 23
L25: 1923 | N25: 24
L26: 1924 | N26: 25
L27: 1925 | N27: 26
L28: 1926 | N28: 27
L29: 1927 | N29: 28
L30: 1928 | N30: 29
L31: 1929 | N31: 30
L32: 1930 | N32: 31
L33: 1931
L34: 1932
L35: 1933
L36: 1934
L37: 1935
L38: 1936
L39: 1937
L40: 1938
...
